Workbook

Sheet Anlagendaten
A1: Allgmeine Daten
A3: Anlagenbetreiber: | B3: Schulstiftung der Evangelischen Landeskirche in Württemberg
B4: Schlossweg 8
B5: 74544 Michelbach/Bilz
A6: Ansprechpartner | B6: Herr Hans Hübner | C6: (Vertrag) | D6: Sven Ehrenberg | E6: (Technik)
B7: 0791/93016-270 | D7: 0176 2232 1125
B8: Hans.Huebner@schulstiftung.info | D8: sven.ehrenberg@lichtenstern.info
A10: Anlage: | B10: Lichtenstern Gymnasium
B11: Ludwigsburger Str. 34
B12: 74343 Sachsenheim
A14: BHKW:
A15: =+Verbrauchsdaten!A7 -> BHKW Type: | B15: Kraftwerk Mephisto
A16: elkt. Leistung | B16: 34 | C16: kW
A17: therm. Leistung | B17: 78 | C17: kW
A18: Leistungsbezug | B18: 108 | C18: kW (Hu)
A19: Tag der Inbetriebnahme | B19: 41849
A21: Höhe Anlagenstandort | B21: 250 | C21: Meter über Meer
A22: Fließdruck BHKW-Gaszähler | B22: 22 | C22: mbar
A24: Investition | B24: 199000 | C24: € brutto
A25: Zinssatz: | B25: 2 | C25: %
B28: Wartungskosten (brutto) | C28: interne Betriebskosten
A29: 2017
A30: 2017 | B30: 8073.74
A31: 2016 | B31: 8443.6532

Sheet Verbrauchsdaten
A1: BHKW Daten | C1: , | E1: Hinweise:
A2: Kunde: | B2: =+Anlagendaten!B3 -> Schulstiftung der Evangelischen Landeskirche in Württemberg | E2: Die Ablesung sollte möglichst nah um den 1. jedes Manates erfolgen - je nach Wochentag sind die Tage davor oder danach auch möglich. Bitte ggf. Datum berichtigen
E3: Sind Zähler nicht vorhanden bzw nicht auslesbar - bitte als Hinweis kurz eintragen - danch kann die Spalte ausgeblendet werden bitte nicht löschen
A4: Anlage: | B4: =+Anlagendaten!B10 -> Lichtenstern Gymnasium | E4: Die kursiv geschriebenen Werte bitte nach der jeweiligen Abrechnung eintragen
E5: Falls die Zähler abgelesen werden können bitte monatlich eintragen
E6: *Zählerstände bitte wenn möglich monatlich auslesen - diese Stände dienen der Kontrolle der Energierechnungen bzw. besseren Beurteilung der Struktur da z.B. der ausgespeiste Strom i.d.R. nur jährlich abgerechnet wird
A7: BHKW Type: | B7: =+Anlagendaten!B15 -> Kraftwerk Mephisto | D7: Zählerfaktor: | G7: Zählerfaktor: | O7: Zählerfaktor: | R7: Zusätzliche Brennstoffe für Wärmeerzeugung
D8: 1 | G8: 120 | M8: 383576
B9: BHKW | C9: 314378 | D9: 1NZR 0721163921 | G9: 21309589 | H9: (2.8.2) | I9: Aus Abrechnung (Netzbetreiber) | K9: Aus Abrechnung (Netzbetreiber) | M9: Bezug | N9: Bezug | O9: Erdgasbezugs- | P9: Bezug (1.8.1) | Q9: Bezug (1.8.2) | R9: Aus Stromrechnung vom Stromlieferant
B10: Betriebstunden | C10: Erdgas | D10: erzeugter Strom | E10: erzeugte Wärme | F10: Starts | G10: ausgespeister Strom | H10: ausgespeister Strom | I10: ausgespeister Strom | J10: Vergütung | K10: erzeugter Strom | L10: erhaltener | M10: Erdgas(gesamt) | N10: Erdgas | O10: kosten | P10: Strom (gesamt) | Q10: Strom (gesamt) | R10: Strom | S10: Kosten
B11: Zählerstand | C11: Zählerstand | D11: *Zählerstand | E11: Zählerstand | F11: Zählerstand | G11: *Zählerstand | H11: *Zählerstand | J11: o. KWK-Bonus | L11: kWK-Bonus | M11: *Zählerstand | N11: Rechnung | O11: Rechnung | P11: *Zählerstand | Q11: *Zählerstand | R11: gesamt | S11: gesamt
A12: Zeit | B12: Stunden | C12: m³ | D12: kWh | E12: kWh/MWh | F12: Anzahl | G12: kWh | H12: kWh | I12: kWh | J12: € | K12: kWh | L12: € | M12: m³ | N12: kWh | O12: € (brutto) | P12: kWh | Q12: kWh | R12: kWh | S12: € (brutto)
B13: - | I13: bitte hier nur die jährlichen Rechnungen als PDF zusenden - Daten werden eingetragen
A14: 41671 | B14: - | C14: - | M14: 2497766.7
A15: 41699 | B15: - | C15: - | M15: 2506385.8
A16: 41730 | B16: - | C16: - | M16: 2511284.8
A17: 41760 | B17: - | C17: - | M17: 2515015
A18: 41791 | B18: - | C18: - | M18: 2517686.7
A19: 41821 | B19: - | C19: - | M19: 2518857.7
A20: 41852 | C20: - | D20: 3 | M20: 2520714.2
A21: 41891 | B21: 317 | C21: - | D21: 4896 | E21: - | F21: 311 | G21: - | M21: 2523006.3
A22: 41913 | B22: 533 | C22: - | D22: 14376 | E22: - | F22: 476 | G22: - | M22: 2526512.8
A23: 41944 | B23: 968 | C23: - | D23: 26862 | E23: - | F23: 811 | G23: - | M23: 2531021.7
A24: 41974 | B24: 1569 | C24: 159662.3 | D24: 44486 | E24: 95 | F24: 911 | G24: - | M24: 2540310.9
A25: 42005 | B25: 2290 | C25: 25872.38 | D25: 67983 | E25: 157 | F25: 923 | G25: 313 | I25: bitte hier nur die jährlichen Rechnungen als PDF zusenden - Daten werden eingetragen | M25: 2554989.3
A26: 42036 | B26: 2996 | C26: 32869.5 | D26: 93756 | E26: 201 | F26: 938 | G26: 381 | I26: 8160 | J26: 370.21455 | K26: 25773 | L26: 1659.24 | M26: 2566447.4
A27: 42064 | B27: 3674 | C27: 40578.7 | D27: 116444 | E27: 249 | F27: 942 | G27: 466 | I27: 10200 | J27: 462.76818 | K27: 22688 | L27: 1460.6308 | M27: 2579459.2
A28: 42095 | B28: 4326 | C28: 47720 | D28: 137129 | E28: 294 | F28: 990 | G28: 516 | I28: 6000 | J28: 272.21658 | K28: 20685 | L28: 1331.6796 | M28: 2589152.6
A29: 42125 | B29: 4760 | C29: 52391.53 | D29: 150523 | E29: 323 | F29: 1071 | G29: 567 | I29: 6120 | J29: 257.85169 | K29: 13394 | L29: 862.29233 | M29: 2595544.1
A30: 42156 | B30: 4987 | C30: 54807.5 | D30: 157375 | E30: 338 | F30: 1168 | G30: 600 | I30: 3960 | J30: 166.84521 | K30: 6852 | L30: 441.12491 | M30: 2598595.5
A31: 42186 | B31: 5232 | C31: 57517.71 | D31: 165124 | E31: 355 | F31: 1294 | G31: 633 | I31: 3960 | J31: 166.84521 | K31: 7749 | L31: 498.87287 | M31: 2601468.2
A32: 42217 | B32: 5395 | C32: 59427.19 | D32: 170490 | E32: 367 | F32: 1399 | G32: 658 | I32: 3000 | J32: 113.01039 | K32: 5366 | L32: 345.45771 | M32: 2603757.6
A33: 42248 | B33: 5467 | C33: 60069.46 | D33: 172269 | E33: 374 | F33: 1451 | G33: 669 | I33: 1320 | J33: 49.724571 | K33: 1779 | L33: 114.53024 | M33: 2605297.7
A34: 42278 | B34: 5918 | C34: 64911.8 | D34: 186093 | E34: 404 | F34: 1567 | G34: 726 | I34: 6840 | J34: 257.66369 | K34: 13824 | L34: 889.9753 | M34: 2610168.7
A35: 42309 | B35: 6555 | C35: 72293.54 | D35: 207520 | E35: 450.62 | F35: 1622 | G35: 790 | I35: 7680 | J35: 330.34161 | K35: 21427 | L35: 1379.4488 | M35: 2618174.2
A36: 42339 | B36: 7161.4335 | C36: 79040.38 | D36: 227056 | E36: 493.16 | F36: 1741.8104 | G36: 842.9 | I36: 6348 | J36: 273.04798 | K36: 19536 | L36: 1257.7081 | M36: 2626970.1
A37: 42370 | B37: 8065.8456 | C37: 89022.33 | D37: 256123 | E37: 555.82 | F37: 1963.1216 | G37: 988 | I37: 17412 | J37: 748.94636 | K37: 29067 | L37: 1871.3044 | M37: 2640719.2 | N37: 906942 | O37: 50063.44 | R37: 63620 | S37: 24815.39
A38: 42402 | B38: =+$B$52/$C$52*C38 -> 8295.2252 | C38: 95099.4 | D38: 273880 | E38: 594.13 | G38: 1009.5 | M38: 2650552.4
A39: 42430 | B39: =+$B$52/$C$52*C39 -> 8979.4504 | C39: 102943.6 | D39: 296514 | E39: 643.08 | G39: 1072.5 | M39: 2661835.3
A40: 42461 | B40: =+$B$52/$C$52*C40 -> 9728.5323 | C40: 111531.34 | D40: 321376 | E40: 696.76 | G40: 1156 | M40: 2672823.1
...

Sheet Unterlagenübersicht
B3: Unterlagen
B5: Kunde: | C5: =+Verbrauchsdaten!B2 -> Schulstiftung der Evangelischen Landeskirche in Württemberg
B6: Anlage: | C6: =+Verbrauchsdaten!B4 -> Lichtenstern Gymnasium
B7: BHKW Type: | C7: =+Verbrauchsdaten!B7 -> Kraftwerk Mephisto
B9: 1.1 Überprüfung des BHKW Konzepts auf Basis der vom Kunden übermittelten | D9: erhalten am:
B10: Anlagenschema mit Puffer, Kessel und Heizkreiseinbindung sowie allen einzubauenden Zählern
B11: Regelungsschema
B12: Lageplan Standort
B13: Beschreibung der Regelungsabläufe (1)
B14: technische Datenblätter der Komponenten
B15: Grundlagen für die Konzeption: Verbrauchsdaten, Geordnete Jahresdauerlinie Wärme
B17: 1.2 Überprüfung des Wartungsvertrages
B18: Wartungsvertragsentwurf
B19: abgeschlossener Wartungsvertrag
B20: erwartete Betriebsstunden
B21: Beschreibung der geplanten Fahrweise (2)
B23: 2.1 Optimierung und Überwachung des Betriebs
... B25: Abrechnung KWK-Bonus
B26: Abrechnung eingspeister Strom | D26: 42319
B27: Abrechnung Messung für BHKW | D27: 42319
B28: Abrechnungen Strombezug
B29: Abrechnungen Erdgasbezug
B30: Inbetriebnahme-Protokoll
B31: Informationen über Veränderungen bei Nutzung, Einkauf und Struktur
B33: 2.2 Überprüfung der Wartungskosten
B34: Wartungsrechnungen | D34: 42319
B35: ausgefüllte Exceldatei mit monatlichen Zählerständen
B36: Informationen über besondere Vorkommnisse
B38: 2.3 Vorbereitung der jährlichen Anträge und Mitteilung
B39: Hocheffizienznachweis
B40: Zulassungsbestätigung der BAFA
B41: ausgefüllte Exceldatei mit monatlichen Zählerständen
B43: 2.4 Wirtschaftlichkeits- und Energiebericht
B44: Investitions- und Betriebskosten
B45: ausgefüllte Exceldatei mit monatlichen Zählerständen
B46: Energie- und Wartungsrechnungen
B49: 1. Beschreibung der Regelungsabläufe mit folgendem Inhalt: Wo sind die Fühler (mit Bezeichnung) eingebaut, was wird gemessen, bei welchen Temperaturen erfolgen welche Regeleingriffe bzw. Schaltungen, wie sind die Heizkessel in die Regelung eingebunden, welche sonstige Parameter wirken auf die Regelung ein z.B. Zeit, Stromspitzen...
B50: 2. Beschreibung der geplanten Fahrweise mit folgendem Inhalt: Welche Priorität haben die einzelen Wärmeerzeuger, welche saisionale Regelstrategien sind geplant, wie wird der erzeugte Strom verwendet…
