Workbook

Sheet Ablesewerte Gas
A1: Gas
A2: 2005 | B2: m³ | C2: Jan | D2: Feb | E2: Mrz | F2: Apr | G2: Mai | H2: Jun | I2: Jul | J2: Aug | K2: Sep | L2: Okt | M2: Nov | N2: Dez
C3: 38362 | D3: 1.2. | E3: 1.3. | F3: 1.4. | G3: 2.5. | H3: 1.6. | I3: 1.7. | J3: 28.7. | K3: 1.9. | L3: 5.10. | M3: 7.11. | N3: 1.12. | O3: 38726
A4: Hauptzähler Internat | C4: 1912734.7 | D4: 1922570.4 | E4: 1933497.4 | F4: 1941579.1 | G4: 1946480.8 | H4: 1949124.6 | I4: 1950733.2 | J4: 1952022.1 | K4: 1953436.4 | L4: 1955850.8 | M4: 1960502.7 | N4: 1968762.6 | O4: 1981729.5 | Q4: =SUM(O4-C4) -> 68994.8
A5: Zwischenzähler Küche | E5: 27.15 | F5: 68.48 | G5: 110.81 | H5: 139.4 | I5: 188.1 | J5: 228 | K5: 283.61 | L5: 340.14 | M5: 397.39 | N5: 455.14 | O5: 499.22 | R5: 499.22 | S5: (Küche ab Feb)
A6: alte Aula | C6: 62778.22 | D6: 63714.25 | E6: 64709.86 | F6: 65696.31 | G6: 66374.47 | H6: 66526.93 | I6: 66526.93 | J6: 66526.93 | K6: 66526.93 | L6: 66567.49 | M6: 67120.98 | N6: 68103.25 | O6: 69566 | Q6: =SUM(O6-C6) -> 6787.78
A7: Lichtenstern 13 | C7: 3549.655 | D7: 4443.864 | E7: 5443.076 | F7: 6418.824 | G7: 6948.7 | H7: 7243.88 | I7: 7448.3 | J7: 7607.76 | K7: 7772.41 | L7: 8067.54 | M7: 8593.67 | N7: 9409.27 | O7: 10746.02 | Q7: =SUM(O7-C7) -> 7196.365
A8: Schulleiterhaus*
A11: nicht abgelesene Werte
A12: Wert stammt aus Abrechnung
A13: am 5.11. wurde der Zähler erneuert
A16: 2006 | B16: m³ | C16: Jan | D16: Feb | E16: Mrz | F16: Apr | G16: Mai | H16: Jun | I16: Jul | J16: Aug | K16: Sep | L16: Okt | M16: Nov | N16: Dez | Q16: Gesamtverbrauch
C17: 38726 | D17: 1.2. | E17: 6.3. | F17: 4.4. | G17: 3.5. | H17: 1.6. | I17: 3.7. | J17: 7.8. | K17: 1.9. | L17: 4.10. | M17: 2.11. | N17: 1.12. | O17: 39073
A18: Hauptzähler Internat | C18: 1981729.5 | D18: 1992110.2 | E18: 2003860.5 | F18: 2011800.4 | G18: 2016015.8 | H18: 2018288.8 | I18: 2020238.1 | J18: 2021738.6 | K18: 2023309.4 | L18: 2025122.3 | M18: 2028569.4 | N18: 2035133.5 | O18: 2041124.6 | Q18: =SUM(O18-C18) -> 59395.1
A19: Zwischenzähler Küche | C19: 499.22 | D19: 550.7 | E19: 608.36 | F19: 671.46 | G19: 711.82 | H19: 747.46 | I19: 801.75 | J19: 855.74 | K19: 903.69 | L19: 943.56 | M19: 1000.79 | N19: 1071.31 | O19: 1118.64 | R19: =SUM(O19-C19) -> 619.42 | S19: (Küche)
A20: alte Aula | C20: 69566 | D20: 70875.3 | E20: 72517.07 | F20: 73551.12 | G20: 73688.91 | H20: 73688.91 | I20: 73688.91 | J20: 73688.91 | K20: 73688.91 | L20: 73688.91 | M20: 172410 | N20: 173117.62 | O20: 173744.21 | P20: ** | Q20: =SUM(O20-M20+L20-C20) -> 5457.12
A21: Lichtenstern 13 | C21: 10746.02 | D21: 11879.9 | E21: 13234.193 | F21: 14184.05 | G21: 14679.06 | H21: 14944.02 | I21: 15160.3 | J21: 15318.68 | K21: 15442.529 | L21: 15634.317 | M21: 16047.453 | N21: 16788.87 | O21: 17392.125 | Q21: =SUM(O21-C21) -> 6646.105
A22: Schulleiterhaus* | O22: 50493.3
A24: * wird direkt abgerechnet
A25: ** Zählerwechsel / neue Heizung
A28: 2007 | B28: m³ | C28: Jan | D28: Feb | E28: Mrz | F28: Apr | G28: Mai | H28: Jun | I28: Jul | J28: Aug | K28: Sep | L28: Okt | M28: Nov | N28: Dez
C29: 39073 | D29: 1.2. | E29: 1.3. | F29: 3.4. | G29: 2.5. | H29: 5.6. | I29: 2.7. | J29: 13.8. | K29: 3.9. | L29: 29.9. | M29: 6.11. | N29: 3.12. | O29: 39454
A30: Hauptzähler Internat | C30: 2041124.6 | D30: 2052151.6 | E30: 2059719.1 | F30: 2067240.5 | G30: 2069893.6 | H30: 2072691 | I30: 2074219.7 | J30: 2076437.6 | K30: 2077293.1 | L30: 2079812 | M30: 2085850.3 | N30: 2094379.4 | O30: 2106415.1 | Q30: =SUM(O30-C30) -> 65290.5
A31: Zwischenzähler Küche | C31: 1118.64 | D31: 1178.23 | E31: 1239.3 | F31: 1332.27 | G31: 1373.1 | H31: 1425.13 | I31: 1474.49 | J31: 1559.22 | K31: 1559.23 | L31: 1609.7 | M31: 1666.16 | N31: 1730.85 | O31: 1780.4 | R31: =SUM(O31-C31) -> 661.76 | S31: (Küche)
A32: alte Aula | C32: 173744.21 | D32: 174889.52 | E32: 175592.75 | F32: 176272.24 | G32: 176448.9 | H32: 176570.08 | I32: 176570.14 | J32: 176570.15 | K32: 176570.19 | L32: 176762.8 | M32: 177166.92 | N32: 177816.72 | O32: 178801.97 | Q32: =SUM(O32-C32) -> 5057.76
A33: Lichtenstern 13 | C33: 17392.125 | D33: 18542.67 | E33: 19341.64 | F33: 20116.05 | G33: 20397.63 | H33: 20667.84 | I33: 20838.72 | J33: 21071.36 | K33: 21185.01 | L33: 21477.36 | M33: 22166.4 | N33: 23088.25 | O33: 24388.83 | Q33: =SUM(O33-C33) -> 6996.705
A36: 2008 | B36: m³ | C36: Jan | D36: Feb | E36: Mrz | F36: Apr | G36: Mai | H36: Jun | I36: Jul | J36: Aug | K36: Sep | L36: Okt | M36: Nov | N36: Dez
C37: 39454 | D37: 1.2. | E37: 3.3. | F37: 1.4. | G37: 30.4. | H37: 2.6. | I37: 1.7. | J37: 4.8. | K37: 2.9. | L37: 1.10. | M37: 3.11. | N37: 2.12. | O37: 39805
A38: Hauptzähler Internat | C38: 2106415.1 | D38: 2114392.2 | E38: 2122386.4 | F38: 2128461.4 | G38: 2133867.3 | H38: 2135880.7 | I38: 2137451 | J38: 2138994.9 | K38: 2140024.7 | L38: 2142917.3 | M38: 2147514.4 | N38: 2155230.9 | O38: 2162066.8 | Q38: =SUM(O38-C38) -> 55651.7
A39: Zwischenzähler Küche | C39: 1780.4 | D39: 1853.65 | E39: 1910.75 | F39: 1957.4 | G39: 2045.55 | H39: 2097.1 | I39: 2165.52 | J39: 2216.54 | K39: 2255.31 | L39: 2347.07 | M39: 2403.5 | N39: 2498.3 | O39: 2554.19 | R39: =SUM(O39-C39) -> 773.79 | S39: (Küche)
A40: alte Aula | C40: 178801.97 | D40: 179460.3 | E40: 180128.91 | F40: 180668.59 | G40: 181048.2 | H40: 181073.95 | I40: 181073.95 | J40: 181073.95 | K40: 181073.94 | L40: 181224.2 | M40: 181564.4 | N40: 182170.57 | O40: 182717.2 | Q40: =SUM(O40-C40) -> 3915.23
A41: Lichtenstern 13 | C41: 24388.83 | D41: 25260 | E41: 26176.86 | F41: 26834.94 | G41: 27533.23 | H41: 27729.38 | I41: 27846.06 | J41: 27957.24 | K41: 28040.8 | L41: 28361.24 | M41: 28861.77 | N41: 29596.7 | O41: 30256.97 | Q41: =SUM(O41-C41) -> 5868.14
A44: 2009 | B44: m³ | C44: Jan | D44: Feb | E44: Mrz | F44: Apr | G44: Mai | H44: Jun | I44: Jul | J44: Aug | K44: Sep | L44: Okt | M44: Nov | N44: Dez
C45: 39805 | D45: 39846 | E45: 39874 | F45: 39904 | G45: 39933 | H45: 39966 | I45: 39996 | J45: 40024 | K45: 40057 | L45: 40088 | M45: 40119 | N45: 40148 | O45: 40170
A46: Hauptzähler Internat | C46: 2162066.8 | D46: 2177160.9 | E46: 2186334.4 | F46: 2194175 | G46: 2197006.2 | H46: 2199333.4 | I46: 2201202 | J46: 2202639.4 | K46: 2204082.9 | L46: 2206268.3 | M46: 2211097 | N46: 2217445.1 | O46: 2225184 | Q46: =SUM(O46-C46) -> 63117.2
A47: Zwischenzähler Küche | C47: 2554.19 | D47: 2614.48 | E47: 2674.37 | F47: 2780.33 | G47: 2843.1 | H47: 2894.35 | I47: 2968.65 | J47: 3034.81 | K47: 3102.1 | L47: 3190.6 | M47: 3262.61 | N47: 3381.68 | O47: 3487.6 | R47: =SUM(O47-C47) -> 933.41 | S47: (Küche)
A48: alte Aula | C48: 182717.2 | D48: 184177.8 | E48: 184891.26 | F48: 185475.02 | G48: 185575.9 | H48: 185625.65 | I48: 185625.65 | J48: 185625.6 | K48: 185625.6 | L48: 185657.98 | M48: 185934.74 | N48: 186348.66 | O48: 187020.91 | Q48: =SUM(O48-C48) -> 4303.71
A49: Lichtenstern 13 | C49: 30256.97 | D49: 31743.96 | E49: 32664.5 | F49: 33523.12 | G49: 33855.62 | H49: 34146.867 | I49: 34366.274 | J49: 34541.46 | K49: 34644.26 | L49: 34889.442 | M49: 35455.78 | N49: 36236.35 | O49: 37054.745 | Q49: =SUM(O49-C49) -> 6797.775
A52: 2010 | B52: m³ | C52: Jan | D52: Feb | E52: Mrz | F52: Apr | G52: Mai | H52: Jun | I52: Jul | J52: Aug | K52: Sep | L52: Okt | M52: Nov | N52: Dez
C53: 40170 | D53: 40210 | E53: 40238 | F53: 40269 | G53: 40301 | H53: 40319 | I53: 40360 | J53: 40392 | K53: 40422 | L53: 40452 | M53: 40484 | N53: 40513 | O53: 40543
...

Sheet Verbrauch Gas
A1: Verbrauch Gas
A2: ='Ablesewerte Gas'!A2 -> 2005 | B2: ='Ablesewerte Gas'!B2 -> m³ | C2: ='Ablesewerte Gas'!C2 -> Jan | D2: ='Ablesewerte Gas'!D2 -> Feb | E2: ='Ablesewerte Gas'!E2 -> Mrz | F2: ='Ablesewerte Gas'!F2 -> Apr | G2: ='Ablesewerte Gas'!G2 -> Mai | H2: ='Ablesewerte Gas'!H2 -> Jun | ... N2: ='Ablesewerte Gas'!N2 -> Dez
A4: ='Ablesewerte Gas'!A4 -> Hauptzähler Internat | C4: =SUM('Ablesewerte Gas'!D4-'Ablesewerte Gas'!C4) -> 9835.7 | D4: =SUM('Ablesewerte Gas'!E4-'Ablesewerte Gas'!D4) -> 10927 | E4: =SUM('Ablesewerte Gas'!F4-'Ablesewerte Gas'!E4) -> 8081.7 | F4: =SUM('Ablesewerte Gas'!G4-'Ablesewerte Gas'!F4) -> 4901.7 | G4: =SUM('Ablesewerte Gas'!H4-'Ablesewerte Gas'!G4) -> 2643.8 | H4: =SUM('Ablesewerte Gas'!I4-'Ablesewerte Gas'!H4) -> 1608.6 | I4: =SUM('Ablesewerte Gas'!J4-'Ablesewerte Gas'!I4) -> 1288.9 | J4: =SUM('Ablesewerte Gas'!K4-'Ablesewerte Gas'!J4) -> 1414.3 | ... N4: =SUM('Ablesewerte Gas'!O4-'Ablesewerte Gas'!N4) -> 12966.9
A5: ='Ablesewerte Gas'!A5 -> Zwischenzähler Küche | C5: 0 | D5: =SUM('Ablesewerte Gas'!E5-'Ablesewerte Gas'!D5) -> 27.15 | E5: =SUM('Ablesewerte Gas'!F5-'Ablesewerte Gas'!E5) -> 41.33 | F5: =SUM('Ablesewerte Gas'!G5-'Ablesewerte Gas'!F5) -> 42.33 | G5: =SUM('Ablesewerte Gas'!H5-'Ablesewerte Gas'!G5) -> 28.59 | H5: =SUM('Ablesewerte Gas'!I5-'Ablesewerte Gas'!H5) -> 48.7 | I5: =SUM('Ablesewerte Gas'!J5-'Ablesewerte Gas'!I5) -> 39.9 | J5: =SUM('Ablesewerte Gas'!K5-'Ablesewerte Gas'!J5) -> 55.61 | K5: =SUM('Ablesewerte Gas'!L5-'Ablesewerte Gas'!K5) -> 56.53 | ... N5: =SUM('Ablesewerte Gas'!O5-'Ablesewerte Gas'!N5) -> 44.08
A6: ='Ablesewerte Gas'!A6 -> alte Aula | C6: =SUM('Ablesewerte Gas'!D6-'Ablesewerte Gas'!C6) -> 936.03 | D6: =SUM('Ablesewerte Gas'!E6-'Ablesewerte Gas'!D6) -> 995.61 | E6: =SUM('Ablesewerte Gas'!F6-'Ablesewerte Gas'!E6) -> 986.45 | F6: =SUM('Ablesewerte Gas'!G6-'Ablesewerte Gas'!F6) -> 678.16 | G6: =SUM('Ablesewerte Gas'!H6-'Ablesewerte Gas'!G6) -> 152.46 | H6: =SUM('Ablesewerte Gas'!I6-'Ablesewerte Gas'!H6) -> 0 | I6: =SUM('Ablesewerte Gas'!J6-'Ablesewerte Gas'!I6) -> 0 | J6: =SUM('Ablesewerte Gas'!K6-'Ablesewerte Gas'!J6) -> 0 | ... N6: =SUM('Ablesewerte Gas'!O6-'Ablesewerte Gas'!N6) -> 1462.75
A7: ='Ablesewerte Gas'!A7 -> Lichtenstern 13 | C7: =SUM('Ablesewerte Gas'!D7-'Ablesewerte Gas'!C7) -> 894.209 | D7: =SUM('Ablesewerte Gas'!E7-'Ablesewerte Gas'!D7) -> 999.212 | E7: =SUM('Ablesewerte Gas'!F7-'Ablesewerte Gas'!E7) -> 975.748 | F7: =SUM('Ablesewerte Gas'!G7-'Ablesewerte Gas'!F7) -> 529.876 | G7: =SUM('Ablesewerte Gas'!H7-'Ablesewerte Gas'!G7) -> 295.18 | H7: =SUM('Ablesewerte Gas'!I7-'Ablesewerte Gas'!H7) -> 204.42 | I7: =SUM('Ablesewerte Gas'!J7-'Ablesewerte Gas'!I7) -> 159.46 | J7: =SUM('Ablesewerte Gas'!K7-'Ablesewerte Gas'!J7) -> 164.65 | ... N7: =SUM('Ablesewerte Gas'!O7-'Ablesewerte Gas'!N7) -> 1336.75 | P7: =SUM(C7:O7) -> 7196.365
A10: ='Ablesewerte Gas'!A16 -> 2006 | B10: ='Ablesewerte Gas'!B16 -> m³ | C10: ='Ablesewerte Gas'!C16 -> Jan | D10: ='Ablesewerte Gas'!D16 -> Feb | E10: ='Ablesewerte Gas'!E16 -> Mrz | F10: ='Ablesewerte Gas'!F16 -> Apr | G10: ='Ablesewerte Gas'!G16 -> Mai | H10: ='Ablesewerte Gas'!H16 -> Jun | ... N10: ='Ablesewerte Gas'!N16 -> Dez
A12: ='Ablesewerte Gas'!A18 -> Hauptzähler Internat | C12: ='Ablesewerte Gas'!D18-'Ablesewerte Gas'!C18 -> 10380.7 | D12: ='Ablesewerte Gas'!E18-'Ablesewerte Gas'!D18 -> 11750.3 | E12: ='Ablesewerte Gas'!F18-'Ablesewerte Gas'!E18 -> 7939.9 | F12: ='Ablesewerte Gas'!G18-'Ablesewerte Gas'!F18 -> 4215.4 | G12: ='Ablesewerte Gas'!H18-'Ablesewerte Gas'!G18 -> 2273 | H12: ='Ablesewerte Gas'!I18-'Ablesewerte Gas'!H18 -> 1949.3 | I12: ='Ablesewerte Gas'!J18-'Ablesewerte Gas'!I18 -> 1500.5 | J12: ='Ablesewerte Gas'!K18-'Ablesewerte Gas'!J18 -> 1570.8 | ... N12: ='Ablesewerte Gas'!O18-'Ablesewerte Gas'!N18 -> 5991.1
A13: ='Ablesewerte Gas'!A19 -> Zwischenzähler Küche | C13: ='Ablesewerte Gas'!D19-'Ablesewerte Gas'!C19 -> 51.48 | D13: ='Ablesewerte Gas'!E19-'Ablesewerte Gas'!D19 -> 57.66 | E13: ='Ablesewerte Gas'!F19-'Ablesewerte Gas'!E19 -> 63.1 | F13: ='Ablesewerte Gas'!G19-'Ablesewerte Gas'!F19 -> 40.36 | G13: ='Ablesewerte Gas'!H19-'Ablesewerte Gas'!G19 -> 35.64 | H13: ='Ablesewerte Gas'!I19-'Ablesewerte Gas'!H19 -> 54.29 | I13: ='Ablesewerte Gas'!J19-'Ablesewerte Gas'!I19 -> 53.99 | J13: ='Ablesewerte Gas'!K19-'Ablesewerte Gas'!J19 -> 47.95 | ... N13: ='Ablesewerte Gas'!O19-'Ablesewerte Gas'!N19 -> 47.33
A14: ='Ablesewerte Gas'!A20 -> alte Aula | B14: ** | C14: ='Ablesewerte Gas'!D20-'Ablesewerte Gas'!C20 -> 1309.3 | D14: ='Ablesewerte Gas'!E20-'Ablesewerte Gas'!D20 -> 1641.77 | E14: ='Ablesewerte Gas'!F20-'Ablesewerte Gas'!E20 -> 1034.05 | F14: ='Ablesewerte Gas'!G20-'Ablesewerte Gas'!F20 -> 137.79 | G14: ='Ablesewerte Gas'!H20-'Ablesewerte Gas'!G20 -> 0 | H14: ='Ablesewerte Gas'!I20-'Ablesewerte Gas'!H20 -> 0 | I14: ='Ablesewerte Gas'!J20-'Ablesewerte Gas'!I20 -> 0 | J14: ='Ablesewerte Gas'!K20-'Ablesewerte Gas'!J20 -> 0 | K14: ='Ablesewerte Gas'!L20-'Ablesewerte Gas'!K20 -> 0 | L14: 0 | M14: ='Ablesewerte Gas'!N20-'Ablesewerte Gas'!M20 -> 707.62 | N14: ='Ablesewerte Gas'!O20-'Ablesewerte Gas'!N20 -> 626.59
A15: ='Ablesewerte Gas'!A21 -> Lichtenstern 13 | C15: ='Ablesewerte Gas'!D21-'Ablesewerte Gas'!C21 -> 1133.88 | D15: ='Ablesewerte Gas'!E21-'Ablesewerte Gas'!D21 -> 1354.293 | E15: ='Ablesewerte Gas'!F21-'Ablesewerte Gas'!E21 -> 949.857 | F15: ='Ablesewerte Gas'!G21-'Ablesewerte Gas'!F21 -> 495.01 | G15: ='Ablesewerte Gas'!H21-'Ablesewerte Gas'!G21 -> 264.96 | H15: ='Ablesewerte Gas'!I21-'Ablesewerte Gas'!H21 -> 216.28 | I15: ='Ablesewerte Gas'!J21-'Ablesewerte Gas'!I21 -> 158.38 | J15: ='Ablesewerte Gas'!K21-'Ablesewerte Gas'!J21 -> 123.849 | ... N15: ='Ablesewerte Gas'!O21-'Ablesewerte Gas'!N21 -> 603.255 | P15: =SUM(C15:O15) -> 6646.105
A17: ='Ablesewerte Gas'!A25 -> ** Zählerwechsel / neue Heizung
A19: ='Ablesewerte Gas'!A28 -> 2007 | B19: ='Ablesewerte Gas'!B28 -> m³ | C19: ='Ablesewerte Gas'!C28 -> Jan | D19: ='Ablesewerte Gas'!D28 -> Feb | E19: ='Ablesewerte Gas'!E28 -> Mrz | F19: ='Ablesewerte Gas'!F28 -> Apr | G19: ='Ablesewerte Gas'!G28 -> Mai | H19: ='Ablesewerte Gas'!H28 -> Jun | ... N19: ='Ablesewerte Gas'!N28 -> Dez
A21: ='Ablesewerte Gas'!A30 -> Hauptzähler Internat | C21: =SUM('Ablesewerte Gas'!D30-'Ablesewerte Gas'!C30) -> 11027 | D21: =SUM('Ablesewerte Gas'!E30-'Ablesewerte Gas'!D30) -> 7567.5 | E21: =SUM('Ablesewerte Gas'!F30-'Ablesewerte Gas'!E30) -> 7521.4 | F21: =SUM('Ablesewerte Gas'!G30-'Ablesewerte Gas'!F30) -> 2653.1 | G21: =SUM('Ablesewerte Gas'!H30-'Ablesewerte Gas'!G30) -> 2797.4 | H21: =SUM('Ablesewerte Gas'!I30-'Ablesewerte Gas'!H30) -> 1528.7 | I21: =SUM('Ablesewerte Gas'!J30-'Ablesewerte Gas'!I30) -> 2217.9 | J21: =SUM('Ablesewerte Gas'!K30-'Ablesewerte Gas'!J30) -> 855.5 | ... N21: =SUM('Ablesewerte Gas'!O30-'Ablesewerte Gas'!N30) -> 12035.7 | P21: =SUM(C21:O21) -> 65290.5
A22: ='Ablesewerte Gas'!A31 -> Zwischenzähler Küche | C22: =SUM('Ablesewerte Gas'!D31-'Ablesewerte Gas'!C31) -> 59.59 | D22: =SUM('Ablesewerte Gas'!E31-'Ablesewerte Gas'!D31) -> 61.07 | E22: =SUM('Ablesewerte Gas'!F31-'Ablesewerte Gas'!E31) -> 92.97 | F22: =SUM('Ablesewerte Gas'!G31-'Ablesewerte Gas'!F31) -> 40.83 | G22: =SUM('Ablesewerte Gas'!H31-'Ablesewerte Gas'!G31) -> 52.03 | H22: =SUM('Ablesewerte Gas'!I31-'Ablesewerte Gas'!H31) -> 49.36 | I22: =SUM('Ablesewerte Gas'!J31-'Ablesewerte Gas'!I31) -> 84.73 | J22: =SUM('Ablesewerte Gas'!K31-'Ablesewerte Gas'!J31) -> 0.01 | ... N22: =SUM('Ablesewerte Gas'!O31-'Ablesewerte Gas'!N31) -> 49.55 | P22: =SUM(C22:O22) -> 661.76
A23: ='Ablesewerte Gas'!A32 -> alte Aula | C23: =SUM('Ablesewerte Gas'!D32-'Ablesewerte Gas'!C32) -> 1145.31 | D23: =SUM('Ablesewerte Gas'!E32-'Ablesewerte Gas'!D32) -> 703.23 | E23: =SUM('Ablesewerte Gas'!F32-'Ablesewerte Gas'!E32) -> 679.49 | F23: =SUM('Ablesewerte Gas'!G32-'Ablesewerte Gas'!F32) -> 176.66 | G23: =SUM('Ablesewerte Gas'!H32-'Ablesewerte Gas'!G32) -> 121.18 | H23: =SUM('Ablesewerte Gas'!I32-'Ablesewerte Gas'!H32) -> 0.06 | I23: =SUM('Ablesewerte Gas'!J32-'Ablesewerte Gas'!I32) -> 0.01 | J23: =SUM('Ablesewerte Gas'!K32-'Ablesewerte Gas'!J32) -> 0.04 | ... N23: =SUM('Ablesewerte Gas'!O32-'Ablesewerte Gas'!N32) -> 985.25 | P23: =SUM(C23:O23) -> 5057.76
A24: ='Ablesewerte Gas'!A33 -> Lichtenstern 13 | C24: =SUM('Ablesewerte Gas'!D33-'Ablesewerte Gas'!C33) -> 1150.545 | D24: =SUM('Ablesewerte Gas'!E33-'Ablesewerte Gas'!D33) -> 798.97 | E24: =SUM('Ablesewerte Gas'!F33-'Ablesewerte Gas'!E33) -> 774.41 | F24: =SUM('Ablesewerte Gas'!G33-'Ablesewerte Gas'!F33) -> 281.58 | G24: =SUM('Ablesewerte Gas'!H33-'Ablesewerte Gas'!G33) -> 270.21 | H24: =SUM('Ablesewerte Gas'!I33-'Ablesewerte Gas'!H33) -> 170.88 | I24: =SUM('Ablesewerte Gas'!J33-'Ablesewerte Gas'!I33) -> 232.64 | J24: =SUM('Ablesewerte Gas'!K33-'Ablesewerte Gas'!J33) -> 113.65 | ... N24: =SUM('Ablesewerte Gas'!O33-'Ablesewerte Gas'!N33) -> 1300.58 | P24: =SUM(C24:O24) -> 6996.705
A27: ='Ablesewerte Gas'!A36 -> 2008 | B27: ='Ablesewerte Gas'!B36 -> m³ | C27: ='Ablesewerte Gas'!C36 -> Jan | D27: ='Ablesewerte Gas'!D36 -> Feb | E27: ='Ablesewerte Gas'!E36 -> Mrz | F27: ='Ablesewerte Gas'!F36 -> Apr | G27: ='Ablesewerte Gas'!G36 -> Mai | H27: ='Ablesewerte Gas'!H36 -> Jun | ... N27: ='Ablesewerte Gas'!N36 -> Dez
A29: ='Ablesewerte Gas'!A38 -> Hauptzähler Internat | C29: =SUM('Ablesewerte Gas'!D38-'Ablesewerte Gas'!C38) -> 7977.1 | D29: =SUM('Ablesewerte Gas'!E38-'Ablesewerte Gas'!D38) -> 7994.2 | E29: =SUM('Ablesewerte Gas'!F38-'Ablesewerte Gas'!E38) -> 6075 | F29: =SUM('Ablesewerte Gas'!G38-'Ablesewerte Gas'!F38) -> 5405.9 | G29: =SUM('Ablesewerte Gas'!H38-'Ablesewerte Gas'!G38) -> 2013.4 | H29: =SUM('Ablesewerte Gas'!I38-'Ablesewerte Gas'!H38) -> 1570.3 | I29: =SUM('Ablesewerte Gas'!J38-'Ablesewerte Gas'!I38) -> 1543.9 | J29: =SUM('Ablesewerte Gas'!K38-'Ablesewerte Gas'!J38) -> 1029.8 | ... N29: =SUM('Ablesewerte Gas'!O38-'Ablesewerte Gas'!N38) -> 6835.9 | P29: =SUM(C29:O29) -> 55651.7
A30: ='Ablesewerte Gas'!A39 -> Zwischenzähler Küche | C30: =SUM('Ablesewerte Gas'!D39-'Ablesewerte Gas'!C39) -> 73.25 | D30: =SUM('Ablesewerte Gas'!E39-'Ablesewerte Gas'!D39) -> 57.1 | E30: =SUM('Ablesewerte Gas'!F39-'Ablesewerte Gas'!E39) -> 46.65 | F30: =SUM('Ablesewerte Gas'!G39-'Ablesewerte Gas'!F39) -> 88.15 | G30: =SUM('Ablesewerte Gas'!H39-'Ablesewerte Gas'!G39) -> 51.55 | H30: =SUM('Ablesewerte Gas'!I39-'Ablesewerte Gas'!H39) -> 68.42 | I30: =SUM('Ablesewerte Gas'!J39-'Ablesewerte Gas'!I39) -> 51.02 | J30: =SUM('Ablesewerte Gas'!K39-'Ablesewerte Gas'!J39) -> 38.77 | ... N30: =SUM('Ablesewerte Gas'!O39-'Ablesewerte Gas'!N39) -> 55.89 | P30: =SUM(C30:O30) -> 773.79
A31: ='Ablesewerte Gas'!A40 -> alte Aula | C31: =SUM('Ablesewerte Gas'!D40-'Ablesewerte Gas'!C40) -> 658.33 | D31: =SUM('Ablesewerte Gas'!E40-'Ablesewerte Gas'!D40) -> 668.61 | E31: =SUM('Ablesewerte Gas'!F40-'Ablesewerte Gas'!E40) -> 539.68 | F31: =SUM('Ablesewerte Gas'!G40-'Ablesewerte Gas'!F40) -> 379.61 | G31: =SUM('Ablesewerte Gas'!H40-'Ablesewerte Gas'!G40) -> 25.75 | H31: =SUM('Ablesewerte Gas'!I40-'Ablesewerte Gas'!H40) -> 0 | I31: =SUM('Ablesewerte Gas'!J40-'Ablesewerte Gas'!I40) -> 0 | J31: =SUM('Ablesewerte Gas'!K40-'Ablesewerte Gas'!J40) -> -0.01 | ... N31: =SUM('Ablesewerte Gas'!O40-'Ablesewerte Gas'!N40) -> 546.63 | P31: =SUM(C31:O31) -> 3915.23
A32: ='Ablesewerte Gas'!A41 -> Lichtenstern 13 | C32: =SUM('Ablesewerte Gas'!D41-'Ablesewerte Gas'!C41) -> 871.17 | D32: =SUM('Ablesewerte Gas'!E41-'Ablesewerte Gas'!D41) -> 916.86 | E32: =SUM('Ablesewerte Gas'!F41-'Ablesewerte Gas'!E41) -> 658.08 | F32: =SUM('Ablesewerte Gas'!G41-'Ablesewerte Gas'!F41) -> 698.29 | G32: =SUM('Ablesewerte Gas'!H41-'Ablesewerte Gas'!G41) -> 196.15 | H32: =SUM('Ablesewerte Gas'!I41-'Ablesewerte Gas'!H41) -> 116.68 | I32: =SUM('Ablesewerte Gas'!J41-'Ablesewerte Gas'!I41) -> 111.18 | J32: =SUM('Ablesewerte Gas'!K41-'Ablesewerte Gas'!J41) -> 83.56 | ... N32: =SUM('Ablesewerte Gas'!O41-'Ablesewerte Gas'!N41) -> 660.27 | P32: =SUM(C32:O32) -> 5868.14
A35: ='Ablesewerte Gas'!A44 -> 2009 | B35: ='Ablesewerte Gas'!B44 -> m³ | C35: ='Ablesewerte Gas'!C44 -> Jan | D35: ='Ablesewerte Gas'!D44 -> Feb | E35: ='Ablesewerte Gas'!E44 -> Mrz | F35: ='Ablesewerte Gas'!F44 -> Apr | G35: ='Ablesewerte Gas'!G44 -> Mai | H35: ='Ablesewerte Gas'!H44 -> Jun | ... N35: ='Ablesewerte Gas'!N44 -> Dez
A37: ='Ablesewerte Gas'!A46 -> Hauptzähler Internat | C37: =SUM('Ablesewerte Gas'!D46-'Ablesewerte Gas'!C46) -> 15094.1 | D37: =SUM('Ablesewerte Gas'!E46-'Ablesewerte Gas'!D46) -> 9173.5 | E37: =SUM('Ablesewerte Gas'!F46-'Ablesewerte Gas'!E46) -> 7840.6 | F37: =SUM('Ablesewerte Gas'!G46-'Ablesewerte Gas'!F46) -> 2831.2 | G37: =SUM('Ablesewerte Gas'!H46-'Ablesewerte Gas'!G46) -> 2327.2 | H37: =SUM('Ablesewerte Gas'!I46-'Ablesewerte Gas'!H46) -> 1868.6 | I37: =SUM('Ablesewerte Gas'!J46-'Ablesewerte Gas'!I46) -> 1437.4 | J37: =SUM('Ablesewerte Gas'!K46-'Ablesewerte Gas'!J46) -> 1443.5 | ... N37: =SUM('Ablesewerte Gas'!O46-'Ablesewerte Gas'!N46) -> 7738.9 | P37: =SUM(C37:O37) -> 63117.2
A38: ='Ablesewerte Gas'!A47 -> Zwischenzähler Küche | C38: =SUM('Ablesewerte Gas'!D47-'Ablesewerte Gas'!C47) -> 60.29 | D38: =SUM('Ablesewerte Gas'!E47-'Ablesewerte Gas'!D47) -> 59.89 | E38: =SUM('Ablesewerte Gas'!F47-'Ablesewerte Gas'!E47) -> 105.96 | F38: =SUM('Ablesewerte Gas'!G47-'Ablesewerte Gas'!F47) -> 62.77 | G38: =SUM('Ablesewerte Gas'!H47-'Ablesewerte Gas'!G47) -> 51.25 | H38: =SUM('Ablesewerte Gas'!I47-'Ablesewerte Gas'!H47) -> 74.3 | I38: =SUM('Ablesewerte Gas'!J47-'Ablesewerte Gas'!I47) -> 66.16 | J38: =SUM('Ablesewerte Gas'!K47-'Ablesewerte Gas'!J47) -> 67.29 | ... N38: =SUM('Ablesewerte Gas'!O47-'Ablesewerte Gas'!N47) -> 105.92 | P38: =SUM(C38:O38) -> 933.41
A39: ='Ablesewerte Gas'!A48 -> alte Aula | C39: =SUM('Ablesewerte Gas'!D48-'Ablesewerte Gas'!C48) -> 1460.6 | D39: =SUM('Ablesewerte Gas'!E48-'Ablesewerte Gas'!D48) -> 713.46 | E39: =SUM('Ablesewerte Gas'!F48-'Ablesewerte Gas'!E48) -> 583.76 | F39: =SUM('Ablesewerte Gas'!G48-'Ablesewerte Gas'!F48) -> 100.88 | G39: =SUM('Ablesewerte Gas'!H48-'Ablesewerte Gas'!G48) -> 49.75 | H39: =SUM('Ablesewerte Gas'!I48-'Ablesewerte Gas'!H48) -> 0 | I39: =SUM('Ablesewerte Gas'!J48-'Ablesewerte Gas'!I48) -> -0.05 | J39: =SUM('Ablesewerte Gas'!K48-'Ablesewerte Gas'!J48) -> 0 | ... N39: =SUM('Ablesewerte Gas'!O48-'Ablesewerte Gas'!N48) -> 672.25 | P39: =SUM(C39:O39) -> 4303.71
A40: ='Ablesewerte Gas'!A49 -> Lichtenstern 13 | C40: =SUM('Ablesewerte Gas'!D49-'Ablesewerte Gas'!C49) -> 1486.99 | D40: =SUM('Ablesewerte Gas'!E49-'Ablesewerte Gas'!D49) -> 920.54 | E40: =SUM('Ablesewerte Gas'!F49-'Ablesewerte Gas'!E49) -> 858.62 | F40: =SUM('Ablesewerte Gas'!G49-'Ablesewerte Gas'!F49) -> 332.5 | G40: =SUM('Ablesewerte Gas'!H49-'Ablesewerte Gas'!G49) -> 291.247 | H40: =SUM('Ablesewerte Gas'!I49-'Ablesewerte Gas'!H49) -> 219.407 | I40: =SUM('Ablesewerte Gas'!J49-'Ablesewerte Gas'!I49) -> 175.186 | J40: =SUM('Ablesewerte Gas'!K49-'Ablesewerte Gas'!J49) -> 102.8 | ... N40: =SUM('Ablesewerte Gas'!O49-'Ablesewerte Gas'!N49) -> 818.395 | P40: =SUM(C40:O40) -> 6797.775
A43: ='Ablesewerte Gas'!A52 -> 2010 | B43: ='Ablesewerte Gas'!B52 -> m³ | C43: ='Ablesewerte Gas'!C52 -> Jan | D43: ='Ablesewerte Gas'!D52 -> Feb | E43: ='Ablesewerte Gas'!E52 -> Mrz | F43: ='Ablesewerte Gas'!F52 -> Apr | G43: ='Ablesewerte Gas'!G52 -> Mai | H43: ='Ablesewerte Gas'!H52 -> Jun | ... N43: ='Ablesewerte Gas'!N52 -> Dez
A45: ='Ablesewerte Gas'!A54 -> Hauptzähler Internat | C45: =SUM('Ablesewerte Gas'!D54-'Ablesewerte Gas'!C54) -> 15240.4 | D45: =SUM('Ablesewerte Gas'!E54-'Ablesewerte Gas'!D54) -> 9408.3 | E45: =SUM('Ablesewerte Gas'!F54-'Ablesewerte Gas'!E54) -> 7307.7 | F45: =SUM('Ablesewerte Gas'!G54-'Ablesewerte Gas'!F54) -> 4406.2 | G45: =SUM('Ablesewerte Gas'!H54-'Ablesewerte Gas'!G54) -> 2646.4 | H45: =SUM('Ablesewerte Gas'!I54-'Ablesewerte Gas'!H54) -> 2493.3 | I45: =SUM('Ablesewerte Gas'!J54-'Ablesewerte Gas'!I54) -> 1513.5 | J45: =SUM('Ablesewerte Gas'!K54-'Ablesewerte Gas'!J54) -> 1551.2 | ... N45: =SUM('Ablesewerte Gas'!O54-'Ablesewerte Gas'!N54) -> 12080.6 | P45: =SUM(C45:O45) -> 73480.3
A46: ='Ablesewerte Gas'!A55 -> Zwischenzähler Küche | C46: =SUM('Ablesewerte Gas'!D55-'Ablesewerte Gas'!C55) -> 81.2 | D46: =SUM('Ablesewerte Gas'!E55-'Ablesewerte Gas'!D55) -> 83.07 | E46: =SUM('Ablesewerte Gas'!F55-'Ablesewerte Gas'!E55) -> 94.11 | F46: =SUM('Ablesewerte Gas'!G55-'Ablesewerte Gas'!F55) -> 66.13 | G46: =SUM('Ablesewerte Gas'!H55-'Ablesewerte Gas'!G55) -> 57.22 | H46: =SUM('Ablesewerte Gas'!I55-'Ablesewerte Gas'!H55) -> 93.25 | I46: =SUM('Ablesewerte Gas'!J55-'Ablesewerte Gas'!I55) -> 67.09 | J46: =SUM('Ablesewerte Gas'!K55-'Ablesewerte Gas'!J55) -> 58.4 | ... N46: =SUM('Ablesewerte Gas'!O55-'Ablesewerte Gas'!N55) -> 79.06 | P46: =SUM(C46:O46) -> 1017.34
A47: ='Ablesewerte Gas'!A56 -> alte Aula | C47: =SUM('Ablesewerte Gas'!D56-'Ablesewerte Gas'!C56) -> 1246.59 | D47: =SUM('Ablesewerte Gas'!E56-'Ablesewerte Gas'!D56) -> 750.5 | E47: =SUM('Ablesewerte Gas'!F56-'Ablesewerte Gas'!E56) -> 567.7 | F47: =SUM('Ablesewerte Gas'!G56-'Ablesewerte Gas'!F56) -> 164.47 | G47: =SUM('Ablesewerte Gas'!H56-'Ablesewerte Gas'!G56) -> 125.19 | H47: =SUM('Ablesewerte Gas'!I56-'Ablesewerte Gas'!H56) -> 3.38 | I47: =SUM('Ablesewerte Gas'!J56-'Ablesewerte Gas'!I56) -> -0.04 | J47: =SUM('Ablesewerte Gas'!K56-'Ablesewerte Gas'!J56) -> 0.04 | ... N47: =SUM('Ablesewerte Gas'!O56-'Ablesewerte Gas'!N56) -> 1004.66 | P47: =SUM(C47:O47) -> 4843.49
A48: ='Ablesewerte Gas'!A57 -> Lichtenstern 13 | C48: =SUM('Ablesewerte Gas'!D57-'Ablesewerte Gas'!C57) -> 1507.115 | D48: =SUM('Ablesewerte Gas'!E57-'Ablesewerte Gas'!D57) -> 1021.54 | E48: =SUM('Ablesewerte Gas'!F57-'Ablesewerte Gas'!E57) -> 819.48 | F48: =SUM('Ablesewerte Gas'!G57-'Ablesewerte Gas'!F57) -> 550.95 | G48: =SUM('Ablesewerte Gas'!H57-'Ablesewerte Gas'!G57) -> 339.35 | H48: =SUM('Ablesewerte Gas'!I57-'Ablesewerte Gas'!H57) -> 293.63 | I48: =SUM('Ablesewerte Gas'!J57-'Ablesewerte Gas'!I57) -> 128.3 | J48: =SUM('Ablesewerte Gas'!K57-'Ablesewerte Gas'!J57) -> 126.53 | ... N48: =SUM('Ablesewerte Gas'!O57-'Ablesewerte Gas'!N57) -> 609.43 | P48: =SUM(C48:O48) -> 6307.735
A51: ='Ablesewerte Gas'!A60 -> 2011 | B51: ='Ablesewerte Gas'!B60 -> m³ | C51: ='Ablesewerte Gas'!C60 -> Jan | D51: ='Ablesewerte Gas'!D60 -> Feb | E51: ='Ablesewerte Gas'!E60 -> Mrz | F51: ='Ablesewerte Gas'!F60 -> Apr | G51: ='Ablesewerte Gas'!G60 -> Mai | H51: ='Ablesewerte Gas'!H60 -> Jun | ... N51: ='Ablesewerte Gas'!N60 -> Dez
A53: ='Ablesewerte Gas'!A62 -> Hauptzähler Internat | C53: =SUM('Ablesewerte Gas'!D62-'Ablesewerte Gas'!C62) -> 11380.9 | D53: =SUM('Ablesewerte Gas'!E62-'Ablesewerte Gas'!D62) -> 9045.3 | E53: =SUM('Ablesewerte Gas'!F62-'Ablesewerte Gas'!E62) -> 6166.9 | F53: =SUM('Ablesewerte Gas'!G62-'Ablesewerte Gas'!F62) -> 3232.9 | G53: =SUM('Ablesewerte Gas'!H62-'Ablesewerte Gas'!G62) -> 2366.3 | H53: =SUM('Ablesewerte Gas'!I62-'Ablesewerte Gas'!H62) -> 1551.3 | I53: =SUM('Ablesewerte Gas'!J62-'Ablesewerte Gas'!I62) -> 1698 | J53: =SUM('Ablesewerte Gas'!K62-'Ablesewerte Gas'!J62) -> 1274 | ... N53: =SUM('Ablesewerte Gas'!O62-'Ablesewerte Gas'!N62) -> 8062.6 | P53: =SUM(C53:O53) -> 59153.8
A54: ='Ablesewerte Gas'!A63 -> Zwischenzähler Küche | C54: =SUM('Ablesewerte Gas'!D63-'Ablesewerte Gas'!C63) -> 87.76 | D54: =SUM('Ablesewerte Gas'!E63-'Ablesewerte Gas'!D63) -> 113.54 | E54: =SUM('Ablesewerte Gas'!F63-'Ablesewerte Gas'!E63) -> 112.36 | F54: =SUM('Ablesewerte Gas'!G63-'Ablesewerte Gas'!F63) -> 63.04 | G54: =SUM('Ablesewerte Gas'!H63-'Ablesewerte Gas'!G63) -> 103.17 | H54: =SUM('Ablesewerte Gas'!I63-'Ablesewerte Gas'!H63) -> 72.2 | I54: =SUM('Ablesewerte Gas'!J63-'Ablesewerte Gas'!I63) -> 73.06 | J54: =SUM('Ablesewerte Gas'!K63-'Ablesewerte Gas'!J63) -> 46.57 | ... N54: =SUM('Ablesewerte Gas'!O63-'Ablesewerte Gas'!N63) -> 70.51 | P54: =SUM(C54:O54) -> 1025.45
A55: ='Ablesewerte Gas'!A64 -> alte Aula | C55: =SUM('Ablesewerte Gas'!D64-'Ablesewerte Gas'!C64) -> 811.9 | D55: =SUM('Ablesewerte Gas'!E64-'Ablesewerte Gas'!D64) -> 682.5 | E55: =SUM('Ablesewerte Gas'!F64-'Ablesewerte Gas'!E64) -> 430.8 | F55: =SUM('Ablesewerte Gas'!G64-'Ablesewerte Gas'!F64) -> 104.99 | G55: =SUM('Ablesewerte Gas'!H64-'Ablesewerte Gas'!G64) -> 45.08 | H55: =SUM('Ablesewerte Gas'!I64-'Ablesewerte Gas'!H64) -> 12.16 | I55: =SUM('Ablesewerte Gas'!J64-'Ablesewerte Gas'!I64) -> 9.27 | J55: =SUM('Ablesewerte Gas'!K64-'Ablesewerte Gas'!J64) -> 2.4 | ... N55: =SUM('Ablesewerte Gas'!O64-'Ablesewerte Gas'!N64) -> 543.91 | P55: =SUM(C55:O55) -> 3468.32
A56: ='Ablesewerte Gas'!A65 -> Lichtenstern 13 | C56: =SUM('Ablesewerte Gas'!D65-'Ablesewerte Gas'!C65) -> 559.37 | D56: =SUM('Ablesewerte Gas'!E65-'Ablesewerte Gas'!D65) -> 434.904 | E56: =SUM('Ablesewerte Gas'!F65-'Ablesewerte Gas'!E65) -> 399.226 | F56: =SUM('Ablesewerte Gas'!G65-'Ablesewerte Gas'!F65) -> 202.93 | G56: =SUM('Ablesewerte Gas'!H65-'Ablesewerte Gas'!G65) -> 139.235 | H56: =SUM('Ablesewerte Gas'!I65-'Ablesewerte Gas'!H65) -> 103.722 | I56: =SUM('Ablesewerte Gas'!J65-'Ablesewerte Gas'!I65) -> 107.235 | J56: =SUM('Ablesewerte Gas'!K65-'Ablesewerte Gas'!J65) -> 79.198 | ... N56: =SUM('Ablesewerte Gas'!O65-'Ablesewerte Gas'!N65) -> 372.891 | P56: =SUM(C56:O56) -> 3059.02
A59: ='Ablesewerte Gas'!A68 -> 2012 | B59: ='Ablesewerte Gas'!B68 -> m³ | C59: ='Ablesewerte Gas'!C68 -> Jan | D59: ='Ablesewerte Gas'!D68 -> Feb | E59: ='Ablesewerte Gas'!E68 -> Mrz | F59: ='Ablesewerte Gas'!F68 -> Apr | G59: ='Ablesewerte Gas'!G68 -> Mai | H59: ='Ablesewerte Gas'!H68 -> Jun | ... N59: ='Ablesewerte Gas'!N68 -> Dez
A61: ='Ablesewerte Gas'!A70 -> Hauptzähler Internat | C61: =SUM('Ablesewerte Gas'!D70-'Ablesewerte Gas'!C70) -> 11397.9 | D61: =SUM('Ablesewerte Gas'!E70-'Ablesewerte Gas'!D70) -> 12084 | E61: =SUM('Ablesewerte Gas'!F70-'Ablesewerte Gas'!E70) -> 5906.2 | F61: =SUM('Ablesewerte Gas'!G70-'Ablesewerte Gas'!F70) -> 4279 | G61: =SUM('Ablesewerte Gas'!H70-'Ablesewerte Gas'!G70) -> 2228 | H61: =SUM('Ablesewerte Gas'!I70-'Ablesewerte Gas'!H70) -> 1734.8 | I61: =SUM('Ablesewerte Gas'!J70-'Ablesewerte Gas'!I70) -> 1250.4 | J61: =SUM('Ablesewerte Gas'!K70-'Ablesewerte Gas'!J70) -> 1473.4 | ... N61: =SUM('Ablesewerte Gas'!O70-'Ablesewerte Gas'!N70) -> 10491.2 | P61: =SUM(C61:O61) -> 66272.9
A62: ='Ablesewerte Gas'!A71 -> Zwischenzähler Küche | C62: =SUM('Ablesewerte Gas'!D71-'Ablesewerte Gas'!C71) -> 99.71 | D62: =SUM('Ablesewerte Gas'!E71-'Ablesewerte Gas'!D71) -> 78.13 | E62: =SUM('Ablesewerte Gas'!F71-'Ablesewerte Gas'!E71) -> 91.13 | F62: =SUM('Ablesewerte Gas'!G71-'Ablesewerte Gas'!F71) -> 56.16 | G62: =SUM('Ablesewerte Gas'!H71-'Ablesewerte Gas'!G71) -> 83.85 | H62: =SUM('Ablesewerte Gas'!I71-'Ablesewerte Gas'!H71) -> 58.34 | I62: =SUM('Ablesewerte Gas'!J71-'Ablesewerte Gas'!I71) -> 48.49 | J62: =SUM('Ablesewerte Gas'!K71-'Ablesewerte Gas'!J71) -> 26.72 | ... N62: =SUM('Ablesewerte Gas'!O71-'Ablesewerte Gas'!N71) -> 67.26 | P62: =SUM(C62:O62) -> 847.45
...

Sheet Ablesewerte Strom
A1: 2005
A2: Strom | C2: Jan | D2: Feb | E2: Mrz | F2: Apr | G2: Mai | H2: Jun | I2: Jul | J2: Aug | K2: Sep | L2: Okt | M2: Nov | N2: Dez
C3: 10.1. | D3: 1.2. | E3: 1.3. | F3: 1.4. | G3: 2.5. | H3: 1.6. | I3: 1.7. | J3: 28.7. | K3: 1.9. | L3: 5.10. | M3: 7.11. | N3: 1.12. | O3: 9.1.
A4: Internat | C4: 66446 | D4: 74777.3 | G4: 84015.6 | H4: 85895 | I4: 88333.7 | J4: 90302.6 | K4: 91789.7 | L4: 94063.1 | M4: 97514.9 | N4: 100831.7 | O4: 104666.1 | Q4: =SUM(O4-C4) -> 38220.1
A5: UZ Aula * | D5: 12286.6 | G5: 19107 | H5: 20463.5 | I5: 22065.2 | J5: 23422.5 | K5: 24479.3 | L5: 25962.6 | M5: 28431 | N5: 30861.1 | O5: 33715.5 | Q5: =SUM(O5-G5) -> 14608.5 | R5: ab Mai
A6: L13 Internat | C6: 27840.5 | G6: 28718.5 | H6: 28814.4 | I6: 28949.9 | J6: 29052.4 | K6: 29077.8 | L6: 29238.7 | M6: 29432.7 | N6: 29643.4 | O6: 29863.5 | Q6: =SUM(O6-C6) -> 2023
A7: L13 Gemeinschaft | C7: 35661.2 | G7: 36475 | H7: 36579.4 | I7: 36647.8 | J7: 36708.4 | K7: 36778.4 | L7: 36860.4 | M7: 37005.5 | N7: 37134.7 | O7: 37331.4 | Q7: =SUM(O7-C7) -> 1670.2
A8: Schule** | P8: Verbrauch direkt eingetragen
A9: UZ P002 | C9: 68.96 | D9: 108.77 | E9: 145.94 | F9: 191.1 | G9: 240.29 | H9: 273.2 | I9: 320.42 | J9: 362.13 | K9: 424.6 | L9: 469.69 | M9: 523.25 | N9: 567.32 | O9: 612.84 | Q9: =SUM(O9-C9) -> 543.88
A10: UZ P003 | C10: 51.56 | D10: 81.65 | E10: 109.43 | F10: 135.19 | G10: 160.25 | H10: 176.85 | I10: 199.43 | J10: 219.18 | K10: 235.4 | L10: 256.62 | M10: 285.18 | N10: 310.84 | O10: 339.55 | Q10: =SUM(O10-C10) -> 287.99
A11: UZ P004 | C11: 11675.9 | D11: 12206.1 | E11: 12666.5 | F11: 13120 | G11: 13660.4 | H11: 14034.7 | I11: 14488.1 | J11: 14892.7 | K11: 15239.1 | L11: 15886.4 | M11: 16674.6 | N11: 17441.4 | O11: 18250.6 | Q11: =SUM(O11-C11) -> 6574.7
A12: UZ P9 | C12: 25.4 | D12: 25.4 | E12: 25.4 | F12: 25.4 | G12: 25.4 | H12: 25.4 | I12: 25.4 | J12: 25.4 | K12: 25.4 | L12: 25.4 | M12: 25.4 | N12: 25.4 | O12: 25.4 | Q12: =SUM(O12-C12) -> 0
A13: UZ P10 | C13: 1026.7 | D13: 1827.3 | E13: 1829.5 | F13: 1830.9 | G13: 1834.8 | H13: 1840.1 | I13: 1841.5 | J13: 1843.2 | K13: 1846.3 | L13: 1847.8 | M13: 1849.3 | N13: 1853.3 | O13: 1854 | Q13: =SUM(O13-C13) -> 827.3
A14: Sporthalle** | P14: Verbrauch direkt eingetragen
A15: Sporthälle UZ P4 | C15: 7137.2 | D15: 7833.5 | E15: 8516 | F15: 9235.4 | G15: 9906.9 | H15: 10382.1 | I15: 10877.7 | J15: 11331.4 | K15: 11564.2 | L15: 12120.7 | M15: 12850.4 | N15: 13435.6 | O15: 14283.4 | Q15: =SUM(O15-C15) -> 7146.2
A17: nicht abgelesene Werte
A18: Wert stammt aus Abrechnung
A20: 2006
A21: Strom | B21: kWh | C21: Jan | D21: Feb | E21: Mrz | F21: Apr | G21: Mai | H21: Jun | I21: Jul | J21: Aug | K21: Sep | L21: Okt | M21: Nov | N21: Dez | Q21: Verbrauch
C22: 9.1. | D22: 1.2. | E22: 6.3. | F22: 4.4. | G22: 3.5. | H22: 1.6. | I22: 3.7. | J22: 7.8. | K22: 1.9. | L22: 4.10. | M22: 2.11. | N22: 1.12. | O22: 22.12. | Q22: pro Messstelle
A23: Internat | C23: 104666.1 | D23: 107795.7 | E23: 111877.8 | F23: 115148.2 | G23: 117801.7 | H23: 119970.2 | I23: 122680.7 | J23: 124938.2 | K23: 126527.2 | L23: 128459.6 | M23: 131926.8 | N23: 135566.9 | O23: 138805.5 | Q23: =SUM(O23-C23) -> 34139.4
A24: UZ Aula * | C24: 33715.5 | D24: 35970.7 | E24: 39079.3 | F24: 41400.6 | G24: 43486.8 | H24: 44940.9 | I24: 46846.1 | J24: 48235.3 | K24: 49412.9 | L24: 50571.2 | M24: 52946.6 | N24: 55336 | O24: 57591.3 | Q24: =SUM(O24-C24) -> 23875.8 | R24: =SUM(Q23-Q24) -> 10263.6
A25: L13 Internat | C25: 29863.5 | D25: 30070.5 | E25: 30303.2 | F25: 30519.2 | G25: 30629.6 | H25: 30752.9 | I25: 30844.6 | J25: 30866.8 | K25: 30880 | L25: 30982.3 | M25: 31142.9 | N25: 31341.3 | O25: 31500.8 | Q25: =SUM(O25-C25) -> 1637.3
A26: L13 Gemeinschaft | C26: 37331.4 | D26: 37489.9 | E26: 37743.7 | F26: 37977.9 | G26: 38188.6 | H26: 38382.4 | I26: 38529.5 | J26: 38664.5 | K26: 38716.9 | L26: 38792.3 | M26: 38960.2 | N26: 39152.3 | O26: 39290.7 | Q26: =SUM(O26-C26) -> 1959.3
A27: Schule** | P27: keine Ablesung möglich
A28: UZ P002 | C28: 612.84 | D28: 652.63 | E28: 700.81 | F28: 751.08 | G28: 785.63 | H28: 827.77 | I28: 874.36 | J28: 930.6 | K28: 989.14 | L28: 1026.57 | M28: 1074.34 | N28: 1123.37 | O28: 1164.22 | Q28: =SUM(O28-C28) -> 551.38
A29: UZ P003 | C29: 339.55 | D29: 363.69 | E29: 392.73 | F29: 419.82 | G29: 436.57 | H29: 456.49 | I29: 477.2 | J29: 500.8 | K29: 516.15 | L29: 534.01 | M29: 560.06 | N29: 592.92 | O29: 616.78 | Q29: =SUM(O29-C29) -> 277.23
A30: UZ P004 | C30: 18250.6 | D30: 19011.7 | E30: 19900.4 | F30: 20702.8 | G30: 21212.6 | H30: 21768.9 | I30: 22277.3 | J30: 22843.2 | K30: 23119.7 | L30: 23584 | M30: 24325.9 | N30: 25240.1 | O30: 25941.7 | Q30: =SUM(O30-C30) -> 7691.1
A31: UZ P9 | C31: 25.4 | D31: 25.4 | E31: 25.4 | F31: 25.4 | G31: 25.4 | H31: 25.4 | I31: 25.4 | J31: 25.4 | K31: 25.4 | L31: 25.4 | M31: 25.4 | N31: 25.4 | O31: 25.4 | Q31: =SUM(O31-C31) -> 0
A32: UZ P10 | C32: 1854 | D32: 1854.8 | E32: 1855.5 | F32: 1857 | G32: 1859.1 | H32: 1861.7 | I32: 1864.6 | J32: 1866 | K32: 1868.9 | L32: 1870.2 | M32: 1871.9 | N32: 1874.5 | O32: 1875.2 | Q32: =SUM(O32-C32) -> 21.2
A33: Sporthalle** | P33: keine Ablesung möglich
A34: Sporthälle UZ P4 | C34: 14283.4 | D34: 14844.5 | E34: 15638.1 | F34: 16307.4 | G34: 16923.6 | H34: 17464.3 | I34: 18024.3 | J34: 18600.5 | K34: 19058.7 | L34: 19675.8 | M34: 20310.2 | N34: 21072.9 | O34: 21655.9 | Q34: =SUM(O34-C34) -> 7372.5
A36: * Unterzähler vom Internat
A37: ** kann nicht abgelesen werden - siehe Abrechnung
A39: 2007
A40: Strom | B40: kWh | C40: Jan | D40: Feb | E40: Mrz | F40: Apr | G40: Mai | H40: Jun | I40: Jul | J40: Aug | K40: Sep | L40: Okt | M40: Nov | N40: Dez | O40: Jan
C41: 22.12. | D41: 1.2. | E41: 1.3. | F41: 3.4. | G41: 2.5. | H41: 4.6. | I41: 2.7. | J41: 13.8. | K41: 3.9. | L41: 29.9. | M41: 6.11. | N41: 3.12. | O41: 39454
A42: Internat | C42: 138805.5 | D42: 143171.3 | E42: 146910.3 | F42: 150930.8 | G42: 153319.5 | H42: 156176.8 | I42: 158673.1 | J42: 161682.7 | K42: 162366.6 | L42: 165188.4 | M42: 169923.1 | N42: 174316.7 | O42: 178701.4 | Q42: =SUM(O42-C42) -> 39895.9
A43: UZ Aula * | C43: 57591.3 | D43: 60618.3 | E43: 63214.4 | F43: 65910.5 | G43: 67479.5 | H43: 69356.8 | I43: 70930.5 | J43: 72893.4 | K43: 73330.6 | L43: 75274.4 | M43: 78766.8 | N43: 81965.8 | O43: 85225.5 | Q43: =SUM(O43-C43) -> 27634.2 | R43: =SUM(Q42-Q43) -> 12261.7
A44: L13 Internat | C44: 31500.8 | D44: 31718.3 | E44: 31887.8 | F44: 32084.4 | G44: 32212.7 | H44: 32345.5 | I44: 32467 | J44: 32552.3 | K44: 32555.5 | L44: 32682.4 | M44: 32874.4 | N44: 33096.6 | O44: 33283.5 | Q44: =SUM(O44-C44) -> 1782.7
...

Sheet Verbrauch Strom
A1: 2005
A2: Strom | C2: ='Ablesewerte Strom'!C21 -> Jan | D2: Jan | E2: Feb | F2: Mrz | G2: Apr | H2: Mai | I2: Jun | J2: Jul | K2: Aug | L2: Sep | M2: Okt | N2: Nov | O2: Dez
C3: ='Ablesewerte Strom'!C22 -> 9.1.
A4: Internat | B4: ='Ablesewerte Strom'!B23 | D4: =SUM('Ablesewerte Strom'!D4-'Ablesewerte Strom'!C4) -> 8331.3 | E4: 0 | F4: =SUM('Ablesewerte Strom'!F4-'Ablesewerte Strom'!E4) -> 0 | G4: =SUM('Ablesewerte Strom'!G4-'Ablesewerte Strom'!F4) -> 84015.6 | H4: =SUM('Ablesewerte Strom'!H4-'Ablesewerte Strom'!G4) -> 1879.4 | I4: =SUM('Ablesewerte Strom'!I4-'Ablesewerte Strom'!H4) -> 2438.7 | J4: =SUM('Ablesewerte Strom'!J4-'Ablesewerte Strom'!I4) -> 1968.9 | K4: =SUM('Ablesewerte Strom'!K4-'Ablesewerte Strom'!J4) -> 1487.1 | L4: =SUM('Ablesewerte Strom'!L4-'Ablesewerte Strom'!K4) -> 2273.4 | M4: =SUM('Ablesewerte Strom'!M4-'Ablesewerte Strom'!L4) -> 3451.8 | ... O4: =SUM('Ablesewerte Strom'!O4-'Ablesewerte Strom'!N4) -> 3834.4
A5: UZ Aula * | D5: =SUM('Ablesewerte Strom'!D5-'Ablesewerte Strom'!C5) -> 12286.6 | E5: 0 | F5: =SUM('Ablesewerte Strom'!F5-'Ablesewerte Strom'!E5) -> 0 | G5: =SUM('Ablesewerte Strom'!G5-'Ablesewerte Strom'!F5) -> 19107 | H5: =SUM('Ablesewerte Strom'!H5-'Ablesewerte Strom'!G5) -> 1356.5 | I5: =SUM('Ablesewerte Strom'!I5-'Ablesewerte Strom'!H5) -> 1601.7 | J5: =SUM('Ablesewerte Strom'!J5-'Ablesewerte Strom'!I5) -> 1357.3 | K5: =SUM('Ablesewerte Strom'!K5-'Ablesewerte Strom'!J5) -> 1056.8 | L5: =SUM('Ablesewerte Strom'!L5-'Ablesewerte Strom'!K5) -> 1483.3 | M5: =SUM('Ablesewerte Strom'!M5-'Ablesewerte Strom'!L5) -> 2468.4 | ... O5: =SUM('Ablesewerte Strom'!O5-'Ablesewerte Strom'!N5) -> 2854.4
A6: L13 Internat | D6: 0 | E6: =SUM('Ablesewerte Strom'!E6-'Ablesewerte Strom'!D6) -> 0 | F6: =SUM('Ablesewerte Strom'!F6-'Ablesewerte Strom'!E6) -> 0 | G6: =SUM('Ablesewerte Strom'!G6-'Ablesewerte Strom'!F6) -> 28718.5 | H6: =SUM('Ablesewerte Strom'!H6-'Ablesewerte Strom'!G6) -> 95.9 | I6: =SUM('Ablesewerte Strom'!I6-'Ablesewerte Strom'!H6) -> 135.5 | J6: =SUM('Ablesewerte Strom'!J6-'Ablesewerte Strom'!I6) -> 102.5 | K6: =SUM('Ablesewerte Strom'!K6-'Ablesewerte Strom'!J6) -> 25.4 | L6: =SUM('Ablesewerte Strom'!L6-'Ablesewerte Strom'!K6) -> 160.9 | ... O6: =SUM('Ablesewerte Strom'!O6-'Ablesewerte Strom'!N6) -> 220.1
A7: L13 Gemeinschaft | D7: 0 | E7: =SUM('Ablesewerte Strom'!E7-'Ablesewerte Strom'!D7) -> 0 | F7: =SUM('Ablesewerte Strom'!F7-'Ablesewerte Strom'!E7) -> 0 | G7: =SUM('Ablesewerte Strom'!G7-'Ablesewerte Strom'!F7) -> 36475 | H7: =SUM('Ablesewerte Strom'!H7-'Ablesewerte Strom'!G7) -> 104.4 | I7: =SUM('Ablesewerte Strom'!I7-'Ablesewerte Strom'!H7) -> 68.4 | J7: =SUM('Ablesewerte Strom'!J7-'Ablesewerte Strom'!I7) -> 60.6 | K7: =SUM('Ablesewerte Strom'!K7-'Ablesewerte Strom'!J7) -> 70 | L7: =SUM('Ablesewerte Strom'!L7-'Ablesewerte Strom'!K7) -> 82 | ... O7: =SUM('Ablesewerte Strom'!O7-'Ablesewerte Strom'!N7) -> 196.7
A8: Schule** | D8: =SUM('Ablesewerte Strom'!D8-'Ablesewerte Strom'!C8) -> 0 | E8: =SUM('Ablesewerte Strom'!E8-'Ablesewerte Strom'!D8) -> 0 | F8: =SUM('Ablesewerte Strom'!F8-'Ablesewerte Strom'!E8) -> 0 | G8: =SUM('Ablesewerte Strom'!G8-'Ablesewerte Strom'!F8) -> 0 | H8: =SUM('Ablesewerte Strom'!H8-'Ablesewerte Strom'!G8) -> 0 | I8: =SUM('Ablesewerte Strom'!I8-'Ablesewerte Strom'!H8) -> 0 | J8: =SUM('Ablesewerte Strom'!J8-'Ablesewerte Strom'!I8) -> 0 | K8: =SUM('Ablesewerte Strom'!K8-'Ablesewerte Strom'!J8) -> 0 | ... O8: =SUM('Ablesewerte Strom'!O8-'Ablesewerte Strom'!N8) -> 0
A9: UZ P002 | D9: =SUM('Ablesewerte Strom'!D9-'Ablesewerte Strom'!C9) -> 39.81 | E9: =SUM('Ablesewerte Strom'!E9-'Ablesewerte Strom'!D9) -> 37.17 | F9: =SUM('Ablesewerte Strom'!F9-'Ablesewerte Strom'!E9) -> 45.16 | G9: =SUM('Ablesewerte Strom'!G9-'Ablesewerte Strom'!F9) -> 49.19 | H9: =SUM('Ablesewerte Strom'!H9-'Ablesewerte Strom'!G9) -> 32.91 | I9: =SUM('Ablesewerte Strom'!I9-'Ablesewerte Strom'!H9) -> 47.22 | J9: =SUM('Ablesewerte Strom'!J9-'Ablesewerte Strom'!I9) -> 41.71 | K9: =SUM('Ablesewerte Strom'!K9-'Ablesewerte Strom'!J9) -> 62.47 | ... O9: =SUM('Ablesewerte Strom'!O9-'Ablesewerte Strom'!N9) -> 45.52
A10: UZ P003 | D10: =SUM('Ablesewerte Strom'!D10-'Ablesewerte Strom'!C10) -> 30.09 | E10: =SUM('Ablesewerte Strom'!E10-'Ablesewerte Strom'!D10) -> 27.78 | F10: =SUM('Ablesewerte Strom'!F10-'Ablesewerte Strom'!E10) -> 25.76 | G10: =SUM('Ablesewerte Strom'!G10-'Ablesewerte Strom'!F10) -> 25.06 | H10: =SUM('Ablesewerte Strom'!H10-'Ablesewerte Strom'!G10) -> 16.6 | I10: =SUM('Ablesewerte Strom'!I10-'Ablesewerte Strom'!H10) -> 22.58 | J10: =SUM('Ablesewerte Strom'!J10-'Ablesewerte Strom'!I10) -> 19.75 | K10: =SUM('Ablesewerte Strom'!K10-'Ablesewerte Strom'!J10) -> 16.22 | ... O10: =SUM('Ablesewerte Strom'!O10-'Ablesewerte Strom'!N10) -> 28.71
A11: UZ P004 | D11: =SUM('Ablesewerte Strom'!D11-'Ablesewerte Strom'!C11) -> 530.2 | E11: =SUM('Ablesewerte Strom'!E11-'Ablesewerte Strom'!D11) -> 460.4 | F11: =SUM('Ablesewerte Strom'!F11-'Ablesewerte Strom'!E11) -> 453.5 | G11: =SUM('Ablesewerte Strom'!G11-'Ablesewerte Strom'!F11) -> 540.4 | H11: =SUM('Ablesewerte Strom'!H11-'Ablesewerte Strom'!G11) -> 374.3 | I11: =SUM('Ablesewerte Strom'!I11-'Ablesewerte Strom'!H11) -> 453.4 | J11: =SUM('Ablesewerte Strom'!J11-'Ablesewerte Strom'!I11) -> 404.6 | K11: =SUM('Ablesewerte Strom'!K11-'Ablesewerte Strom'!J11) -> 346.4 | ... O11: =SUM('Ablesewerte Strom'!O11-'Ablesewerte Strom'!N11) -> 809.2
A12: UZ P9 | D12: =SUM('Ablesewerte Strom'!D12-'Ablesewerte Strom'!C12) -> 0 | E12: =SUM('Ablesewerte Strom'!E12-'Ablesewerte Strom'!D12) -> 0 | F12: =SUM('Ablesewerte Strom'!F12-'Ablesewerte Strom'!E12) -> 0 | G12: =SUM('Ablesewerte Strom'!G12-'Ablesewerte Strom'!F12) -> 0 | H12: =SUM('Ablesewerte Strom'!H12-'Ablesewerte Strom'!G12) -> 0 | I12: =SUM('Ablesewerte Strom'!I12-'Ablesewerte Strom'!H12) -> 0 | J12: =SUM('Ablesewerte Strom'!J12-'Ablesewerte Strom'!I12) -> 0 | K12: =SUM('Ablesewerte Strom'!K12-'Ablesewerte Strom'!J12) -> 0 | ... O12: =SUM('Ablesewerte Strom'!O12-'Ablesewerte Strom'!N12) -> 0
A13: UZ P10 | D13: =SUM('Ablesewerte Strom'!D13-'Ablesewerte Strom'!C13) -> 800.6 | E13: =SUM('Ablesewerte Strom'!E13-'Ablesewerte Strom'!D13) -> 2.2 | F13: =SUM('Ablesewerte Strom'!F13-'Ablesewerte Strom'!E13) -> 1.4 | G13: =SUM('Ablesewerte Strom'!G13-'Ablesewerte Strom'!F13) -> 3.9 | H13: =SUM('Ablesewerte Strom'!H13-'Ablesewerte Strom'!G13) -> 5.3 | I13: =SUM('Ablesewerte Strom'!I13-'Ablesewerte Strom'!H13) -> 1.4 | J13: =SUM('Ablesewerte Strom'!J13-'Ablesewerte Strom'!I13) -> 1.7 | K13: =SUM('Ablesewerte Strom'!K13-'Ablesewerte Strom'!J13) -> 3.1 | ... O13: =SUM('Ablesewerte Strom'!O13-'Ablesewerte Strom'!N13) -> 0.7
A14: Sporthalle** | D14: =SUM('Ablesewerte Strom'!D14-'Ablesewerte Strom'!C14) -> 0 | E14: =SUM('Ablesewerte Strom'!E14-'Ablesewerte Strom'!D14) -> 0 | F14: =SUM('Ablesewerte Strom'!F14-'Ablesewerte Strom'!E14) -> 0 | G14: =SUM('Ablesewerte Strom'!G14-'Ablesewerte Strom'!F14) -> 0 | H14: =SUM('Ablesewerte Strom'!H14-'Ablesewerte Strom'!G14) -> 0 | I14: =SUM('Ablesewerte Strom'!I14-'Ablesewerte Strom'!H14) -> 0 | J14: =SUM('Ablesewerte Strom'!J14-'Ablesewerte Strom'!I14) -> 0 | K14: =SUM('Ablesewerte Strom'!K14-'Ablesewerte Strom'!J14) -> 0 | ... O14: =SUM('Ablesewerte Strom'!O14-'Ablesewerte Strom'!N14) -> 0
A15: Sporthälle UZ P4 | D15: =SUM('Ablesewerte Strom'!D15-'Ablesewerte Strom'!C15) -> 696.3 | E15: =SUM('Ablesewerte Strom'!E15-'Ablesewerte Strom'!D15) -> 682.5 | F15: =SUM('Ablesewerte Strom'!F15-'Ablesewerte Strom'!E15) -> 719.4 | G15: =SUM('Ablesewerte Strom'!G15-'Ablesewerte Strom'!F15) -> 671.5 | H15: =SUM('Ablesewerte Strom'!H15-'Ablesewerte Strom'!G15) -> 475.2 | I15: =SUM('Ablesewerte Strom'!I15-'Ablesewerte Strom'!H15) -> 495.6 | J15: =SUM('Ablesewerte Strom'!J15-'Ablesewerte Strom'!I15) -> 453.7 | K15: =SUM('Ablesewerte Strom'!K15-'Ablesewerte Strom'!J15) -> 232.8 | ... O15: =SUM('Ablesewerte Strom'!O15-'Ablesewerte Strom'!N15) -> 847.8
A17: nicht abgelesene Werte
A18: Wert stammt aus Abrechnung
A21: 2006
A22: Strom | C22: ='Ablesewerte Strom'!C2 -> Jan | D22: Jan | E22: Feb | F22: Mrz | G22: Apr | H22: Mai | I22: Jun | J22: Jul | K22: Aug | L22: Sep | M22: Okt | N22: Nov | O22: Dez
C23: ='Ablesewerte Strom'!C3 -> 10.1.
A24: Internat | D24: =SUM('Ablesewerte Strom'!D23-'Ablesewerte Strom'!C23) -> 3129.6 | E24: =SUM('Ablesewerte Strom'!E23-'Ablesewerte Strom'!D23) -> 4082.1 | F24: =SUM('Ablesewerte Strom'!F23-'Ablesewerte Strom'!E23) -> 3270.4 | G24: =SUM('Ablesewerte Strom'!G23-'Ablesewerte Strom'!F23) -> 2653.5 | H24: =SUM('Ablesewerte Strom'!H23-'Ablesewerte Strom'!G23) -> 2168.5 | I24: =SUM('Ablesewerte Strom'!I23-'Ablesewerte Strom'!H23) -> 2710.5 | J24: =SUM('Ablesewerte Strom'!J23-'Ablesewerte Strom'!I23) -> 2257.5 | K24: =SUM('Ablesewerte Strom'!K23-'Ablesewerte Strom'!J23) -> 1589 | ... O24: =SUM('Ablesewerte Strom'!O23-'Ablesewerte Strom'!N23) -> 3238.6 | Q24: =SUM(D24:P24) -> 34139.4
A25: UZ Aula * | D25: =SUM('Ablesewerte Strom'!D24-'Ablesewerte Strom'!C24) -> 2255.2 | E25: =SUM('Ablesewerte Strom'!E24-'Ablesewerte Strom'!D24) -> 3108.6 | F25: =SUM('Ablesewerte Strom'!F24-'Ablesewerte Strom'!E24) -> 2321.3 | G25: =SUM('Ablesewerte Strom'!G24-'Ablesewerte Strom'!F24) -> 2086.2 | H25: =SUM('Ablesewerte Strom'!H24-'Ablesewerte Strom'!G24) -> 1454.1 | I25: =SUM('Ablesewerte Strom'!I24-'Ablesewerte Strom'!H24) -> 1905.2 | J25: =SUM('Ablesewerte Strom'!J24-'Ablesewerte Strom'!I24) -> 1389.2 | K25: =SUM('Ablesewerte Strom'!K24-'Ablesewerte Strom'!J24) -> 1177.6 | ... O25: =SUM('Ablesewerte Strom'!O24-'Ablesewerte Strom'!N24) -> 2255.3 | Q25: =SUM(D25:P25) -> 23875.8
A26: L13 Internat | D26: =SUM('Ablesewerte Strom'!D25-'Ablesewerte Strom'!C25) -> 207 | E26: =SUM('Ablesewerte Strom'!E25-'Ablesewerte Strom'!D25) -> 232.7 | F26: =SUM('Ablesewerte Strom'!F25-'Ablesewerte Strom'!E25) -> 216 | G26: =SUM('Ablesewerte Strom'!G25-'Ablesewerte Strom'!F25) -> 110.4 | H26: =SUM('Ablesewerte Strom'!H25-'Ablesewerte Strom'!G25) -> 123.3 | I26: =SUM('Ablesewerte Strom'!I25-'Ablesewerte Strom'!H25) -> 91.7 | J26: =SUM('Ablesewerte Strom'!J25-'Ablesewerte Strom'!I25) -> 22.2 | K26: =SUM('Ablesewerte Strom'!K25-'Ablesewerte Strom'!J25) -> 13.2 | ... O26: =SUM('Ablesewerte Strom'!O25-'Ablesewerte Strom'!N25) -> 159.5 | Q26: =SUM(D26:P26) -> 1637.3
A27: L13 Gemeinschaft | D27: =SUM('Ablesewerte Strom'!D26-'Ablesewerte Strom'!C26) -> 158.5 | E27: =SUM('Ablesewerte Strom'!E26-'Ablesewerte Strom'!D26) -> 253.8 | F27: =SUM('Ablesewerte Strom'!F26-'Ablesewerte Strom'!E26) -> 234.2 | G27: =SUM('Ablesewerte Strom'!G26-'Ablesewerte Strom'!F26) -> 210.7 | H27: =SUM('Ablesewerte Strom'!H26-'Ablesewerte Strom'!G26) -> 193.8 | I27: =SUM('Ablesewerte Strom'!I26-'Ablesewerte Strom'!H26) -> 147.1 | J27: =SUM('Ablesewerte Strom'!J26-'Ablesewerte Strom'!I26) -> 135 | K27: =SUM('Ablesewerte Strom'!K26-'Ablesewerte Strom'!J26) -> 52.4 | ... O27: =SUM('Ablesewerte Strom'!O26-'Ablesewerte Strom'!N26) -> 138.4 | Q27: =SUM(D27:P27) -> 1959.3
A28: Schule** | B28: HT | E28: 13801 | F28: 7220 | G28: 5096 | H28: 6184 | I28: 5396 | J28: 6864 | K28: 6551 | L28: 5070 | M28: 7402 | N28: 7988 | O28: 7384
B29: NT | E29: 3240 | F29: 1735 | G29: 1626 | H29: 1793 | I29: 1748 | J29: 1977 | K29: 1886 | L29: 1672 | M29: 1886 | N29: 1771 | O29: 1735 | Q29: =SUM(E28:O29) -> 100025
A30: UZ P002*** | D30: =SUM('Ablesewerte Strom'!D28-'Ablesewerte Strom'!C28) -> 39.79 | E30: =SUM('Ablesewerte Strom'!E28-'Ablesewerte Strom'!D28) -> 48.18 | F30: =SUM('Ablesewerte Strom'!F28-'Ablesewerte Strom'!E28) -> 50.27 | G30: =SUM('Ablesewerte Strom'!G28-'Ablesewerte Strom'!F28) -> 34.55 | H30: =SUM('Ablesewerte Strom'!H28-'Ablesewerte Strom'!G28) -> 42.14 | I30: =SUM('Ablesewerte Strom'!I28-'Ablesewerte Strom'!H28) -> 46.59 | J30: =SUM('Ablesewerte Strom'!J28-'Ablesewerte Strom'!I28) -> 56.24 | K30: =SUM('Ablesewerte Strom'!K28-'Ablesewerte Strom'!J28) -> 58.54 | ... O30: =SUM('Ablesewerte Strom'!O28-'Ablesewerte Strom'!N28) -> 40.85
A31: UZ P003*** | D31: =SUM('Ablesewerte Strom'!D29-'Ablesewerte Strom'!C29) -> 24.14 | E31: =SUM('Ablesewerte Strom'!E29-'Ablesewerte Strom'!D29) -> 29.04 | F31: =SUM('Ablesewerte Strom'!F29-'Ablesewerte Strom'!E29) -> 27.09 | G31: =SUM('Ablesewerte Strom'!G29-'Ablesewerte Strom'!F29) -> 16.75 | H31: =SUM('Ablesewerte Strom'!H29-'Ablesewerte Strom'!G29) -> 19.92 | I31: =SUM('Ablesewerte Strom'!I29-'Ablesewerte Strom'!H29) -> 20.71 | J31: =SUM('Ablesewerte Strom'!J29-'Ablesewerte Strom'!I29) -> 23.6 | K31: =SUM('Ablesewerte Strom'!K29-'Ablesewerte Strom'!J29) -> 15.35 | ... O31: =SUM('Ablesewerte Strom'!O29-'Ablesewerte Strom'!N29) -> 23.86
A32: UZ P004*** | D32: =SUM('Ablesewerte Strom'!D30-'Ablesewerte Strom'!C30) -> 761.1 | E32: =SUM('Ablesewerte Strom'!E30-'Ablesewerte Strom'!D30) -> 888.7 | F32: =SUM('Ablesewerte Strom'!F30-'Ablesewerte Strom'!E30) -> 802.4 | G32: =SUM('Ablesewerte Strom'!G30-'Ablesewerte Strom'!F30) -> 509.8 | H32: =SUM('Ablesewerte Strom'!H30-'Ablesewerte Strom'!G30) -> 556.3 | I32: =SUM('Ablesewerte Strom'!I30-'Ablesewerte Strom'!H30) -> 508.4 | J32: =SUM('Ablesewerte Strom'!J30-'Ablesewerte Strom'!I30) -> 565.9 | K32: =SUM('Ablesewerte Strom'!K30-'Ablesewerte Strom'!J30) -> 276.5 | ... O32: =SUM('Ablesewerte Strom'!O30-'Ablesewerte Strom'!N30) -> 701.6
A33: UZ P9*** | D33: =SUM('Ablesewerte Strom'!D31-'Ablesewerte Strom'!C31) -> 0 | E33: =SUM('Ablesewerte Strom'!E31-'Ablesewerte Strom'!D31) -> 0 | F33: =SUM('Ablesewerte Strom'!F31-'Ablesewerte Strom'!E31) -> 0 | G33: =SUM('Ablesewerte Strom'!G31-'Ablesewerte Strom'!F31) -> 0 | H33: =SUM('Ablesewerte Strom'!H31-'Ablesewerte Strom'!G31) -> 0 | I33: =SUM('Ablesewerte Strom'!I31-'Ablesewerte Strom'!H31) -> 0 | J33: =SUM('Ablesewerte Strom'!J31-'Ablesewerte Strom'!I31) -> 0 | K33: =SUM('Ablesewerte Strom'!K31-'Ablesewerte Strom'!J31) -> 0 | ... O33: =SUM('Ablesewerte Strom'!O31-'Ablesewerte Strom'!N31) -> 0
A34: UZ P10*** | D34: =SUM('Ablesewerte Strom'!D32-'Ablesewerte Strom'!C32) -> 0.8 | E34: =SUM('Ablesewerte Strom'!E32-'Ablesewerte Strom'!D32) -> 0.7 | F34: =SUM('Ablesewerte Strom'!F32-'Ablesewerte Strom'!E32) -> 1.5 | G34: =SUM('Ablesewerte Strom'!G32-'Ablesewerte Strom'!F32) -> 2.1 | H34: =SUM('Ablesewerte Strom'!H32-'Ablesewerte Strom'!G32) -> 2.6 | I34: =SUM('Ablesewerte Strom'!I32-'Ablesewerte Strom'!H32) -> 2.9 | J34: =SUM('Ablesewerte Strom'!J32-'Ablesewerte Strom'!I32) -> 1.4 | K34: =SUM('Ablesewerte Strom'!K32-'Ablesewerte Strom'!J32) -> 2.9 | ... O34: =SUM('Ablesewerte Strom'!O32-'Ablesewerte Strom'!N32) -> 0.7
A35: Sporthalle** | D35: 3081 | E35: 3240 | F35: 2656 | G35: 1199 | H35: 1231 | I35: 841 | O35: 13837
D36: 808 | E36: 727 | F36: 714 | G36: 394 | H36: 417 | I36: 342 | O36: 3345 | Q36: =SUM(D35:O36) -> 32832
A37: Sporthälle UZ P4*** | D37: =SUM('Ablesewerte Strom'!D34-'Ablesewerte Strom'!C34) -> 561.1 | E37: =SUM('Ablesewerte Strom'!E34-'Ablesewerte Strom'!D34) -> 793.6 | F37: =SUM('Ablesewerte Strom'!F34-'Ablesewerte Strom'!E34) -> 669.3 | G37: =SUM('Ablesewerte Strom'!G34-'Ablesewerte Strom'!F34) -> 616.2 | H37: =SUM('Ablesewerte Strom'!H34-'Ablesewerte Strom'!G34) -> 540.7 | I37: =SUM('Ablesewerte Strom'!I34-'Ablesewerte Strom'!H34) -> 560 | J37: =SUM('Ablesewerte Strom'!J34-'Ablesewerte Strom'!I34) -> 576.2 | K37: =SUM('Ablesewerte Strom'!K34-'Ablesewerte Strom'!J34) -> 458.2 | ... O37: =SUM('Ablesewerte Strom'!O34-'Ablesewerte Strom'!N34) -> 583 | Q37: KWH | R37: =SUM(Q24:Q37) -> 194468.8
A40: 2007
A41: Strom | C41: ='Ablesewerte Strom'!C19 -> 0 | D41: Jan | E41: Feb | F41: Mrz | G41: Apr | H41: Mai | I41: Jun | J41: Jul | K41: Aug | L41: Sep | M41: Okt | N41: Nov | O41: Dez
A43: Internat | D43: =SUM('Ablesewerte Strom'!D42-'Ablesewerte Strom'!C42) -> 4365.8 | E43: =SUM('Ablesewerte Strom'!E42-'Ablesewerte Strom'!D42) -> 3739 | F43: =SUM('Ablesewerte Strom'!F42-'Ablesewerte Strom'!E42) -> 4020.5 | G43: =SUM('Ablesewerte Strom'!G42-'Ablesewerte Strom'!F42) -> 2388.7 | H43: =SUM('Ablesewerte Strom'!H42-'Ablesewerte Strom'!G42) -> 2857.3 | I43: =SUM('Ablesewerte Strom'!I42-'Ablesewerte Strom'!H42) -> 2496.3 | J43: =SUM('Ablesewerte Strom'!J42-'Ablesewerte Strom'!I42) -> 3009.6 | K43: =SUM('Ablesewerte Strom'!K42-'Ablesewerte Strom'!J42) -> 683.9 | ... N43: =SUM('Ablesewerte Strom'!N42-'Ablesewerte Strom'!M42) -> 4393.6 | O43: =SUM('Ablesewerte Strom'!C60-'Ablesewerte Strom'!N42) -> 4384.7 | Q43: =SUM(D43:O43) -> 39895.9
A44: UZ Aula * | D44: =SUM('Ablesewerte Strom'!D43-'Ablesewerte Strom'!C43) -> 3027 | E44: =SUM('Ablesewerte Strom'!E43-'Ablesewerte Strom'!D43) -> 2596.1 | F44: =SUM('Ablesewerte Strom'!F43-'Ablesewerte Strom'!E43) -> 2696.1 | G44: =SUM('Ablesewerte Strom'!G43-'Ablesewerte Strom'!F43) -> 1569 | H44: =SUM('Ablesewerte Strom'!H43-'Ablesewerte Strom'!G43) -> 1877.3 | I44: =SUM('Ablesewerte Strom'!I43-'Ablesewerte Strom'!H43) -> 1573.7 | J44: =SUM('Ablesewerte Strom'!J43-'Ablesewerte Strom'!I43) -> 1962.9 | K44: =SUM('Ablesewerte Strom'!K43-'Ablesewerte Strom'!J43) -> 437.2 | ... N44: =SUM('Ablesewerte Strom'!N43-'Ablesewerte Strom'!M43) -> 3199 | O44: =SUM('Ablesewerte Strom'!C61-'Ablesewerte Strom'!N43) -> 3259.7 | Q44: =SUM(D44:O44) -> 27634.2
A45: L13 Internat | D45: =SUM('Ablesewerte Strom'!D44-'Ablesewerte Strom'!C44) -> 217.5 | E45: =SUM('Ablesewerte Strom'!E44-'Ablesewerte Strom'!D44) -> 169.5 | F45: =SUM('Ablesewerte Strom'!F44-'Ablesewerte Strom'!E44) -> 196.6 | G45: =SUM('Ablesewerte Strom'!G44-'Ablesewerte Strom'!F44) -> 128.3 | H45: =SUM('Ablesewerte Strom'!H44-'Ablesewerte Strom'!G44) -> 132.8 | I45: =SUM('Ablesewerte Strom'!I44-'Ablesewerte Strom'!H44) -> 121.5 | J45: =SUM('Ablesewerte Strom'!J44-'Ablesewerte Strom'!I44) -> 85.3 | K45: =SUM('Ablesewerte Strom'!K44-'Ablesewerte Strom'!J44) -> 3.2 | ... N45: =SUM('Ablesewerte Strom'!N44-'Ablesewerte Strom'!M44) -> 222.2 | O45: =SUM('Ablesewerte Strom'!C62-'Ablesewerte Strom'!N44) -> 186.9 | Q45: =SUM(D45:O45) -> 1782.7
A46: L13 Gemeinschaft | D46: =SUM('Ablesewerte Strom'!D45-'Ablesewerte Strom'!C45) -> 259.3 | E46: =SUM('Ablesewerte Strom'!E45-'Ablesewerte Strom'!D45) -> 166.7 | F46: =SUM('Ablesewerte Strom'!F45-'Ablesewerte Strom'!E45) -> 208.9 | G46: =SUM('Ablesewerte Strom'!G45-'Ablesewerte Strom'!F45) -> 180.6 | H46: =SUM('Ablesewerte Strom'!H45-'Ablesewerte Strom'!G45) -> 188.3 | I46: =SUM('Ablesewerte Strom'!I45-'Ablesewerte Strom'!H45) -> 110.6 | J46: =SUM('Ablesewerte Strom'!J45-'Ablesewerte Strom'!I45) -> 166.8 | K46: =SUM('Ablesewerte Strom'!K45-'Ablesewerte Strom'!J45) -> 84.3 | ... N46: =SUM('Ablesewerte Strom'!N45-'Ablesewerte Strom'!M45) -> 198.8 | O46: =SUM('Ablesewerte Strom'!C63-'Ablesewerte Strom'!N45) -> 297 | Q46: =SUM(D46:O46) -> 2271.3
...

Sheet Ablesewerte Wasser
A1: Wasser
A2: 2005 | C2: Jan | D2: Feb | E2: Mrz | F2: Apr | G2: Mai | H2: Jun | I2: Jul | J2: Aug | K2: Sep | L2: Okt | M2: Nov | N2: Dez
B3: m³ | C3: 10.1. | D3: 1.2. | E3: 1.3. | F3: 1.4. | G3: 2.5. | H3: 1.6. | I3: 1.7. | J3: 28.7. | K3: 1.9. | L3: 5.10. | M3: 7.11. | N3: 1.12. | O3: 9.1.
A5: Zähler Schloss | C5: 614 | F5: 1210 | G5: 1401 | H5: 1511 | I5: 1756 | J5: 1945 | K5: 2087 | L5: 2248 | M5: 2436 | N5: 2627 | O5: 2795 | Q5: =SUM(O5-C5) -> 2181
A6: davon Sporthalle | F6: 251 | G6: 266 | H6: 274 | I6: 311 | J6: 321 | K6: 323 | L6: 334 | M6: 349 | N6: 367 | O6: 382 | Q6: =SUM(O6-F6) -> 131 | R6: (ab April)
A7: Aula | C7: 6 | I7: 33 | J7: 36 | K7: 43 | L7: 48 | M7: 50 | N7: 52 | O7: 54 | Q7: =SUM(O7-C7) -> 48
A8: Lichtenstern 13 | C8: 313 | G8: 466 | H8: 486 | I8: 510 | J8: 541 | K8: 551 | L8: 581 | M8: 615 | N8: 645 | O8: 680 | Q8: =SUM(O8-C8) -> 367 | R8: gesamt
R9: =SUM(Q5:Q8) -> 2727 | S9: m³
A10: nicht abgelesene Werte
A11: Wert stammt aus Abrechnung
A13: 2006 | B13: m³ | C13: Jan | D13: Feb | E13: Mrz | F13: Apr | G13: Mai | H13: Jun | I13: Jul | J13: Aug | K13: Sep | L13: Okt | M13: Nov | N13: Dez | Q13: Verbrauch
C14: 9.1. | D14: 1.2. | E14: 6.3. | F14: 4.4. | G14: 3.5. | H14: 1.6. | I14: 3.7. | J14: 7.8. | K14: 1.9. | L14: 4.10. | M14: 2.11. | N14: 1.12. | O14: 22.12. | Q14: pro Messstelle
A16: Zähler Schloss | C16: 2795 | D16: 2993 | E16: 3200 | F16: 3447 | G16: 3579 | H16: 3798 | I16: 3986 | J16: 4184 | K16: 4293 | L16: 4430 | M16: 4696 | N16: 4985 | O16: 5189 | Q16: =SUM(O16-C16) -> 2394
A17: davon Sporthalle | C17: 382 | D17: 402 | E17: 424 | F17: 441.2 | G17: 451.1 | H17: 461 | I17: 476 | J17: 495 | K17: 497 | L17: 505 | M17: 523 | N17: 545 | O17: 560 | Q17: =SUM(O17-C17) -> 178
A18: Aula | C18: 54 | D18: 56 | E18: 59 | F18: 61 | G18: 63 | H18: 66 | I18: 70 | J18: 78 | K18: 105 | L18: 129 | M18: 153 | N18: 167.2 | O18: 173 | Q18: =SUM(O18-C18) -> 119
A19: Lichtenstern 13 | C19: 680 | D19: 724 | E19: 768.3 | F19: 807 | G19: 838 | H19: 871 | I19: 899 | J19: 923 | K19: 932 | L19: 961 | M19: 993 | N19: 1029 | O19: 1060 | Q19: =SUM(O19-C19) -> 380 | R19: gesamt
R20: =SUM(Q16:Q19) -> 3071 | S20: m³
A21: 2007 | B21: m³ | C21: Jan | D21: Feb | E21: Mrz | F21: Apr | G21: Mai | H21: Jun | I21: Jul | J21: Aug | K21: Sep | L21: Okt | M21: Nov | N21: Dez
C22: 22.12 | D22: 1.2. | E22: 1.3. | F22: 3.4. | G22: 2.5. | H22: 4.6. | I22: 2.7. | J22: 13.8. | K22: 3.9. | L22: 29.9. | M22: 6.11. | N22: 3.12. | O22: 7.1.
A23: Zähler Schloss | C23: 5189 | D23: 5410 | E23: 5633 | F23: 5918 | G23: 6097 | H23: 6281 | I23: 6503 | J23: 6738 | K23: 6747 | L23: 6932 | M23: 7160 | N23: 7417 | O23: 7635 | Q23: =SUM(O23-C23) -> 2446
A24: davon Sporthalle | C24: 560 | D24: 579 | E24: 601 | F24: 624 | G24: 643 | H24: 654 | I24: 670 | J24: 692 | K24: 693 | L24: 703 | M24: 724 | N24: 748 | O24: 763 | Q24: =SUM(O24-C24) -> 203
A25: Aula | C25: 173 | D25: 177 | E25: 180 | F25: 186 | G25: 191 | H25: 195 | I25: 198 | J25: 238 | K25: 238 | L25: 244 | M25: 253 | N25: 257 | O25: 260 | Q25: =SUM(O25-C25) -> 87
A26: Lichtenstern 13 | C26: 1060 | D26: 1100 | E26: 1137 | F26: 1179 | G26: 1211 | H26: 1246 | I26: 1273 | J26: 1300 | K26: 1311 | L26: 1336 | M26: 1365 | N26: 1396 | O26: 1428 | Q26: =SUM(O26-C26) -> 368 | R26: gesamt
R27: =SUM(Q23:Q26) -> 3104 | S27: m³
A28: 2008 | B28: m³ | C28: Jan | D28: Feb | E28: Mrz | F28: Apr | G28: Mai | H28: Jun | I28: Jul | J28: Aug | K28: Sep | L28: Okt | M28: Nov | N28: Dez
C29: 07.01.2008 | D29: 01.02.2008 | E29: 03.03.2008 | F29: 01.04.2008 | G29: 30.04.2008 | H29: 02.06.2008 | I29: 01.07.2008 | J29: 04.08.2008 | K29: 02.09.2008 | L29: 01.10.2008 | M29: 03.11.2008 | N29: 02.12.2008 | O29: 23.12.2008
A30: Zähler Schloss | C30: 7635 | D30: 7896 | E30: 8115 | F30: 8287 | G30: 8597 | H30: 8763 | I30: 9079 | J30: 9307 | K30: 9396 | L30: 9614 | M30: 9815 | N30: 10081 | O30: 10258 | Q30: =SUM(O30-C30) -> 2623
A31: davon Sporthalle | C31: 763 | D31: 787 | E31: 810 | F31: 831 | G31: 852 | H31: 867 | I31: 882 | J31: 899 | K31: 900 | L31: 915 | M31: 938 | N31: 967 | O31: 990 | Q31: =SUM(O31-C31) -> 227
A32: Aula | C32: 260 | D32: 264 | E32: 267 | F32: 270 | G32: 276 | H32: 300 | I32: 304 | J32: 311 | K32: 319 | L32: 324 | M32: 343 | N32: 349 | O32: 353 | Q32: =SUM(O32-C32) -> 93
A33: Lichtenstern 13 | C33: 1428 | D33: 1456 | E33: 1484 | F33: 1510 | G33: 1538 | H33: 1561 | I33: 1589 | J33: 1610 | K33: 1623 | L33: 1652 | M33: 1678 | N33: 1709 | O33: 1731 | Q33: =SUM(O33-C33) -> 303 | R33: gesamt
R34: =SUM(Q30:Q33) -> 3246 | S34: m³
