Workbook

Sheet Ablesewerte Gas
A1: Gas
A4: 2012 | B4: m³ | C4: Jan | D4: Feb | E4: Mrz | F4: Apr | G4: Mai | H4: Jun | I4: Jul | J4: Aug | K4: Sep | L4: Okt | M4: Nov | N4: Dez
C5: 40908 | D5: 40940 | E5: 40969 | F5: 41000 | G5: 41031 | H5: 41061 | I5: 41092 | J5: 41117 | K5: 41153 | L5: 41183 | M5: 41218 | N5: 41247 | O5: 41272
A6: Hauptzähler Internat | C6: 2357818.1 | D6: 2369216 | E6: 2381300 | F6: 2387206.2 | G6: 2391485.2 | H6: 2393713.2 | I6: 2395448 | J6: 2396698.4 | K6: 2398171.8 | L6: 2400338.8 | M6: 2405921.7 | N6: 2413599.8 | O6: 2424091 | Q6: =SUM(O6-C6) -> 66272.9
A7: Zwischenzähler Küche | C7: 5530.39 | D7: 5630.1 | E7: 5708.23 | F7: 5799.36 | G7: 5855.52 | H7: 5939.37 | I7: 5997.71 | J7: 6046.2 | K7: 6072.92 | L7: 6145.24 | M7: 6231.2 | N7: 6310.58 | O7: 6377.84 | R7: =SUM(O7-C7) -> 847.45 | S7: (Küche)
A8: alte Aula | C8: 195332.72 | D8: 196181.74 | E8: 197076.83 | F8: 197446.79 | G8: 197623.46 | H8: 197671.1 | I8: 197671.1 | J8: 197671.1 | K8: 197671.1 | L8: 197716.72 | M8: 197994.21 | N8: 198532.09 | O8: 199225.12 | Q8: =SUM(O8-C8) -> 3892.4
A9: Lichtenstern 13 | C9: 46421.5 | D9: 46926.54 | E9: 47541.34 | F9: 47873.73 | G9: 48176.32 | H9: 111.32 | I9: 197.102 | J9: 259.55 | K9: 343.21 | L9: 436.32 | M9: 702.15 | N9: 1067.089 | O9: 1599.187 | Q9: =SUM(G9-C9)+(O9-H9) -> 3242.687
A14: 2013 | B14: m³ | C14: Jan | D14: Feb | E14: Mrz | F14: Apr | G14: Mai | H14: Jun | I14: Jul | J14: Aug | K14: Sep | L14: Okt | M14: Nov | N14: Dez
C15: 41274 | D15: 41306 | E15: 41334 | F15: 41366 | G15: 41397 | H15: 41429 | I15: 41456 | J15: 41487 | K15: 41519 | L15: 41548 | M15: 41582 | N15: 41610 | O15: 41639
A16: Hauptzähler Internat | C16: 2424091 | D16: 2433708.1 | E16: 2444294.8 | F16: 2453427.5 | G16: 2458453.1 | H16: 2461630 | I16: 2463357.8 | J16: 2464632.9 | K16: 2465778.8 | L16: 2468109.1 | M16: 2472373.9 | N16: 2479928.6 | O16: 2490394.6 | Q16: =SUM(O16-C16) -> 66303.6
A17: Zwischenzähler Küche | C17: 6377.84 | D17: 6425.79 | E17: 6466.1 | F17: 6514.99 | G17: 6574.03 | H17: 6596.47 | I17: 6652.18 | J17: 6683.9 | K17: 6700.95 | L17: 6753.71 | M17: 6823.08 | N17: 6883.77 | O17: 6928.63 | R17: =SUM(O17-C17) -> 550.79
A18: alte Aula | C18: 199225.12 | D18: 199975.98 | E18: 200844.17 | F18: 201620.1 | G18: 201867.99 | H18: 201935.5 | I18: 201938.5 | J18: 201938.5 | K18: 201938.5 | L18: 202009.4 | M18: 202228.2 | N18: 202826.8 | O18: 203621.22 | Q18: =SUM(O18-C18) -> 4396.1
A19: Lichtenstern 13 | C19: 1599.187 | D19: 2032.99 | E19: 2543.845 | F19: 3000.42 | G19: 3231.69 | H19: 3418.32 | I19: 3513.82 | J19: 3598.2 | K19: 3661.59 | L19: 3772.255 | M19: 4004.36 | N19: 4343.86 | O19: 4865.99 | Q19: =SUM(O19-C19) -> 3266.803
A23: 2014 | B23: m³ | C23: Jan | D23: Feb | E23: Mrz | F23: Apr | G23: Mai | H23: Jun | I23: Jul | J23: Aug | K23: Sep | L23: Okt | M23: Nov | N23: Dez
C24: 41639 | D24: 41671 | E24: 41699 | F24: 41730 | G24: 41764 | H24: 41792 | I24: 41821 | J24: 41852 | K24: 41886 | L24: 41920 | M24: 41947 | N24: 41974 | O24: 42004
A25: Hauptzähler Internat | C25: 2490394.6 | D25: 2497766.7 | E25: 2506385.8 | F25: 2511284.8 | G25: 2515015 | H25: 2517686.7 | I25: 2518857.7 | J25: 2520714.2 | K25: 2523006.3 | L25: 2526512.8 | M25: 2531021.7 | N25: 2540310.9 | O25: 2554989.3 | Q25: =SUM(O25-C25) -> 64594.7
A26: Zwischenzähler Küche | C26: 6928.63 | D26: 6982 | E26: 7038.57 | F26: 7080.21 | G26: 7111.11 | H26: 7159.44 | I26: 7177.2 | J26: 7206.47 | K26: 7226.77 | L26: 7274.32 | M26: 7315.9 | N26: 7378.48 | O26: 7415.92 | R26: =SUM(O26-C26) -> 487.29
A27: Aula | C27: 203621.22 | D27: 204254.46 | E27: 204848.1 | F27: 205152.78 | G27: 205302.9 | H27: 205360.74 | I27: 205360.74 | J27: 205360.74 | K27: 205360.74 | L27: 205422.91 | M27: 205554.2 | N27: 205965.65 | O27: 206903.74 | Q27: =SUM(O27-C27) -> 3282.52
A28: Lichtenstern 13 | C28: 4865.99 | D28: 5198.32 | E28: 5601.87 | F28: 5833.84 | G28: 6015.61 | H28: 6135.654 | I28: 6142.51 | J28: 6142.512 | K28: 6142.517 | L28: 6142.52 | M28: 6142.52 | N28: 6142.52 | O28: 6142.52 | Q28: =SUM(O28-C28) -> 1276.53
A33: 2015 | B33: m³ | C33: Jan | D33: Feb | E33: Mrz | F33: Apr | G33: Mai | H33: Jun | I33: Jul | J33: Aug | K33: Sep | L33: Okt | M33: Nov | N33: Dez
C34: 42011 | D34: 42036 | E34: 42065 | F34: 42095 | G34: 42128 | H34: 42156 | I34: 42186 | J34: 42217 | K34: 42248 | L34: 42278 | M34: 42310 | N34: 41974 | O34: 42369 | Q34: =SUM(O34-C34) -> 358
A35: Hauptzähler Internat | C35: 2554989.3 | D35: 2566447.4 | E35: 2579459.2 | F35: 2589152.6 | G35: 2595544.1 | H35: 2598595.5 | I35: 2601468.2 | J35: 2603757.6 | K35: 2605297.7 | L35: 2610168.7 | M35: 2618174.2 | N35: 2626970.1 | O35: 2640719.2 | R35: =SUM(O35-C35) -> 85729.9
A36: Zwischenzähler Küche | C36: 7415.92 | D36: 7468.8 | E36: 7508.4 | F36: 7566.74 | G36: 7600 | H36: 7630.2 | I36: 7686.83 | J36: 7719.35 | K36: 7746.35 | L36: 7788.97 | M36: 7857.45 | N36: 7915.36 | O36: 7953.92 | Q36: =SUM(O36-C36) -> 538
A37: Aula | C37: 206903.74 | D37: 207612.78 | E37: 208422.7 | F37: 208893.7 | G37: 209121.39 | H37: 209122.7 | I37: 209122.7 | J37: 209122.77 | K37: 209122.77 | L37: 209191.9 | M37: 209469.99 | N37: 209899.11 | O37: 210611.2 | Q37: =SUM(O37-C37) -> 3707.46
A42: 2016 | B42: m³ | C42: Jan | D42: Feb | E42: Mrz | F42: Apr | G42: Mai | H42: Jun | I42: Jul | J42: Aug | K42: Sep | L42: Okt | M42: Nov | N42: Dez
C43: 42376 | D43: 42402 | E43: 42430 | F43: 42461 | G43: 42492 | H43: 42522 | I43: 42552 | J43: 42594 | K43: 42614 | L43: 42644 | M43: 42676 | N43: 42705 | O43: 42735 | Q43: =SUM(O43-C43) -> 359
A44: Hauptzähler Internat | C44: 2640719.2 | D44: 2650552.4 | E44: 2661835.3 | F44: 2672823.1 | G44: 2680927.7 | H44: 2685900.2 | I44: 2689055.5 | J44: 2692781.6 | K44: 2694316.9 | L44: 2698948.3 | M44: 2706188.4 | N44: 2717395.6 | O44: 2735689.3 | R44: =SUM(O44-C44) -> 94970.1
A45: Zwischenzähler Küche | C45: 7953.92 | D45: 8002.1 | E45: 8041.62 | F45: 8073.22 | G45: 8128.37 | H45: 8156.48 | I45: 8224.2 | J45: 8286.12 | K45: 8286.12 | L45: 8335.7 | M45: 8379.5 | N45: 8431.88 | O45: 8476.4 | Q45: =SUM(O45-C45) -> 522.48
A46: Aula | C46: 210611.2 | D46: 211170.9 | E46: 211881.8 | F46: 212442.18 | G46: 212727 | H46: 212777.5 | I46: 212777.5 | J46: 212777.5 | K46: 212777.58 | L46: 212841.3 | M46: 213063.9 | N46: 213671.5 | O46: 214762.22 | Q46: =SUM(O46-C46) -> 4151.02
A50: 2017 | B50: m³ | C50: Jan | D50: Feb | E50: Mrz | F50: Apr | G50: Mai | H50: Jun | I50: Jul | J50: Aug | K50: Sep | L50: Okt | M50: Nov | N50: Dez
C51: 42744 | D51: 42767 | E51: 42800 | F51: 42826 | G51: 42857 | H51: 42887 | I51: 42917 | J51: 42948 | K51: 42979 | L51: 43012 | M51: 43041 | N51: 43070 | O51: 43100 | Q51: =SUM(O51-C51) -> 356
A52: Hauptzähler Internat | C52: 2735689.3 | D52: 2747740.5 | E52: 2760193 | F52: 2767825.5 | G52: 2774730.9 | H52: 2779241.3 | I52: 2781920 | J52: 2783594.5 | K52: 2786158 | L52: 2792582.8 | M52: 2797836.3 | N52: 2808347.9 | O52: 2824187 | R52: =SUM(O52-C52) -> 88497.7
A53: Zwischenzähler Küche | C53: 8476.4 | D53: 8512.1 | E53: 8558.8 | F53: 8607.1 | G53: 8633.17 | H53: 8678.4 | I53: 8714.29 | J53: 8732 | K53: 8755.9 | L53: 8810.13 | M53: 8853.62 | N53: 8900.1 | O53: 8947.18 | Q53: =SUM(O53-C53) -> 470.78
A54: Aula | C54: 214762.22 | D54: 215604.7 | E54: 216325.71 | F54: 216640.8 | G54: 216874.2 | H54: 216955.3 | I54: 216955.5 | J54: 216955.7 | K54: 216955.7 | L54: 217049.4 | M54: 217290.52 | N54: 217733.2 | O54: 218543.6 | Q54: =SUM(O54-C54) -> 3781.38
A58: 2018 | B58: m³ | C58: Jan | D58: Feb | E58: Mrz | F58: Apr | G58: Mai | H58: Jun | I58: Jul | J58: Aug | K58: Sep | L58: Okt | M58: Nov | N58: Dez
C59: 43109 | D59: 43132 | E59: 43160 | F59: 43193 | G59: 43222 | H59: 43255 | I59: 43282 | J59: 43319 | K59: 43346 | L59: 43374 | M59: 43409 | N59: 43437 | O59: 43465 | Q59: =SUM(O59-C59) -> 356
A60: Hauptzähler Internat | C60: 2824187 | D60: 2833779 | E60: 2847096.3 | F60: 2858403.6 | G60: 2861526.3 | H60: 2864658.3 | I60: 2866907 | J60: 2869623.2 | K60: 2871597.5 | L60: 2873905.1 | M60: 2879592.2 | N60: 2889220.1 | O60: 2903435.2 | R60: =SUM(O60-C60) -> 79248.2
A61: Zwischenzähler Küche | C61: 8947.18 | D61: 8990.66 | E61: 9018.57 | F61: 9059 | G61: 9097.6 | H61: 9134 | I61: 9196 | J61: 9219.22 | K61: 9219.22 | L61: 9270.39 | M61: 9312.49 | N61: 9359.4 | O61: 9392 | Q61: =SUM(O61-C61) -> 444.82
A62: Aula | C62: 1588.3 | D62: 2146.8 | E62: 3095.96 | F62: 3659.72 | G62: 3764.82 | H62: 3785.9 | I62: 3785.9 | J62: 3785.9 | K62: 3785.9 | L62: 3804.6 | M62: 3935 | N62: 4479.2 | O62: 5385.26 | Q62: =SUM(O62-C62) -> 3796.96
A66: 2019 | B66: m³ | C66: Jan | D66: Feb | E66: Mrz | F66: Apr | G66: Mai | H66: Jun | I66: Jul | J66: Aug | K66: Sep | L66: Okt | M66: Nov | N66: Dez
...

Sheet Verbrauch Gas
A1: Verbrauch Gas
A4: ='Ablesewerte Gas'!A4 -> 2012 | B4: ='Ablesewerte Gas'!B4 -> m³ | C4: ='Ablesewerte Gas'!C4 -> Jan | D4: ='Ablesewerte Gas'!D4 -> Feb | E4: ='Ablesewerte Gas'!E4 -> Mrz | F4: ='Ablesewerte Gas'!F4 -> Apr | G4: ='Ablesewerte Gas'!G4 -> Mai | H4: ='Ablesewerte Gas'!H4 -> Jun | ... N4: ='Ablesewerte Gas'!N4 -> Dez
A6: ='Ablesewerte Gas'!A6 -> Hauptzähler Internat | C6: =SUM('Ablesewerte Gas'!D6-'Ablesewerte Gas'!C6) -> 11397.9 | D6: =SUM('Ablesewerte Gas'!E6-'Ablesewerte Gas'!D6) -> 12084 | E6: =SUM('Ablesewerte Gas'!F6-'Ablesewerte Gas'!E6) -> 5906.2 | F6: =SUM('Ablesewerte Gas'!G6-'Ablesewerte Gas'!F6) -> 4279 | G6: =SUM('Ablesewerte Gas'!H6-'Ablesewerte Gas'!G6) -> 2228 | H6: =SUM('Ablesewerte Gas'!I6-'Ablesewerte Gas'!H6) -> 1734.8 | I6: =SUM('Ablesewerte Gas'!J6-'Ablesewerte Gas'!I6) -> 1250.4 | J6: =SUM('Ablesewerte Gas'!K6-'Ablesewerte Gas'!J6) -> 1473.4 | ... N6: =SUM('Ablesewerte Gas'!O6-'Ablesewerte Gas'!N6) -> 10491.2 | P6: =SUM(C6:O6) -> 66272.9
A7: ='Ablesewerte Gas'!A7 -> Zwischenzähler Küche | C7: =SUM('Ablesewerte Gas'!D7-'Ablesewerte Gas'!C7) -> 99.71 | D7: =SUM('Ablesewerte Gas'!E7-'Ablesewerte Gas'!D7) -> 78.13 | E7: =SUM('Ablesewerte Gas'!F7-'Ablesewerte Gas'!E7) -> 91.13 | F7: =SUM('Ablesewerte Gas'!G7-'Ablesewerte Gas'!F7) -> 56.16 | G7: =SUM('Ablesewerte Gas'!H7-'Ablesewerte Gas'!G7) -> 83.85 | H7: =SUM('Ablesewerte Gas'!I7-'Ablesewerte Gas'!H7) -> 58.34 | I7: =SUM('Ablesewerte Gas'!J7-'Ablesewerte Gas'!I7) -> 48.49 | J7: =SUM('Ablesewerte Gas'!K7-'Ablesewerte Gas'!J7) -> 26.72 | ... N7: =SUM('Ablesewerte Gas'!O7-'Ablesewerte Gas'!N7) -> 67.26 | P7: =SUM(C7:O7) -> 847.45
A8: ='Ablesewerte Gas'!A8 -> alte Aula | C8: =SUM('Ablesewerte Gas'!D8-'Ablesewerte Gas'!C8) -> 849.02 | D8: =SUM('Ablesewerte Gas'!E8-'Ablesewerte Gas'!D8) -> 895.09 | E8: =SUM('Ablesewerte Gas'!F8-'Ablesewerte Gas'!E8) -> 369.96 | F8: =SUM('Ablesewerte Gas'!G8-'Ablesewerte Gas'!F8) -> 176.67 | G8: =SUM('Ablesewerte Gas'!H8-'Ablesewerte Gas'!G8) -> 47.64 | H8: =SUM('Ablesewerte Gas'!I8-'Ablesewerte Gas'!H8) -> 0 | I8: =SUM('Ablesewerte Gas'!J8-'Ablesewerte Gas'!I8) -> 0 | J8: =SUM('Ablesewerte Gas'!K8-'Ablesewerte Gas'!J8) -> 0 | ... N8: =SUM('Ablesewerte Gas'!O8-'Ablesewerte Gas'!N8) -> 693.03 | P8: =SUM(C8:O8) -> 3892.4
A9: ='Ablesewerte Gas'!A9 -> Lichtenstern 13 | C9: =SUM('Ablesewerte Gas'!D9-'Ablesewerte Gas'!C9) -> 505.04 | D9: =SUM('Ablesewerte Gas'!E9-'Ablesewerte Gas'!D9) -> 614.8 | E9: =SUM('Ablesewerte Gas'!F9-'Ablesewerte Gas'!E9) -> 332.39 | F9: =SUM('Ablesewerte Gas'!G9-'Ablesewerte Gas'!F9) -> 302.59 | G9: 111.32 | H9: =SUM('Ablesewerte Gas'!I9-'Ablesewerte Gas'!H9) -> 85.782 | I9: =SUM('Ablesewerte Gas'!J9-'Ablesewerte Gas'!I9) -> 62.448 | J9: =SUM('Ablesewerte Gas'!K9-'Ablesewerte Gas'!J9) -> 83.66 | K9: =SUM('Ablesewerte Gas'!L9-'Ablesewerte Gas'!K9) -> 93.11 | L9: =SUM('Ablesewerte Gas'!M9-'Ablesewerte Gas'!L9) -> 265.83 | M9: =SUM('Ablesewerte Gas'!N9-'Ablesewerte Gas'!M9) -> 364.939 | N9: =SUM('Ablesewerte Gas'!O9-'Ablesewerte Gas'!N9) -> 532.098 | P9: =SUM(C9:N9) -> 3354.007
A12: 2013 | B12: ='Ablesewerte Gas'!B14 -> m³ | C12: Jan | D12: Feb | E12: Mrz | F12: Apr | G12: Mai | H12: Jun | I12: Jul | J12: Aug | K12: Sep | L12: Okt | M12: Nov | N12: Dez
A14: Hauptzähler Internat | C14: =SUM('Ablesewerte Gas'!D16-'Ablesewerte Gas'!C16) -> 9617.1 | D14: =SUM('Ablesewerte Gas'!E16-'Ablesewerte Gas'!D16) -> 10586.7 | E14: =SUM('Ablesewerte Gas'!F16-'Ablesewerte Gas'!E16) -> 9132.7 | F14: =SUM('Ablesewerte Gas'!G16-'Ablesewerte Gas'!F16) -> 5025.6 | G14: =SUM('Ablesewerte Gas'!H16-'Ablesewerte Gas'!G16) -> 3176.9 | H14: =SUM('Ablesewerte Gas'!I16-'Ablesewerte Gas'!H16) -> 1727.8 | I14: =SUM('Ablesewerte Gas'!J16-'Ablesewerte Gas'!I16) -> 1275.1 | J14: =SUM('Ablesewerte Gas'!K16-'Ablesewerte Gas'!J16) -> 1145.9 | ... N14: =SUM('Ablesewerte Gas'!O16-'Ablesewerte Gas'!N16) -> 10466 | P14: =SUM(C14:O14) -> 66303.6
A15: Zwischenzähler Küche | C15: =SUM('Ablesewerte Gas'!D17-'Ablesewerte Gas'!C17) -> 47.95 | D15: =SUM('Ablesewerte Gas'!E17-'Ablesewerte Gas'!D17) -> 40.31 | E15: =SUM('Ablesewerte Gas'!F17-'Ablesewerte Gas'!E17) -> 48.89 | F15: =SUM('Ablesewerte Gas'!G17-'Ablesewerte Gas'!F17) -> 59.04 | G15: =SUM('Ablesewerte Gas'!H17-'Ablesewerte Gas'!G17) -> 22.44 | H15: =SUM('Ablesewerte Gas'!I17-'Ablesewerte Gas'!H17) -> 55.71 | I15: =SUM('Ablesewerte Gas'!J17-'Ablesewerte Gas'!I17) -> 31.72 | J15: =SUM('Ablesewerte Gas'!K17-'Ablesewerte Gas'!J17) -> 17.05 | ... N15: =SUM('Ablesewerte Gas'!O17-'Ablesewerte Gas'!N17) -> 44.86 | P15: =SUM(C15:O15) -> 550.79
A16: alte Aula | C16: =SUM('Ablesewerte Gas'!D18-'Ablesewerte Gas'!C18) -> 750.86 | D16: =SUM('Ablesewerte Gas'!E18-'Ablesewerte Gas'!D18) -> 868.19 | E16: =SUM('Ablesewerte Gas'!F18-'Ablesewerte Gas'!E18) -> 775.93 | F16: =SUM('Ablesewerte Gas'!G18-'Ablesewerte Gas'!F18) -> 247.89 | G16: =SUM('Ablesewerte Gas'!H18-'Ablesewerte Gas'!G18) -> 67.51 | H16: =SUM('Ablesewerte Gas'!I18-'Ablesewerte Gas'!H18) -> 3 | I16: =SUM('Ablesewerte Gas'!J18-'Ablesewerte Gas'!I18) -> 0 | J16: =SUM('Ablesewerte Gas'!K18-'Ablesewerte Gas'!J18) -> 0 | ... N16: =SUM('Ablesewerte Gas'!O18-'Ablesewerte Gas'!N18) -> 794.42 | P16: =SUM(C16:O16) -> 4396.1
A17: Lichtenstern 13 | C17: =SUM('Ablesewerte Gas'!D19-'Ablesewerte Gas'!C19) -> 433.803 | D17: =SUM('Ablesewerte Gas'!E19-'Ablesewerte Gas'!D19) -> 510.855 | E17: =SUM('Ablesewerte Gas'!F19-'Ablesewerte Gas'!E19) -> 456.575 | F17: =SUM('Ablesewerte Gas'!G19-'Ablesewerte Gas'!F19) -> 231.27 | G17: =SUM('Ablesewerte Gas'!H19-'Ablesewerte Gas'!G19) -> 186.63 | H17: =SUM('Ablesewerte Gas'!I19-'Ablesewerte Gas'!H19) -> 95.5 | I17: =SUM('Ablesewerte Gas'!J19-'Ablesewerte Gas'!I19) -> 84.38 | J17: =SUM('Ablesewerte Gas'!K19-'Ablesewerte Gas'!J19) -> 63.39 | ... N17: =SUM('Ablesewerte Gas'!O19-'Ablesewerte Gas'!N19) -> 522.13 | P17: =SUM(C17:O17) -> 3266.803
A21: 2014 | B21: ='Ablesewerte Gas'!B23 -> m³ | C21: Jan | D21: Feb | E21: Mrz | F21: Apr | G21: Mai | H21: Jun | I21: Jul | J21: Aug | K21: Sep | L21: Okt | M21: Nov | N21: Dez
A23: Hauptzähler Internat | C23: =SUM('Ablesewerte Gas'!D25-'Ablesewerte Gas'!C25) -> 7372.1 | D23: =SUM('Ablesewerte Gas'!E25-'Ablesewerte Gas'!D25) -> 8619.1 | E23: =SUM('Ablesewerte Gas'!F25-'Ablesewerte Gas'!E25) -> 4899 | F23: =SUM('Ablesewerte Gas'!G25-'Ablesewerte Gas'!F25) -> 3730.2 | G23: =SUM('Ablesewerte Gas'!H25-'Ablesewerte Gas'!G25) -> 2671.7 | H23: =SUM('Ablesewerte Gas'!I25-'Ablesewerte Gas'!H25) -> 1171 | I23: =SUM('Ablesewerte Gas'!J25-'Ablesewerte Gas'!I25) -> 1856.5 | J23: =SUM('Ablesewerte Gas'!K25-'Ablesewerte Gas'!J25) -> 2292.1 | ... N23: =SUM('Ablesewerte Gas'!O25-'Ablesewerte Gas'!N25) -> 14678.4 | P23: =SUM(C23:O23) -> 64594.7
A24: Zwischenzähler Küche | C24: =SUM('Ablesewerte Gas'!D26-'Ablesewerte Gas'!C26) -> 53.37 | D24: =SUM('Ablesewerte Gas'!E26-'Ablesewerte Gas'!D26) -> 56.57 | E24: =SUM('Ablesewerte Gas'!F26-'Ablesewerte Gas'!E26) -> 41.64 | F24: =SUM('Ablesewerte Gas'!G26-'Ablesewerte Gas'!F26) -> 30.9 | G24: =SUM('Ablesewerte Gas'!H26-'Ablesewerte Gas'!G26) -> 48.33 | H24: =SUM('Ablesewerte Gas'!I26-'Ablesewerte Gas'!H26) -> 17.76 | I24: =SUM('Ablesewerte Gas'!J26-'Ablesewerte Gas'!I26) -> 29.27 | J24: =SUM('Ablesewerte Gas'!K26-'Ablesewerte Gas'!J26) -> 20.3 | ... N24: =SUM('Ablesewerte Gas'!O26-'Ablesewerte Gas'!N26) -> 37.44 | P24: =SUM(C24:O24) -> 487.29
A25: alte Aula | C25: =SUM('Ablesewerte Gas'!D27-'Ablesewerte Gas'!C27) -> 633.24 | D25: =SUM('Ablesewerte Gas'!E27-'Ablesewerte Gas'!D27) -> 593.64 | E25: =SUM('Ablesewerte Gas'!F27-'Ablesewerte Gas'!E27) -> 304.68 | F25: =SUM('Ablesewerte Gas'!G27-'Ablesewerte Gas'!F27) -> 150.12 | G25: =SUM('Ablesewerte Gas'!H27-'Ablesewerte Gas'!G27) -> 57.84 | H25: =SUM('Ablesewerte Gas'!I27-'Ablesewerte Gas'!H27) -> 0 | I25: =SUM('Ablesewerte Gas'!J27-'Ablesewerte Gas'!I27) -> 0 | J25: =SUM('Ablesewerte Gas'!K27-'Ablesewerte Gas'!J27) -> 0 | ... N25: =SUM('Ablesewerte Gas'!O27-'Ablesewerte Gas'!N27) -> 938.09 | P25: =SUM(C25:O25) -> 3282.52
A26: Lichtenstern 13 | C26: =SUM('Ablesewerte Gas'!D28-'Ablesewerte Gas'!C28) -> 332.33 | D26: =SUM('Ablesewerte Gas'!E28-'Ablesewerte Gas'!D28) -> 403.55 | E26: =SUM('Ablesewerte Gas'!F28-'Ablesewerte Gas'!E28) -> 231.97 | F26: =SUM('Ablesewerte Gas'!G28-'Ablesewerte Gas'!F28) -> 181.77 | G26: =SUM('Ablesewerte Gas'!H28-'Ablesewerte Gas'!G28) -> 120.044 | H26: =SUM('Ablesewerte Gas'!I28-'Ablesewerte Gas'!H28) -> 6.856 | I26: =SUM('Ablesewerte Gas'!J28-'Ablesewerte Gas'!I28) -> 0.002 | J26: =SUM('Ablesewerte Gas'!K28-'Ablesewerte Gas'!J28) -> 0.005 | ... N26: =SUM('Ablesewerte Gas'!O28-'Ablesewerte Gas'!N28) -> 0 | P26: =SUM(C26:O26) -> 1276.53
A30: 2015 | B30: m³ | C30: Jan | D30: Feb | E30: Mrz | F30: Apr | G30: Mai | H30: Jun | I30: Jul | J30: Aug | K30: Sep | L30: Okt | M30: Nov | N30: Dez
A32: Hauptzähler Internat | C32: =SUM('Ablesewerte Gas'!D35-'Ablesewerte Gas'!C35) -> 11458.1 | D32: =SUM('Ablesewerte Gas'!E35-'Ablesewerte Gas'!D35) -> 13011.8 | E32: =SUM('Ablesewerte Gas'!F35-'Ablesewerte Gas'!E35) -> 9693.4 | F32: =SUM('Ablesewerte Gas'!G35-'Ablesewerte Gas'!F35) -> 6391.5 | G32: =SUM('Ablesewerte Gas'!H35-'Ablesewerte Gas'!G35) -> 3051.4 | H32: =SUM('Ablesewerte Gas'!I35-'Ablesewerte Gas'!H35) -> 2872.7 | I32: =SUM('Ablesewerte Gas'!J35-'Ablesewerte Gas'!I35) -> 2289.4 | J32: =SUM('Ablesewerte Gas'!K35-'Ablesewerte Gas'!J35) -> 1540.1 | ... N32: =SUM('Ablesewerte Gas'!O35-'Ablesewerte Gas'!N35) -> 13749.1 | P32: =SUM(C32:O32) -> 85729.9
A33: Zwischenzähler Küche | C33: =SUM('Ablesewerte Gas'!D36-'Ablesewerte Gas'!C36) -> 52.88 | D33: =SUM('Ablesewerte Gas'!E36-'Ablesewerte Gas'!D36) -> 39.6 | E33: =SUM('Ablesewerte Gas'!F36-'Ablesewerte Gas'!E36) -> 58.34 | F33: =SUM('Ablesewerte Gas'!G36-'Ablesewerte Gas'!F36) -> 33.26 | G33: =SUM('Ablesewerte Gas'!H36-'Ablesewerte Gas'!G36) -> 30.2 | H33: =SUM('Ablesewerte Gas'!I36-'Ablesewerte Gas'!H36) -> 56.63 | I33: =SUM('Ablesewerte Gas'!J36-'Ablesewerte Gas'!I36) -> 32.52 | J33: =SUM('Ablesewerte Gas'!K36-'Ablesewerte Gas'!J36) -> 27 | ... N33: =SUM('Ablesewerte Gas'!O36-'Ablesewerte Gas'!N36) -> 38.56 | P33: =SUM(C33:O33) -> 538
A34: alte Aula | C34: =SUM('Ablesewerte Gas'!D37-'Ablesewerte Gas'!C37) -> 709.04 | D34: =SUM('Ablesewerte Gas'!E37-'Ablesewerte Gas'!D37) -> 809.92 | E34: =SUM('Ablesewerte Gas'!F37-'Ablesewerte Gas'!E37) -> 471 | F34: =SUM('Ablesewerte Gas'!G37-'Ablesewerte Gas'!F37) -> 227.69 | G34: =SUM('Ablesewerte Gas'!H37-'Ablesewerte Gas'!G37) -> 1.31 | H34: =SUM('Ablesewerte Gas'!I37-'Ablesewerte Gas'!H37) -> 0 | I34: =SUM('Ablesewerte Gas'!J37-'Ablesewerte Gas'!I37) -> 0.07 | J34: =SUM('Ablesewerte Gas'!K37-'Ablesewerte Gas'!J37) -> 0 | ... N34: =SUM('Ablesewerte Gas'!O37-'Ablesewerte Gas'!N37) -> 712.09 | P34: =SUM(C34:O34) -> 3707.46
A35: Lichtenstern 13
A38: 2016 | B38: m³ | C38: Jan | D38: Feb | E38: Mrz | F38: Apr | G38: Mai | H38: Jun | I38: Jul | J38: Aug | K38: Sep | L38: Okt | M38: Nov | N38: Dez
A40: Hauptzähler Internat | C40: =SUM('Ablesewerte Gas'!D44-'Ablesewerte Gas'!C44) -> 9833.2 | D40: =SUM('Ablesewerte Gas'!E44-'Ablesewerte Gas'!D44) -> 11282.9 | E40: =SUM('Ablesewerte Gas'!F44-'Ablesewerte Gas'!E44) -> 10987.8 | F40: =SUM('Ablesewerte Gas'!G44-'Ablesewerte Gas'!F44) -> 8104.6 | G40: =SUM('Ablesewerte Gas'!H44-'Ablesewerte Gas'!G44) -> 4972.5 | H40: =SUM('Ablesewerte Gas'!I44-'Ablesewerte Gas'!H44) -> 3155.3 | I40: =SUM('Ablesewerte Gas'!J44-'Ablesewerte Gas'!I44) -> 3726.1 | J40: =SUM('Ablesewerte Gas'!K44-'Ablesewerte Gas'!J44) -> 1535.3 | ... N40: =SUM('Ablesewerte Gas'!O44-'Ablesewerte Gas'!N44) -> 18293.7 | P40: =SUM(C40:O40) -> 94970.1
A41: Zwischenzähler Küche | C41: =SUM('Ablesewerte Gas'!D45-'Ablesewerte Gas'!C45) -> 48.18 | D41: =SUM('Ablesewerte Gas'!E45-'Ablesewerte Gas'!D45) -> 39.52 | E41: =SUM('Ablesewerte Gas'!F45-'Ablesewerte Gas'!E45) -> 31.6 | F41: =SUM('Ablesewerte Gas'!G45-'Ablesewerte Gas'!F45) -> 55.15 | G41: =SUM('Ablesewerte Gas'!H45-'Ablesewerte Gas'!G45) -> 28.11 | H41: =SUM('Ablesewerte Gas'!I45-'Ablesewerte Gas'!H45) -> 67.72 | I41: =SUM('Ablesewerte Gas'!J45-'Ablesewerte Gas'!I45) -> 61.92 | J41: =SUM('Ablesewerte Gas'!K45-'Ablesewerte Gas'!J45) -> 0 | ... N41: =SUM('Ablesewerte Gas'!O45-'Ablesewerte Gas'!N45) -> 44.52 | P41: =SUM(C41:O41) -> 522.48
A42: alte Aula | C42: =SUM('Ablesewerte Gas'!D46-'Ablesewerte Gas'!C46) -> 559.7 | D42: =SUM('Ablesewerte Gas'!E46-'Ablesewerte Gas'!D46) -> 710.9 | E42: =SUM('Ablesewerte Gas'!F46-'Ablesewerte Gas'!E46) -> 560.38 | F42: =SUM('Ablesewerte Gas'!G46-'Ablesewerte Gas'!F46) -> 284.82 | G42: =SUM('Ablesewerte Gas'!H46-'Ablesewerte Gas'!G46) -> 50.5 | H42: =SUM('Ablesewerte Gas'!I46-'Ablesewerte Gas'!H46) -> 0 | I42: =SUM('Ablesewerte Gas'!J46-'Ablesewerte Gas'!I46) -> 0 | J42: =SUM('Ablesewerte Gas'!K46-'Ablesewerte Gas'!J46) -> 0.08 | ... N42: =SUM('Ablesewerte Gas'!O46-'Ablesewerte Gas'!N46) -> 1090.72 | P42: =SUM(C42:O42) -> 4151.02
A46: 2017 | B46: m³ | C46: Jan | D46: Feb | E46: Mrz | F46: Apr | G46: Mai | H46: Jun | I46: Jul | J46: Aug | K46: Sep | L46: Okt | M46: Nov | N46: Dez
A48: Hauptzähler Internat | C48: =SUM('Ablesewerte Gas'!D52-'Ablesewerte Gas'!C52) -> 12051.2 | D48: =SUM('Ablesewerte Gas'!E52-'Ablesewerte Gas'!D52) -> 12452.5 | E48: =SUM('Ablesewerte Gas'!F52-'Ablesewerte Gas'!E52) -> 7632.5 | F48: =SUM('Ablesewerte Gas'!G52-'Ablesewerte Gas'!F52) -> 6905.4 | G48: =SUM('Ablesewerte Gas'!H52-'Ablesewerte Gas'!G52) -> 4510.4 | H48: =SUM('Ablesewerte Gas'!I52-'Ablesewerte Gas'!H52) -> 2678.7 | I48: =SUM('Ablesewerte Gas'!J52-'Ablesewerte Gas'!I52) -> 1674.5 | J48: =SUM('Ablesewerte Gas'!K52-'Ablesewerte Gas'!J52) -> 2563.5 | ... N48: =SUM('Ablesewerte Gas'!O52-'Ablesewerte Gas'!N52) -> 15839.1 | P48: =SUM(C48:O48) -> 88497.7
A49: Zwischenzähler Küche | C49: =SUM('Ablesewerte Gas'!D53-'Ablesewerte Gas'!C53) -> 35.7 | D49: =SUM('Ablesewerte Gas'!E53-'Ablesewerte Gas'!D53) -> 46.7 | E49: =SUM('Ablesewerte Gas'!F53-'Ablesewerte Gas'!E53) -> 48.3 | F49: =SUM('Ablesewerte Gas'!G53-'Ablesewerte Gas'!F53) -> 26.07 | G49: =SUM('Ablesewerte Gas'!H53-'Ablesewerte Gas'!G53) -> 45.23 | H49: =SUM('Ablesewerte Gas'!I53-'Ablesewerte Gas'!H53) -> 35.89 | I49: =SUM('Ablesewerte Gas'!J53-'Ablesewerte Gas'!I53) -> 17.71 | J49: =SUM('Ablesewerte Gas'!K53-'Ablesewerte Gas'!J53) -> 23.9 | ... N49: =SUM('Ablesewerte Gas'!O53-'Ablesewerte Gas'!N53) -> 47.08 | P49: =SUM(C49:O49) -> 470.78
A50: alte Aula | C50: =SUM('Ablesewerte Gas'!D54-'Ablesewerte Gas'!C54) -> 842.48 | D50: =SUM('Ablesewerte Gas'!E54-'Ablesewerte Gas'!D54) -> 721.01 | E50: =SUM('Ablesewerte Gas'!F54-'Ablesewerte Gas'!E54) -> 315.09 | F50: =SUM('Ablesewerte Gas'!G54-'Ablesewerte Gas'!F54) -> 233.4 | G50: =SUM('Ablesewerte Gas'!H54-'Ablesewerte Gas'!G54) -> 81.1 | H50: =SUM('Ablesewerte Gas'!I54-'Ablesewerte Gas'!H54) -> 0.2 | I50: =SUM('Ablesewerte Gas'!J54-'Ablesewerte Gas'!I54) -> 0.2 | J50: =SUM('Ablesewerte Gas'!K54-'Ablesewerte Gas'!J54) -> 0 | ... N50: =SUM('Ablesewerte Gas'!O54-'Ablesewerte Gas'!N54) -> 810.4 | P50: =SUM(C50:O50) -> 3781.38
A55: 2018 | B55: m³ | C55: Jan | D55: Feb | E55: Mrz | F55: Apr | G55: Mai | H55: Jun | I55: Jul | J55: Aug | K55: Sep | L55: Okt | M55: Nov | N55: Dez
A57: Hauptzähler Internat | C57: =SUM('Ablesewerte Gas'!D60-'Ablesewerte Gas'!C60) -> 9592 | D57: =SUM('Ablesewerte Gas'!E60-'Ablesewerte Gas'!D60) -> 13317.3 | E57: =SUM('Ablesewerte Gas'!F60-'Ablesewerte Gas'!E60) -> 11307.3 | F57: =SUM('Ablesewerte Gas'!G60-'Ablesewerte Gas'!F60) -> 3122.7 | G57: =SUM('Ablesewerte Gas'!H60-'Ablesewerte Gas'!G60) -> 3132 | H57: =SUM('Ablesewerte Gas'!I60-'Ablesewerte Gas'!H60) -> 2248.7 | I57: =SUM('Ablesewerte Gas'!J60-'Ablesewerte Gas'!I60) -> 2716.2 | J57: =SUM('Ablesewerte Gas'!K60-'Ablesewerte Gas'!J60) -> 1974.3 | ... N57: =SUM('Ablesewerte Gas'!O60-'Ablesewerte Gas'!N60) -> 14215.1 | P57: =SUM(C57:O57) -> 79248.2
A58: Zwischenzähler Küche | C58: =SUM('Ablesewerte Gas'!D61-'Ablesewerte Gas'!C61) -> 43.48 | D58: =SUM('Ablesewerte Gas'!E61-'Ablesewerte Gas'!D61) -> 27.91 | E58: =SUM('Ablesewerte Gas'!F61-'Ablesewerte Gas'!E61) -> 40.43 | F58: =SUM('Ablesewerte Gas'!G61-'Ablesewerte Gas'!F61) -> 38.6 | G58: =SUM('Ablesewerte Gas'!H61-'Ablesewerte Gas'!G61) -> 36.4 | H58: =SUM('Ablesewerte Gas'!I61-'Ablesewerte Gas'!H61) -> 62 | I58: =SUM('Ablesewerte Gas'!J61-'Ablesewerte Gas'!I61) -> 23.22 | J58: =SUM('Ablesewerte Gas'!K61-'Ablesewerte Gas'!J61) -> 0 | ... N58: =SUM('Ablesewerte Gas'!O61-'Ablesewerte Gas'!N61) -> 32.6 | P58: =SUM(C58:O58) -> 444.82
A59: alte Aula | C59: =SUM('Ablesewerte Gas'!D62-'Ablesewerte Gas'!C62) -> 558.5 | D59: =SUM('Ablesewerte Gas'!E62-'Ablesewerte Gas'!D62) -> 949.16 | E59: =SUM('Ablesewerte Gas'!F62-'Ablesewerte Gas'!E62) -> 563.76 | F59: =SUM('Ablesewerte Gas'!G62-'Ablesewerte Gas'!F62) -> 105.1 | G59: =SUM('Ablesewerte Gas'!H62-'Ablesewerte Gas'!G62) -> 21.08 | H59: =SUM('Ablesewerte Gas'!I62-'Ablesewerte Gas'!H62) -> 0 | I59: =SUM('Ablesewerte Gas'!J62-'Ablesewerte Gas'!I62) -> 0 | J59: =SUM('Ablesewerte Gas'!K62-'Ablesewerte Gas'!J62) -> 0 | ... N59: =SUM('Ablesewerte Gas'!O62-'Ablesewerte Gas'!N62) -> 906.06 | P59: =SUM(C59:O59) -> 3796.96
A65: 2019 | B65: m³ | C65: Jan | D65: Feb | E65: Mrz | F65: Apr | G65: Mai | H65: Jun | I65: Jul | J65: Aug | K65: Sep | L65: Okt | M65: Nov | N65: Dez
A67: Hauptzähler Internat | C67: =SUM('Ablesewerte Gas'!D68-'Ablesewerte Gas'!C68) -> 12076 | D67: =SUM('Ablesewerte Gas'!E68-'Ablesewerte Gas'!D68) -> 11341.2 | E67: =SUM('Ablesewerte Gas'!F68-'Ablesewerte Gas'!E68) -> 9672.8 | F67: =SUM('Ablesewerte Gas'!G68-'Ablesewerte Gas'!F68) -> 6954.1 | G67: =SUM('Ablesewerte Gas'!H68-'Ablesewerte Gas'!G68) -> 6134.7 | H67: =SUM('Ablesewerte Gas'!I68-'Ablesewerte Gas'!H68) -> 2325.2 | I67: =SUM('Ablesewerte Gas'!J68-'Ablesewerte Gas'!I68) -> 3682 | J67: =SUM('Ablesewerte Gas'!K68-'Ablesewerte Gas'!J68) -> 2542.8 | ... N67: =SUM('Ablesewerte Gas'!O68-'Ablesewerte Gas'!N68) -> 5496.1 | P67: =SUM(C67:O67) -> 82933.9
A68: Zwischenzähler Küche | C68: =SUM('Ablesewerte Gas'!D69-'Ablesewerte Gas'!C69) -> 41.62 | D68: =SUM('Ablesewerte Gas'!E69-'Ablesewerte Gas'!D69) -> 48.12 | E68: =SUM('Ablesewerte Gas'!F69-'Ablesewerte Gas'!E69) -> 34.43 | F68: =SUM('Ablesewerte Gas'!G69-'Ablesewerte Gas'!F69) -> 31.26 | G68: =SUM('Ablesewerte Gas'!H69-'Ablesewerte Gas'!G69) -> 37.84 | H68: =SUM('Ablesewerte Gas'!I69-'Ablesewerte Gas'!H69) -> 13.22 | I68: =SUM('Ablesewerte Gas'!J69-'Ablesewerte Gas'!I69) -> 40.9 | J68: =SUM('Ablesewerte Gas'!K69-'Ablesewerte Gas'!J69) -> 1.79 | ... N68: =SUM('Ablesewerte Gas'!O69-'Ablesewerte Gas'!N69) -> 15.83 | P68: =SUM(C68:O68) -> 415.53
A69: alte Aula | C69: =SUM('Ablesewerte Gas'!D70-'Ablesewerte Gas'!C70) -> 793.41 | D69: =SUM('Ablesewerte Gas'!E70-'Ablesewerte Gas'!D70) -> 621.33 | E69: =SUM('Ablesewerte Gas'!F70-'Ablesewerte Gas'!E70) -> 356.7 | F69: =SUM('Ablesewerte Gas'!G70-'Ablesewerte Gas'!F70) -> 158.5 | G69: =SUM('Ablesewerte Gas'!H70-'Ablesewerte Gas'!G70) -> 132.46 | H69: =SUM('Ablesewerte Gas'!I70-'Ablesewerte Gas'!H70) -> 0 | I69: =SUM('Ablesewerte Gas'!J70-'Ablesewerte Gas'!I70) -> 0 | J69: =SUM('Ablesewerte Gas'!K70-'Ablesewerte Gas'!J70) -> 92.8 | ... N69: =SUM('Ablesewerte Gas'!O70-'Ablesewerte Gas'!N70) -> 263.66 | P69: =SUM(C69:N69) -> 3342.81
G70: =SUM('Ablesewerte Gas'!H71-'Ablesewerte Gas'!G71) -> 0
A72: 2020 | B72: m³ | C72: Jan | D72: Feb | E72: Mrz | F72: Apr | G72: Mai | H72: Jun | I72: Jul | J72: Aug | K72: Sep | L72: Okt | M72: Nov | N72: Dez
A74: Hauptzähler Internat | C74: =SUM('Ablesewerte Gas'!D76-'Ablesewerte Gas'!C76) -> 18133.1 | D74: =SUM('Ablesewerte Gas'!E76-'Ablesewerte Gas'!D76) -> 9960 | E74: =SUM('Ablesewerte Gas'!F76-'Ablesewerte Gas'!E76) -> 9138.2 | F74: =SUM('Ablesewerte Gas'!G76-'Ablesewerte Gas'!F76) -> 5291.1 | G74: =SUM('Ablesewerte Gas'!H76-'Ablesewerte Gas'!G76) -> 4813.3 | H74: =SUM('Ablesewerte Gas'!I76-'Ablesewerte Gas'!H76) -> 2868.2 | I74: =SUM('Ablesewerte Gas'!J76-'Ablesewerte Gas'!I76) -> 2451.2 | J74: =SUM('Ablesewerte Gas'!K76-'Ablesewerte Gas'!J76) -> 2251.6 | ... N74: =SUM('Ablesewerte Gas'!O76-'Ablesewerte Gas'!N76) -> 17319.3 | P74: =SUM(C74:O74) -> 97711.4
...

Sheet Ablesewerte Strom
A2: 2012 | Q2: Verbrauch
A3: Strom | B3: kWh | C3: Jan | D3: Feb | E3: Mrz | F3: Apr | G3: Mai | H3: Jun | I3: Jul | J3: Aug | K3: Sep | L3: Okt | M3: Nov | N3: Dez | Q3: pro Messstelle
C4: 40908 | D4: 40940 | E4: 40969 | F4: 41000 | G4: 41031 | H4: 41061 | I4: 41092 | J4: 41117 | K4: 41153 | L4: 04.10.2012 | M4: 41218 | N4: 41247 | O4: 41274
A5: Internat | C5: 327383.8 | D5: 331826.8 | E5: 335501.6 | F5: 339532.3 | G5: 342183.9 | H5: 344905.3 | I5: 346980.3 | J5: 348875.2 | K5: 350516 | L5: 353171.3 | M5: 356948.9 | N5: 360682.2 | O5: 364580.7 | Q5: =SUM(O5-C5) -> 37196.9
A6: UZ Aula * | C6: 183317.3 | D6: 186544.5 | E6: 189105.5 | F6: 191949.9 | G6: 193766.4 | H6: 195468.4 | I6: 196623.5 | J6: 197738.3 | K6: 198856.4 | L6: 200671.8 | M6: 203318.7 | N6: 206038.1 | O6: 208914.2 | Q6: =SUM(O6-C6) -> 25596.9 | R6: =SUM(Q5-Q6) -> 11600
A7: L13 Internat | C7: 38142.5 | D7: 38222.5 | E7: 38286.5 | F7: 38343.5 | G7: 38367 | H7: 38399.5 | I7: 38499.4 | J7: 38502.2 | K7: 38502.2 | L7: 38560.7 | M7: 38622.3 | N7: 38664.7 | O7: 38690.7 | Q7: =SUM(O7-C7) -> 548.2
A8: L13 Gemeinschaft | C8: 49269.2 | D8: 49428 | E8: 49551.5 | F8: 49695.6 | G8: 49816.3 | H8: 49931.6 | I8: 50046.8 | J8: 50165.6 | K8: 50298.8 | L8: 50400 | M8: 50544.2 | N8: 50663.6 | O8: 50812.1 | Q8: =SUM(O8-C8) -> 1542.9
A9: Schule** | P9: keine Ablesung möglich
A10: UZ P002 | C10: 4714.8 | D10: 4784.07 | E10: 4848.45 | F10: 4929.19 | G10: 4980.8 | H10: 5056.18 | I10: 5122.06 | J10: 5182.24 | K10: 5246.44 | L10: 5304.09 | M10: 5382.36 | N10: 5451.51 | O10: 5512.46 | Q10: =SUM(O10-C10) -> 797.66
A11: UZ P003 | C11: 2094.61 | D11: 2122.3 | E11: 2147.61 | F11: 2176.93 | G11: 2195.04 | H11: 2220.14 | I11: 2242.86 | J11: 2263.39 | K11: 2279.52 | L11: 2302.32 | M11: 2336.57 | N11: 2371.23 | O11: 2401.09 | Q11: =SUM(O11-C11) -> 306.48
A12: UZ P004 | C12: 76204.8 | D12: 77316.7 | E12: 78249.6 | F12: 79261.9 | G12: 79889.7 | H12: 80598.2 | I12: 81351.9 | J12: 81871.7 | K12: 82438.3 | L12: 83104.1 | M12: 84119.2 | N12: 85276.7 | O12: 86290.7 | Q12: =SUM(O12-C12) -> 10085.9 | S12: Container
A13: UZ P9 | C13: 5128.1 | D13: 5380 | E13: 6382.9 | F13: 6618.2 | G13: 6678 | H13: 6678 | I13: 6678 | J13: 6678 | K13: 6678 | L13: 6678 | M13: 6678 | N13: 6678 | O13: 6678 | Q13: =SUM(O13-C13) -> 1549.9 | S13: =SUM(Q13:Q14) -> 1859.7
A14: UZ P10 | C14: 7409.3 | D14: 7444.8 | E14: 7541.6 | F14: 7641.3 | G14: 7699.8 | H14: 7714.5 | I14: 7715.2 | J14: 7715.5 | K14: 7715.9 | L14: 7716.5 | M14: 7717.6 | N14: 7718.3 | O14: 7719.1 | Q14: =SUM(O14-C14) -> 309.8
A15: Sporthalle** | P15: keine Ablesung möglich
A16: Sporthalle UZ P4 | C16: 93767.2 | D16: 94979 | E16: 96077.8 | F16: 97210.4 | G16: 98210.9 | H16: 99138.8 | I16: 100062.6 | J16: 100801.2 | K16: 101143.3 | L16: 101965.1 | M16: 103135.9 | N16: 104163.6 | O16: 105579.6 | Q16: =SUM(O16-C16) -> 11812.4
A21: 2013
A22: Strom | B22: kWh | C22: Jan | D22: Feb | E22: Mrz | F22: Apr | G22: Mai | H22: Jun | I22: Jul | J22: Aug | K22: Sep | L22: Okt | M22: Nov | N22: Dez
C23: 41274 | D23: 41306 | E23: 41334 | F23: 41366 | G23: 41397 | H23: 41429 | I23: 41456 | J23: 41487 | K23: 41519 | L23: 41548 | M23: 41582 | N23: 41610 | O23: 41639
A24: Internat | C24: 364580.7 | D24: 367942.7 | E24: 371233.9 | F24: 374692.2 | G24: 377757.1 | H24: 380477.9 | I24: 382451.8 | J24: 383952.2 | K24: 385102.2 | L24: 387240 | M24: 390221.8 | N24: 393847.1 | O24: 397816.7
A25: UZ Aula * | C25: 208914.2 | D25: 211374.3 | E25: 213778.4 | F25: 216319.7 | G25: 218416.4 | H25: 220403.7 | I25: 221631.9 | J25: 222502.5 | K25: 223226.9 | L25: 224622.6 | M25: 226738.8 | N25: 229495 | O25: 232489.1
A26: L13 Internat | C26: 38690.7 | D26: 38718.8 | E26: 38749.4 | F26: 38766.2 | G26: 38802.8 | H26: 38826 | I26: 38834.9 | J26: 38843.8 | K26: 38843.8 | L26: 38909.2 | M26: 38962.4 | N26: 39058.7 | O26: 39110.3
A27: L13 Gemeinschaft | C27: 50812.1 | D27: 50923.4 | E27: 51045.1 | F27: 51180.9 | G27: 51317.4 | H27: 51455.8 | I27: 51555.4 | J27: 51665.6 | K27: 51779 | L27: 51887.6 | M27: 52027.2 | N27: 52148.2 | O27: 52301.6
A28: Schule** | P28: keine Ablesung möglich
A29: UZ P002 | C29: 5512.46 | D29: 5573.65 | E29: 5630.62 | F29: 5694.42 | G29: 5765.3 | H29: 5813.9 | I29: 5885.82 | J29: 5959.3 | K29: 6002.78 | L29: 6065.34 | M29: 6135.13 | N29: 6209.9 | O29: 6277.25
A30: UZ P003 | C30: 2401.09 | D30: 2430.19 | E30: 2458.26 | F30: 2487.06 | G30: 2514.9 | H30: 2535.25 | I30: 2561.56 | J30: 2582.5 | K30: 2594.27 | L30: 2619.32 | M30: 2650.56 | N30: 2684.98 | O30: 2714.73
A31: UZ P004 | C31: 86290.7 | D31: 87229.6 | E31: 88171.6 | F31: 89000.1 | G31: 89768.7 | H31: 90333.5 | I31: 90953.7 | J31: 91432.7 | K31: 91801.8 | L31: 92499.7 | M31: 93408.7 | N31: 94529.9 | O31: 95567.3
A32: UZ P9 | C32: 6678 | D32: 6678 | E32: 6678 | F32: 6678 | G32: 6678 | H32: 6678 | I32: 6678 | J32: 6678 | K32: 6678 | L32: 6678 | M32: 6678 | N32: 6678 | O32: 6678
A33: UZ P10 | C33: 7719.1 | D33: 7719.4 | E33: 7719.8 | F33: 7720.1 | G33: 7720.7 | H33: 7720.9 | I33: 7721.3 | J33: 7811 | K33: 7811.1 | L33: 7811.4 | M33: 7811.4 | N33: 7811.4 | O33: 7811.4
A34: Sporthalle** | P34: keine Ablesung möglich
A35: Sporthalle UZ P4 | C35: 105579.6 | D35: 106537.4 | E35: 107594.9 | F35: 108771.3 | G35: 109805.2 | H35: 110723.2 | I35: 111475.8 | J35: 112177.2 | K35: 112376.1 | L35: 113159.7 | M35: 114187.1 | N35: 115107.1 | O35: 116089.6
A40: 2014
A41: Strom | B41: kWh | C41: Jan | D41: Feb | E41: Mrz | F41: Apr | G41: Mai | H41: Jun | I41: Jul | J41: Aug | K41: Sep | L41: Okt | M41: Nov | N41: Dez
C42: 41639 | D42: 41671 | E42: 41699 | F42: 41730 | G42: 41764 | H42: 41792 | I42: 41821 | J42: 41852 | K42: 41886 | L42: 41920 | M42: 41947 | N42: 41974 | O42: 42004
A43: Internat | C43: 397816.7 | D43: 400929.3 | E43: 404619.6 | F43: 407523 | G43: 410361.8 | H43: 412882.3 | I43: 414557.2 | J43: 416612.3 | K43: 418086.8 | L43: 420119.2 | M43: 422027.4 | N43: 424498.3 | O43: 427634.1
A44: UZ Aula * | C44: 232489.1 | D44: 234809 | E44: 237535.6 | F44: 239682.6 | G44: 241789.9 | H44: 243546.2 | I44: 244568.4 | J44: 245730.9 | K44: 246591.4 | L44: 247823.3 | M44: 249042.2 | N44: 250706.2 | O44: 252916.7
A45: L13 Internat | C45: 39110.3 | D45: 39174.8 | E45: 39223.7 | F45: 39244.4 | G45: 39263.1 | H45: 39293.4 | I45: 39298.4 | J45: 39315.9 | K45: 39317.9 | L45: 39393.8 | M45: 39439.5 | N45: 39500.5 | O45: 39544.3
A46: L13 Gemeinschaft | C46: 52301.6 | D46: 52403 | E46: 52537.7 | F46: 52650.9 | G46: 52790.3 | H46: 52898.3 | I46: 53177.7 | J46: 53542.3 | K46: 53929.3 | L46: 54122.5 | M46: 54169.5 | N46: 54215.9 | O46: 54277.7
A47: Schule** | P47: keine Ablesung möglich
A48: UZ P002 | C48: 6277.25 | D48: 6337.09 | E48: 6411.26 | F48: 6470.15 | G48: 6525.01 | H48: 6596.6 | I48: 6645.27 | J48: 6712.38 | K48: 6773.26 | L48: 6843.75 | M48: 6900.6 | N48: 6968.95 | O48: 7032.58
A49: UZ P003 | C49: 2714.73 | D49: 2740.72 | E49: 2773.8 | F49: 2797.84 | G49: 2818.86 | H49: 2844 | I49: 2860.72 | J49: 2884.96 | K49: 2901.32 | L49: 2930.56 | M49: 2955.8 | N49: 2988.41 | O49: 3021.68
...

Sheet Verbrauch Strom
A2: 2012
A3: Strom | D3: Jan | E3: Feb | F3: Mrz | G3: Apr | H3: Mai | I3: Jun | J3: Jul | K3: Aug | L3: Sep | M3: Okt | N3: Nov | O3: Dez
A5: Internat | D5: =SUM('Ablesewerte Strom'!D5-'Ablesewerte Strom'!C5) -> 4443 | E5: =SUM('Ablesewerte Strom'!E5-'Ablesewerte Strom'!D5) -> 3674.8 | F5: =SUM('Ablesewerte Strom'!F5-'Ablesewerte Strom'!E5) -> 4030.7 | G5: =SUM('Ablesewerte Strom'!G5-'Ablesewerte Strom'!F5) -> 2651.6 | H5: =SUM('Ablesewerte Strom'!H5-'Ablesewerte Strom'!G5) -> 2721.4 | I5: =SUM('Ablesewerte Strom'!I5-'Ablesewerte Strom'!H5) -> 2075 | J5: =SUM('Ablesewerte Strom'!J5-'Ablesewerte Strom'!I5) -> 1894.9 | K5: =SUM('Ablesewerte Strom'!K5-'Ablesewerte Strom'!J5) -> 1640.8 | ... O5: =SUM('Ablesewerte Strom'!O5-'Ablesewerte Strom'!N5) -> 3898.5 | Q5: =SUM(D5:O5) -> 37196.9
A6: UZ Aula * | D6: =SUM('Ablesewerte Strom'!D6-'Ablesewerte Strom'!C6) -> 3227.2 | E6: =SUM('Ablesewerte Strom'!E6-'Ablesewerte Strom'!D6) -> 2561 | F6: =SUM('Ablesewerte Strom'!F6-'Ablesewerte Strom'!E6) -> 2844.4 | G6: =SUM('Ablesewerte Strom'!G6-'Ablesewerte Strom'!F6) -> 1816.5 | H6: =SUM('Ablesewerte Strom'!H6-'Ablesewerte Strom'!G6) -> 1702 | I6: =SUM('Ablesewerte Strom'!I6-'Ablesewerte Strom'!H6) -> 1155.1 | J6: =SUM('Ablesewerte Strom'!J6-'Ablesewerte Strom'!I6) -> 1114.8 | K6: =SUM('Ablesewerte Strom'!K6-'Ablesewerte Strom'!J6) -> 1118.1 | ... O6: =SUM('Ablesewerte Strom'!O6-'Ablesewerte Strom'!N6) -> 2876.1 | Q6: =SUM(D6:O6) -> 25596.9
A7: L13 Internat | D7: =SUM('Ablesewerte Strom'!D7-'Ablesewerte Strom'!C7) -> 80 | E7: =SUM('Ablesewerte Strom'!E7-'Ablesewerte Strom'!D7) -> 64 | F7: =SUM('Ablesewerte Strom'!F7-'Ablesewerte Strom'!E7) -> 57 | G7: =SUM('Ablesewerte Strom'!G7-'Ablesewerte Strom'!F7) -> 23.5 | H7: =SUM('Ablesewerte Strom'!H7-'Ablesewerte Strom'!G7) -> 32.5 | I7: =SUM('Ablesewerte Strom'!I7-'Ablesewerte Strom'!H7) -> 99.9 | J7: =SUM('Ablesewerte Strom'!J7-'Ablesewerte Strom'!I7) -> 2.8 | K7: =SUM('Ablesewerte Strom'!K7-'Ablesewerte Strom'!J7) -> 0 | ... O7: =SUM('Ablesewerte Strom'!O7-'Ablesewerte Strom'!N7) -> 26 | Q7: =SUM(D7:O7) -> 548.2
A8: L13 Gemeinschaft | D8: =SUM('Ablesewerte Strom'!D8-'Ablesewerte Strom'!C8) -> 158.8 | E8: =SUM('Ablesewerte Strom'!E8-'Ablesewerte Strom'!D8) -> 123.5 | F8: =SUM('Ablesewerte Strom'!F8-'Ablesewerte Strom'!E8) -> 144.1 | G8: =SUM('Ablesewerte Strom'!G8-'Ablesewerte Strom'!F8) -> 120.7 | H8: =SUM('Ablesewerte Strom'!H8-'Ablesewerte Strom'!G8) -> 115.3 | I8: =SUM('Ablesewerte Strom'!I8-'Ablesewerte Strom'!H8) -> 115.2 | J8: =SUM('Ablesewerte Strom'!J8-'Ablesewerte Strom'!I8) -> 118.8 | K8: =SUM('Ablesewerte Strom'!K8-'Ablesewerte Strom'!J8) -> 133.2 | ... O8: =SUM('Ablesewerte Strom'!O8-'Ablesewerte Strom'!N8) -> 148.5 | Q8: =SUM(D8:O8) -> 1542.9
A9: Schule**
Q10: =SUM(D9:O10) -> 0
A11: UZ P002*** | D11: =SUM('Ablesewerte Strom'!D10-'Ablesewerte Strom'!C10) -> 69.27 | E11: =SUM('Ablesewerte Strom'!E10-'Ablesewerte Strom'!D10) -> 64.38 | F11: =SUM('Ablesewerte Strom'!F10-'Ablesewerte Strom'!E10) -> 80.74 | G11: =SUM('Ablesewerte Strom'!G10-'Ablesewerte Strom'!F10) -> 51.61 | H11: =SUM('Ablesewerte Strom'!H10-'Ablesewerte Strom'!G10) -> 75.38 | I11: =SUM('Ablesewerte Strom'!I10-'Ablesewerte Strom'!H10) -> 65.88 | J11: =SUM('Ablesewerte Strom'!J10-'Ablesewerte Strom'!I10) -> 60.18 | K11: =SUM('Ablesewerte Strom'!K10-'Ablesewerte Strom'!J10) -> 64.2 | ... O11: =SUM('Ablesewerte Strom'!O10-'Ablesewerte Strom'!N10) -> 60.95 | P11: =SUM(D11:O11) -> 797.66 | T11: =SUM('Ablesewerte Strom'!T11-'Ablesewerte Strom'!S11) -> 0
A12: UZ P003*** | D12: =SUM('Ablesewerte Strom'!D11-'Ablesewerte Strom'!C11) -> 27.69 | E12: =SUM('Ablesewerte Strom'!E11-'Ablesewerte Strom'!D11) -> 25.31 | F12: =SUM('Ablesewerte Strom'!F11-'Ablesewerte Strom'!E11) -> 29.32 | G12: =SUM('Ablesewerte Strom'!G11-'Ablesewerte Strom'!F11) -> 18.11 | H12: =SUM('Ablesewerte Strom'!H11-'Ablesewerte Strom'!G11) -> 25.1 | I12: =SUM('Ablesewerte Strom'!I11-'Ablesewerte Strom'!H11) -> 22.72 | J12: =SUM('Ablesewerte Strom'!J11-'Ablesewerte Strom'!I11) -> 20.53 | K12: =SUM('Ablesewerte Strom'!K11-'Ablesewerte Strom'!J11) -> 16.13 | ... O12: =SUM('Ablesewerte Strom'!O11-'Ablesewerte Strom'!N11) -> 29.86 | P12: =SUM(D12:O12) -> 306.48
A13: UZ P004*** | D13: =SUM('Ablesewerte Strom'!D12-'Ablesewerte Strom'!C12) -> 1111.9 | E13: =SUM('Ablesewerte Strom'!E12-'Ablesewerte Strom'!D12) -> 932.9 | F13: =SUM('Ablesewerte Strom'!F12-'Ablesewerte Strom'!E12) -> 1012.3 | G13: =SUM('Ablesewerte Strom'!G12-'Ablesewerte Strom'!F12) -> 627.8 | H13: =SUM('Ablesewerte Strom'!H12-'Ablesewerte Strom'!G12) -> 708.5 | I13: =SUM('Ablesewerte Strom'!I12-'Ablesewerte Strom'!H12) -> 753.7 | J13: =SUM('Ablesewerte Strom'!J12-'Ablesewerte Strom'!I12) -> 519.8 | K13: =SUM('Ablesewerte Strom'!K12-'Ablesewerte Strom'!J12) -> 566.6 | ... O13: =SUM('Ablesewerte Strom'!O12-'Ablesewerte Strom'!N12) -> 1014 | P13: =SUM(D13:O13) -> 10085.9
A14: UZ P9*** | D14: =SUM('Ablesewerte Strom'!D13-'Ablesewerte Strom'!C13) -> 251.9 | E14: =SUM('Ablesewerte Strom'!E13-'Ablesewerte Strom'!D13) -> 1002.9 | F14: =SUM('Ablesewerte Strom'!F13-'Ablesewerte Strom'!E13) -> 235.3 | G14: =SUM('Ablesewerte Strom'!G13-'Ablesewerte Strom'!F13) -> 59.8 | H14: =SUM('Ablesewerte Strom'!H13-'Ablesewerte Strom'!G13) -> 0 | I14: =SUM('Ablesewerte Strom'!I13-'Ablesewerte Strom'!H13) -> 0 | J14: =SUM('Ablesewerte Strom'!J13-'Ablesewerte Strom'!I13) -> 0 | K14: =SUM('Ablesewerte Strom'!K13-'Ablesewerte Strom'!J13) -> 0 | ... O14: =SUM('Ablesewerte Strom'!O13-'Ablesewerte Strom'!N13) -> 0 | P14: =SUM(D14:O14) -> 1549.9
A15: UZ P10*** | D15: =SUM('Ablesewerte Strom'!D14-'Ablesewerte Strom'!C14) -> 35.5 | E15: =SUM('Ablesewerte Strom'!E14-'Ablesewerte Strom'!D14) -> 96.8 | F15: =SUM('Ablesewerte Strom'!F14-'Ablesewerte Strom'!E14) -> 99.7 | G15: =SUM('Ablesewerte Strom'!G14-'Ablesewerte Strom'!F14) -> 58.5 | H15: =SUM('Ablesewerte Strom'!H14-'Ablesewerte Strom'!G14) -> 14.7 | I15: =SUM('Ablesewerte Strom'!I14-'Ablesewerte Strom'!H14) -> 0.7 | J15: =SUM('Ablesewerte Strom'!J14-'Ablesewerte Strom'!I14) -> 0.3 | K15: =SUM('Ablesewerte Strom'!K14-'Ablesewerte Strom'!J14) -> 0.4 | ... O15: =SUM('Ablesewerte Strom'!O14-'Ablesewerte Strom'!N14) -> 0.8 | P15: =SUM(D15:O15) -> 309.8
A16: Sporthalle**
Q17: =SUM(D16:O17) -> 0
A18: Sporthalle UZ P4*** | D18: =SUM('Ablesewerte Strom'!D16-'Ablesewerte Strom'!C16) -> 1211.8 | E18: =SUM('Ablesewerte Strom'!E16-'Ablesewerte Strom'!D16) -> 1098.8 | F18: =SUM('Ablesewerte Strom'!F16-'Ablesewerte Strom'!E16) -> 1132.6 | G18: =SUM('Ablesewerte Strom'!G16-'Ablesewerte Strom'!F16) -> 1000.5 | H18: =SUM('Ablesewerte Strom'!H16-'Ablesewerte Strom'!G16) -> 927.9 | I18: =SUM('Ablesewerte Strom'!I16-'Ablesewerte Strom'!H16) -> 923.8 | J18: =SUM('Ablesewerte Strom'!J16-'Ablesewerte Strom'!I16) -> 738.6 | K18: =SUM('Ablesewerte Strom'!K16-'Ablesewerte Strom'!J16) -> 342.1 | ... O18: =SUM('Ablesewerte Strom'!O16-'Ablesewerte Strom'!N16) -> 1416 | P18: =SUM(D18:O18) -> 11812.4 | Q18: KWH | R18: =SUM(Q5:Q17) -> 64884.9
A21: 2013
A22: Strom | D22: Jan | E22: Feb | F22: Mrz | G22: Apr | H22: Mai | I22: Jun | J22: Jul | K22: Aug | L22: Sep | M22: Okt | N22: Nov | O22: Dez
A24: Internat | D24: =SUM('Ablesewerte Strom'!D24-'Ablesewerte Strom'!C24) -> 3362 | E24: =SUM('Ablesewerte Strom'!E24-'Ablesewerte Strom'!D24) -> 3291.2 | F24: =SUM('Ablesewerte Strom'!F24-'Ablesewerte Strom'!E24) -> 3458.3 | G24: =SUM('Ablesewerte Strom'!G24-'Ablesewerte Strom'!F24) -> 3064.9 | H24: =SUM('Ablesewerte Strom'!H24-'Ablesewerte Strom'!G24) -> 2720.8 | I24: =SUM('Ablesewerte Strom'!I24-'Ablesewerte Strom'!H24) -> 1973.9 | J24: =SUM('Ablesewerte Strom'!J24-'Ablesewerte Strom'!I24) -> 1500.4 | K24: =SUM('Ablesewerte Strom'!K24-'Ablesewerte Strom'!J24) -> 1150 | ... O24: =SUM('Ablesewerte Strom'!O24-'Ablesewerte Strom'!N24) -> 3969.6 | Q24: =SUM(D24:O24) -> 33236
A25: UZ Aula * | D25: =SUM('Ablesewerte Strom'!D25-'Ablesewerte Strom'!C25) -> 2460.1 | E25: =SUM('Ablesewerte Strom'!E25-'Ablesewerte Strom'!D25) -> 2404.1 | F25: =SUM('Ablesewerte Strom'!F25-'Ablesewerte Strom'!E25) -> 2541.3 | G25: =SUM('Ablesewerte Strom'!G25-'Ablesewerte Strom'!F25) -> 2096.7 | H25: =SUM('Ablesewerte Strom'!H25-'Ablesewerte Strom'!G25) -> 1987.3 | I25: =SUM('Ablesewerte Strom'!I25-'Ablesewerte Strom'!H25) -> 1228.2 | J25: =SUM('Ablesewerte Strom'!J25-'Ablesewerte Strom'!I25) -> 870.6 | K25: =SUM('Ablesewerte Strom'!K25-'Ablesewerte Strom'!J25) -> 724.4 | ... O25: =SUM('Ablesewerte Strom'!O25-'Ablesewerte Strom'!N25) -> 2994.1 | Q25: =SUM(D25:O25) -> 23574.9
A26: L13 Internat | D26: =SUM('Ablesewerte Strom'!D26-'Ablesewerte Strom'!C26) -> 28.1 | E26: =SUM('Ablesewerte Strom'!E26-'Ablesewerte Strom'!D26) -> 30.6 | F26: =SUM('Ablesewerte Strom'!F26-'Ablesewerte Strom'!E26) -> 16.8 | G26: =SUM('Ablesewerte Strom'!G26-'Ablesewerte Strom'!F26) -> 36.6 | H26: =SUM('Ablesewerte Strom'!H26-'Ablesewerte Strom'!G26) -> 23.2 | I26: =SUM('Ablesewerte Strom'!I26-'Ablesewerte Strom'!H26) -> 8.9 | J26: =SUM('Ablesewerte Strom'!J26-'Ablesewerte Strom'!I26) -> 8.9 | K26: =SUM('Ablesewerte Strom'!K26-'Ablesewerte Strom'!J26) -> 0 | ... O26: =SUM('Ablesewerte Strom'!O26-'Ablesewerte Strom'!N26) -> 51.6 | Q26: =SUM(D26:O26) -> 419.6
A27: L13 Gemeinschaft | D27: =SUM('Ablesewerte Strom'!D27-'Ablesewerte Strom'!C27) -> 111.3 | E27: =SUM('Ablesewerte Strom'!E27-'Ablesewerte Strom'!D27) -> 121.7 | F27: =SUM('Ablesewerte Strom'!F27-'Ablesewerte Strom'!E27) -> 135.8 | G27: =SUM('Ablesewerte Strom'!G27-'Ablesewerte Strom'!F27) -> 136.5 | H27: =SUM('Ablesewerte Strom'!H27-'Ablesewerte Strom'!G27) -> 138.4 | I27: =SUM('Ablesewerte Strom'!I27-'Ablesewerte Strom'!H27) -> 99.6 | J27: =SUM('Ablesewerte Strom'!J27-'Ablesewerte Strom'!I27) -> 110.2 | K27: =SUM('Ablesewerte Strom'!K27-'Ablesewerte Strom'!J27) -> 113.4 | ... O27: =SUM('Ablesewerte Strom'!O27-'Ablesewerte Strom'!N27) -> 153.4 | Q27: =SUM(D27:O27) -> 1489.5
A28: Schule**
Q29: =SUM(D28:O29) -> 0
A30: UZ P002*** | D30: =SUM('Ablesewerte Strom'!D29-'Ablesewerte Strom'!C29) -> 61.19 | E30: =SUM('Ablesewerte Strom'!E29-'Ablesewerte Strom'!D29) -> 56.97 | F30: =SUM('Ablesewerte Strom'!F29-'Ablesewerte Strom'!E29) -> 63.8 | G30: =SUM('Ablesewerte Strom'!G29-'Ablesewerte Strom'!F29) -> 70.88 | H30: =SUM('Ablesewerte Strom'!H29-'Ablesewerte Strom'!G29) -> 48.6 | I30: =SUM('Ablesewerte Strom'!I29-'Ablesewerte Strom'!H29) -> 71.92 | J30: =SUM('Ablesewerte Strom'!J29-'Ablesewerte Strom'!I29) -> 73.48 | K30: =SUM('Ablesewerte Strom'!K29-'Ablesewerte Strom'!J29) -> 43.48 | ... O30: =SUM('Ablesewerte Strom'!O29-'Ablesewerte Strom'!N29) -> 67.35 | P30: =SUM(D30:O30) -> 764.79
A31: UZ P003*** | D31: =SUM('Ablesewerte Strom'!D30-'Ablesewerte Strom'!C30) -> 29.1 | E31: =SUM('Ablesewerte Strom'!E30-'Ablesewerte Strom'!D30) -> 28.07 | F31: =SUM('Ablesewerte Strom'!F30-'Ablesewerte Strom'!E30) -> 28.8 | G31: =SUM('Ablesewerte Strom'!G30-'Ablesewerte Strom'!F30) -> 27.84 | H31: =SUM('Ablesewerte Strom'!H30-'Ablesewerte Strom'!G30) -> 20.35 | I31: =SUM('Ablesewerte Strom'!I30-'Ablesewerte Strom'!H30) -> 26.31 | J31: =SUM('Ablesewerte Strom'!J30-'Ablesewerte Strom'!I30) -> 20.94 | K31: =SUM('Ablesewerte Strom'!K30-'Ablesewerte Strom'!J30) -> 11.77 | ... O31: =SUM('Ablesewerte Strom'!O30-'Ablesewerte Strom'!N30) -> 29.75 | P31: =SUM(D31:O31) -> 313.64
A32: UZ P004*** | D32: =SUM('Ablesewerte Strom'!D31-'Ablesewerte Strom'!C31) -> 938.9 | E32: =SUM('Ablesewerte Strom'!E31-'Ablesewerte Strom'!D31) -> 942 | F32: =SUM('Ablesewerte Strom'!F31-'Ablesewerte Strom'!E31) -> 828.5 | G32: =SUM('Ablesewerte Strom'!G31-'Ablesewerte Strom'!F31) -> 768.6 | H32: =SUM('Ablesewerte Strom'!H31-'Ablesewerte Strom'!G31) -> 564.8 | I32: =SUM('Ablesewerte Strom'!I31-'Ablesewerte Strom'!H31) -> 620.2 | J32: =SUM('Ablesewerte Strom'!J31-'Ablesewerte Strom'!I31) -> 479 | K32: =SUM('Ablesewerte Strom'!K31-'Ablesewerte Strom'!J31) -> 369.1 | ... O32: =SUM('Ablesewerte Strom'!O31-'Ablesewerte Strom'!N31) -> 1037.4 | P32: =SUM(D32:O32) -> 9276.6
A33: UZ P9*** | D33: =SUM('Ablesewerte Strom'!D32-'Ablesewerte Strom'!C32) -> 0 | E33: =SUM('Ablesewerte Strom'!E32-'Ablesewerte Strom'!D32) -> 0 | F33: =SUM('Ablesewerte Strom'!F32-'Ablesewerte Strom'!E32) -> 0 | G33: =SUM('Ablesewerte Strom'!G32-'Ablesewerte Strom'!F32) -> 0 | H33: =SUM('Ablesewerte Strom'!H32-'Ablesewerte Strom'!G32) -> 0 | I33: =SUM('Ablesewerte Strom'!I32-'Ablesewerte Strom'!H32) -> 0 | J33: =SUM('Ablesewerte Strom'!J32-'Ablesewerte Strom'!I32) -> 0 | K33: =SUM('Ablesewerte Strom'!K32-'Ablesewerte Strom'!J32) -> 0 | ... O33: =SUM('Ablesewerte Strom'!O32-'Ablesewerte Strom'!N32) -> 0 | P33: =SUM(D33:O33) -> 0
A34: UZ P10*** | D34: =SUM('Ablesewerte Strom'!D33-'Ablesewerte Strom'!C33) -> 0.3 | E34: =SUM('Ablesewerte Strom'!E33-'Ablesewerte Strom'!D33) -> 0.4 | F34: =SUM('Ablesewerte Strom'!F33-'Ablesewerte Strom'!E33) -> 0.3 | G34: =SUM('Ablesewerte Strom'!G33-'Ablesewerte Strom'!F33) -> 0.6 | H34: =SUM('Ablesewerte Strom'!H33-'Ablesewerte Strom'!G33) -> 0.2 | I34: =SUM('Ablesewerte Strom'!I33-'Ablesewerte Strom'!H33) -> 0.4 | J34: =SUM('Ablesewerte Strom'!J33-'Ablesewerte Strom'!I33) -> 89.7 | K34: =SUM('Ablesewerte Strom'!K33-'Ablesewerte Strom'!J33) -> 0.1 | ... O34: =SUM('Ablesewerte Strom'!O33-'Ablesewerte Strom'!N33) -> 0 | P34: =SUM(D34:O34) -> 92.3
A35: Sporthalle**
Q36: =SUM(D35:O36) -> 0
A37: Sporthalle UZ P4*** | D37: =SUM('Ablesewerte Strom'!D35-'Ablesewerte Strom'!C35) -> 957.8 | E37: =SUM('Ablesewerte Strom'!E35-'Ablesewerte Strom'!D35) -> 1057.5 | F37: =SUM('Ablesewerte Strom'!F35-'Ablesewerte Strom'!E35) -> 1176.4 | G37: =SUM('Ablesewerte Strom'!G35-'Ablesewerte Strom'!F35) -> 1033.9 | H37: =SUM('Ablesewerte Strom'!H35-'Ablesewerte Strom'!G35) -> 918 | I37: =SUM('Ablesewerte Strom'!I35-'Ablesewerte Strom'!H35) -> 752.6 | J37: =SUM('Ablesewerte Strom'!J35-'Ablesewerte Strom'!I35) -> 701.4 | K37: =SUM('Ablesewerte Strom'!K35-'Ablesewerte Strom'!J35) -> 198.9 | ... O37: =SUM('Ablesewerte Strom'!O35-'Ablesewerte Strom'!N35) -> 982.5 | P37: =SUM(D37:O37) -> 10510 | Q37: KWH | R37: =SUM(Q24:Q36) -> 58720
A44: 2014
A45: Strom | D45: Jan | E45: Feb | F45: Mrz | G45: Apr | H45: Mai | I45: Jun | J45: Jul | K45: Aug | L45: Sep | M45: Okt | N45: Nov | O45: Dez
A47: Internat | D47: =SUM('Ablesewerte Strom'!D43-'Ablesewerte Strom'!C43) -> 3112.6 | E47: =SUM('Ablesewerte Strom'!E43-'Ablesewerte Strom'!D43) -> 3690.3 | F47: =SUM('Ablesewerte Strom'!F43-'Ablesewerte Strom'!E43) -> 2903.4 | G47: =SUM('Ablesewerte Strom'!G43-'Ablesewerte Strom'!F43) -> 2838.8 | H47: =SUM('Ablesewerte Strom'!H43-'Ablesewerte Strom'!G43) -> 2520.5 | I47: =SUM('Ablesewerte Strom'!I43-'Ablesewerte Strom'!H43) -> 1674.9 | J47: =SUM('Ablesewerte Strom'!J43-'Ablesewerte Strom'!I43) -> 2055.1 | K47: =SUM('Ablesewerte Strom'!K43-'Ablesewerte Strom'!J43) -> 1474.5 | ... O47: =SUM('Ablesewerte Strom'!O43-'Ablesewerte Strom'!N43) -> 3135.8 | Q47: =SUM(D47:O47) -> 29817.4
A48: UZ Aula * | D48: =SUM('Ablesewerte Strom'!D44-'Ablesewerte Strom'!C44) -> 2319.9 | E48: =SUM('Ablesewerte Strom'!E44-'Ablesewerte Strom'!D44) -> 2726.6 | F48: =SUM('Ablesewerte Strom'!F44-'Ablesewerte Strom'!E44) -> 2147 | G48: =SUM('Ablesewerte Strom'!G44-'Ablesewerte Strom'!F44) -> 2107.3 | H48: =SUM('Ablesewerte Strom'!H44-'Ablesewerte Strom'!G44) -> 1756.3 | I48: =SUM('Ablesewerte Strom'!I44-'Ablesewerte Strom'!H44) -> 1022.2 | J48: =SUM('Ablesewerte Strom'!J44-'Ablesewerte Strom'!I44) -> 1162.5 | K48: =SUM('Ablesewerte Strom'!K48-'Ablesewerte Strom'!J48) -> 60.88 | L48: =SUM('Ablesewerte Strom'!L44-'Ablesewerte Strom'!K44) -> 1231.9 | M48: =SUM('Ablesewerte Strom'!M44-'Ablesewerte Strom'!L44) -> 1218.9 | N48: =SUM('Ablesewerte Strom'!N44-'Ablesewerte Strom'!M44) -> 1664 | O48: =SUM('Ablesewerte Strom'!O44-'Ablesewerte Strom'!N44) -> 2210.5 | Q48: =SUM(D48:O48) -> 19627.98
A49: L13 Internat | D49: =SUM('Ablesewerte Strom'!D45-'Ablesewerte Strom'!C45) -> 64.5 | E49: =SUM('Ablesewerte Strom'!E45-'Ablesewerte Strom'!D45) -> 48.9 | F49: =SUM('Ablesewerte Strom'!F45-'Ablesewerte Strom'!E45) -> 20.7 | G49: =SUM('Ablesewerte Strom'!G45-'Ablesewerte Strom'!F45) -> 18.7 | H49: =SUM('Ablesewerte Strom'!H45-'Ablesewerte Strom'!G45) -> 30.3 | I49: =SUM('Ablesewerte Strom'!I45-'Ablesewerte Strom'!H45) -> 5 | J49: =SUM('Ablesewerte Strom'!J45-'Ablesewerte Strom'!I45) -> 17.5 | K49: =SUM('Ablesewerte Strom'!K45-'Ablesewerte Strom'!J45) -> 2 | ... O49: =SUM('Ablesewerte Strom'!O45-'Ablesewerte Strom'!N45) -> 43.8 | Q49: =SUM(D49:O49) -> 434
A50: L13 Gemeinschaft | D50: =SUM('Ablesewerte Strom'!D46-'Ablesewerte Strom'!C46) -> 101.4 | E50: =SUM('Ablesewerte Strom'!E46-'Ablesewerte Strom'!D46) -> 134.7 | F50: =SUM('Ablesewerte Strom'!F46-'Ablesewerte Strom'!E46) -> 113.2 | G50: =SUM('Ablesewerte Strom'!G46-'Ablesewerte Strom'!F46) -> 139.4 | H50: =SUM('Ablesewerte Strom'!H46-'Ablesewerte Strom'!G46) -> 108 | I50: =SUM('Ablesewerte Strom'!I46-'Ablesewerte Strom'!H46) -> 279.4 | J50: =SUM('Ablesewerte Strom'!J46-'Ablesewerte Strom'!I46) -> 364.6 | K50: =SUM('Ablesewerte Strom'!K46-'Ablesewerte Strom'!J46) -> 387 | ... O50: =SUM('Ablesewerte Strom'!O46-'Ablesewerte Strom'!N46) -> 61.8 | Q50: =SUM(D50:O50) -> 1976.1
A51: Schule**
Q52: =SUM(D51:O52) -> 0
...

Sheet Ablesewerte Wasser
A3: 2012 | B3: m³ | C3: Jan | D3: Feb | E3: Mrz | F3: Apr | G3: Mai | H3: Jun | I3: Jul | J3: Aug | K3: Sep | L3: Okt | M3: Nov | N3: Dez | Q3: Verbrauch pro Messstelle
C4: 40908 | D4: 40940 | E4: 40969 | F4: 41000 | G4: 41031 | H4: 41061 | I4: 41092 | J4: 41117 | K4: 41153 | L4: 41186 | M4: 41218 | N4: 41247 | O4: 41274
A6: Zähler Schloss | C6: 5594 | D6: 5844 | E6: 6088 | F6: 6377 | G6: 6548 | H6: 6808 | I6: 7037 | J6: 7220 | K6: 7341 | L6: 7748 | M6: 8108 | N6: 8413 | O6: 8636 | Q6: =SUM(O6-C6) -> 3042
A7: davon Sporthalle | C7: 1861 | D7: 1886 | E7: 1924 | F7: 1952 | G7: 1970 | H7: 1986 | I7: 2003 | J7: 2021 | K7: 2025 | L7: 2048 | M7: 2119 | N7: 2150 | O7: 2173 | Q7: =SUM(O7-C7) -> 312
A8: Aula | C8: 66 | D8: 74 | E8: 80 | F8: 86 | G8: 91 | H8: 98 | I8: 103 | J8: 107 | K8: 112 | L8: 118 | M8: 125 | N8: 130 | O8: 134 | Q8: =SUM(O8-C8) -> 68
A9: Lichtenstern 13 | C9: 685 | D9: 708 | E9: 726 | F9: 750 | G9: 771 | H9: 792 | I9: 807 | J9: 819 | K9: 835 | L9: 850 | M9: 868 | N9: 881 | O9: 898 | Q9: =SUM(O9-C9) -> 213 | R9: gesamt
R10: =SUM(Q5:Q9) -> 3635 | S10: m³
A13: 2013 | B13: m³ | C13: Jan | D13: Feb | E13: Mrz | F13: Apr | G13: Mai | H13: Jun | I13: Jul | J13: Aug | K13: Sep | L13: Okt | M13: Nov | N13: Dez
C14: 41639 | D14: 41306 | E14: 41334 | F14: 41366 | G14: 41397 | H14: 41429 | I14: 41456 | J14: 41487 | K14: 41518 | L14: 41548 | M14: 41582 | N14: 41610 | O14: 41639
A16: Zähler Schloss | C16: 8636 | D16: 8884 | E16: 9103 | F16: 9322 | G16: 9599 | H16: 9747 | I16: 9998 | J16: 10466 | K16: 10733 | L16: 10943.09 | M16: 11185 | N16: 11442 | O16: 11665 | Q16: =SUM(O16-C16) -> 3029
A17: davon Sporthalle | C17: 2173 | D17: 2202 | E17: 2221 | F17: 2247 | G17: 2271 | H17: 2280 | I17: 2298 | J17: 2313 | K17: 2315 | L17: 2331 | M17: 2356 | N17: 2387 | O17: 2416 | Q17: =SUM(O17-C17) -> 243
A18: Aula | C18: 134 | D18: 141 | E18: 146 | F18: 151 | G18: 158 | H18: 160 | I18: 167 | J18: 172 | K18: 174 | L18: 179 | M18: 184 | N18: 192 | O18: 197 | Q18: =SUM(O18-C18) -> 63
A19: Lichtenstern 13 | C19: 898 | D19: 909 | E19: 922 | F19: 937 | G19: 951 | H19: 961 | I19: 974 | J19: 994 | K19: 1004 | L19: 1018 | M19: 1034 | N19: 1046 | O19: 1065 | Q19: =SUM(O19-C19) -> 167 | R19: gesamt
R20: =SUM(Q15:Q19) -> 3502 | S20: m³
A25: 2014 | B25: m³ | C25: Jan | D25: Feb | E25: Mrz | F25: Apr | G25: Mai | H25: Jun | I25: Jul | J25: Aug | K25: Sep | L25: Okt | M25: Nov | N25: Dez
C26: 41639 | D26: 41671 | E26: 41699 | F26: 41730 | G26: 41764 | H26: 41794 | I26: 41821 | J26: 41852 | K26: 41886 | L26: 41920 | M26: 41947 | N26: 41974 | O26: 42004
A28: Zähler Schloss | C28: 11665 | D28: 11873 | E28: 12133 | F28: 12345 | G28: 12518 | H28: 12746 | I28: 12886 | J28: 13093 | K28: 13194 | L28: 13394 | M28: 13573 | N28: 13784 | O28: 13967 | Q28: =SUM(O28-C28) -> 2302
A29: davon Sporthalle | C29: 2416 | D29: 2443 | E29: 2472 | F29: 2499 | G29: 2522 | H29: 2543 | I29: 2555 | J29: 2582 | K29: 2585 | L29: 2607 | M29: 2644 | N29: 2673 | O29: 2693 | Q29: =SUM(O29-C29) -> 277
A30: Aula | C30: 197 | D30: 203 | E30: 208 | F30: 214 | G30: 219 | H30: 225 | I30: 230 | J30: 234 | K30: 240 | L30: 245 | M30: 249 | N30: 260 | O30: 266 | Q30: =SUM(O30-C30) -> 69
A31: Lichtenstern 13 | C31: 1065 | D31: 1077 | E31: 1093 | F31: 1106 | G31: 1126 | H31: 1140 | I31: 1154 | J31: 14 | K31: 29 | L31: 43 | M31: 53 | N31: 64 | O31: 78 | Q31: =SUM(I31-C31)+(O31-J31) -> 153 | R31: gesamt
R32: =SUM(Q27:Q31) -> 2801 | S32: m³
A37: 2015 | B37: m³ | C37: Jan | D37: Feb | E37: Mrz | F37: Apr | G37: Mai | H37: Jun | I37: Jul | J37: Aug | K37: Sep | L37: Okt | M37: Nov | N37: Dez
C38: 42011 | D38: 42036 | E38: 42064 | F38: 42095 | G38: 42128 | H38: 42156 | I38: 42186 | J38: 42217 | K38: 42248 | L38: 42278 | M38: 42310 | N38: 42339 | O38: 42369
A40: Zähler Schloss | C40: 13967 | D40: 14158 | E40: 14333 | F40: 14564 | G40: 14784 | H40: 14942 | I40: 15177 | J40: 15592 | K40: 15677 | L40: 15875 | M40: 16165 | N40: 16415 | O40: 16598 | Q40: =SUM(O40-C40) -> 2631
A41: davon Sporthalle | C41: 2693 | D41: 2721 | E41: 2747 | F41: 2783 | G41: 2802 | H41: 2818 | I41: 2836 | J41: 2854 | K41: 2858 | L41: 2875 | M41: 2907 | N41: 2928 | O41: 2950 | Q41: =SUM(O41-C41) -> 257
A42: Aula | C42: 266 | D42: 271 | E42: 277 | F42: 281 | G42: 285 | H42: 291 | I42: 295 | J42: 299 | K42: 301 | L42: 305 | M42: 312 | N42: 317 | O42: 325 | Q42: =SUM(O42-C42) -> 59
A43: Lichtenstern 13 | C43: 78 | D43: 87 | E43: 97 | F43: 109 | G43: 117 | H43: 126 | I43: 135 | J43: 139 | K43: 152 | L43: 159 | M43: 168 | N43: 177 | O43: 192 | Q43: =SUM(I43-C43)+(O43-J43) -> 110 | R43: gesamt
R44: =SUM(Q39:Q43) -> 3057 | S44: m³
A49: 2016 | B49: m³ | C49: Jan | D49: Feb | E49: Mrz | F49: Apr | G49: Mai | H49: Jun | I49: Jul | J49: Aug | K49: Sep | L49: Okt | M49: Nov | N49: Dez
C50: 42380 | D50: 42401 | E50: 42430 | F50: 42461 | G50: 42492 | H50: 42522 | I50: 42552 | J50: 42594 | K50: 42614 | L50: 42644 | M50: 42676 | N50: 42705 | O50: 42735
A52: Zähler Schloss | C52: 1525 | D52: 1755 | E52: 1996 | F52: 2178 | G52: 2402 | H52: 2507 | I52: 2738 | J52: 3006 | K52: 3020 | L52: 3206 | M52: 3369 | N52: 3590 | O52: 3764 | Q52: =SUM(O52-C52) -> 2239
A53: davon Sporthalle | C53: 2950 | D53: 2973 | E53: 3004 | F53: 3033 | G53: 3069 | H53: 3078 | I53: 3105 | J53: 3133 | K53: 3135 | L53: 3155 | M53: 3179 | N53: 3207 | O53: 3226 | Q53: =SUM(O53-C53) -> 276
A54: Aula | C54: 325 | D54: 331 | E54: 336 | F54: 342 | G54: 347 | H54: 351 | I54: 362 | J54: 369 | K54: 369 | L54: 374 | M54: 378 | N54: 383 | O54: 387 | Q54: =SUM(O54-C54) -> 62
A55: Lichtenstern 13 | C55: 192 | D55: 202 | E55: 213 | F55: 225 | G55: 239 | H55: 249 | I55: 262 | J55: 289 | K55: 289 | L55: 289 | M55: 289 | N55: 289 | O55: 344 | Q55: =SUM(I55-C55)+(O55-J55) -> 125 | R55: gesamt
R56: =SUM(Q51:Q55) -> 2702 | S56: m³
A59: 2017 | B59: m³ | C59: Jan | D59: Feb | E59: Mrz | F59: Apr | G59: Mai | H59: Jun | I59: Jul | J59: Aug | K59: Sep | L59: Okt | M59: Nov | N59: Dez
C60: 42744 | D60: 42767 | E60: 42800 | F60: 42826 | G60: 42857 | H60: 42887 | I60: 42917 | J60: 42948 | K60: 42979 | L60: 43012 | M60: 43041 | N60: 43070 | O60: 43100
A62: Zähler Schloss | C62: 3764 | D62: 3910 | E62: 4120 | F62: 4325 | G62: 4438 | H62: 4650 | I62: 4805 | J62: 4925 | K62: 5025 | L62: 5197 | M62: 5344 | N62: 5538 | O62: 5711 | Q62: =SUM(O62-C62) -> 1947
A63: davon Sporthalle | C63: 3226 | D63: 3246 | E63: 3279 | F63: 3313 | G63: 3332 | H63: 3353 | I63: 3366 | J63: 3385 | K63: 3394 | L63: 3420 | M63: 3439 | N63: 3472 | O63: 3494 | Q63: =SUM(O63-C63) -> 268
A64: Aula | C64: 387 | D64: 392 | E64: 398 | F64: 404 | G64: 407 | H64: 413 | I64: 418 | J64: 418 | K64: 422 | L64: 474 | M64: 478 | N64: 482 | O64: 486 | Q64: =SUM(O64-C64) -> 99
...

Sheet Verbrauch Wasser
A1: WASSER
A3: 2012 | B3: m³ | C3: Jan | D3: Feb | E3: Mrz | F3: Apr | G3: Mai | H3: Jun | I3: Jul | J3: Aug | K3: Sep | L3: Okt | M3: Nov | N3: Dez
